2025-10-29T03:03:51.772510926Z [inf]  During handling of the above exception, another exception occurred:
2025-10-29T03:03:51.772517051Z [inf]  
2025-10-29T03:03:51.773950472Z [inf]                     ^^^^^^^^^^^^^^^^^^^^^^^^^^^^^
2025-10-29T03:03:51.773961667Z [inf]    File "/app/src/clients/binance_client.py", line 455, in get_account_info
2025-10-29T03:03:51.773969235Z [inf]      result = await self._request("GET", "/fapi/v2/account", signed=True)
2025-10-29T03:03:51.773978948Z [inf]               ^^^^^^^^^^^^^^^^^^^^^^^^^^^^^^^^^^^^^^^^^^^^^^^^^^^^^^^^^^^
2025-10-29T03:03:51.773985838Z [inf]    File "/app/src/clients/binance_client.py", line 219, in _request
2025-10-29T03:03:51.773992849Z [inf]      raise BinanceRequestError(
2025-10-29T03:03:51.773998549Z [inf]  src.clients.binance_errors.BinanceRequestError: 熔斷器阻斷(失敗7次)，請6秒後重試
2025-10-29T03:03:53.764967012Z [inf]  2025-10-29 03:03:53,717 - src.core.circuit_breaker - ERROR - 🔴 熔斷器阻斷(失敗7次)，請4秒後重試 | 操作: generic | 優先級: NORMAL
2025-10-29T03:03:53.764973444Z [inf]  2025-10-29 03:03:53,717 - src.clients.binance_client - ERROR - API 請求失敗: /fapi/v2/account - 熔斷器阻斷(失敗7次)，請4秒後重試
2025-10-29T03:03:53.764980290Z [inf]  2025-10-29 03:03:53,717 - src.core.position_monitor_24x7 - ERROR - ❌ 獲取倉位失敗: 熔斷器阻斷(失敗7次)，請4秒後重試
2025-10-29T03:03:53.772160280Z [inf]  2025-10-29 03:03:53,770 - src.core.circuit_breaker - ERROR - 🔴 熔斷器阻斷(失敗7次)，請4秒後重試 | 操作: generic | 優先級: NORMAL
2025-10-29T03:03:53.772173459Z [inf]  2025-10-29 03:03:53,770 - src.clients.binance_client - ERROR - API 請求失敗: /fapi/v2/account - 熔斷器阻斷(失敗7次)，請4秒後重試
2025-10-29T03:03:53.773133945Z [inf]      result = await self._request("GET", "/fapi/v2/account", signed=True)
2025-10-29T03:03:53.773137362Z [inf]  Exception: 熔斷器阻斷(失敗7次)，請4秒後重試
2025-10-29T03:03:53.773139581Z [inf]  2025-10-29 03:03:53,771 - src.core.position_controller - ERROR - ❌ 獲取持倉失敗: 熔斷器阻斷(失敗7次)，請4秒後重試
2025-10-29T03:03:53.773146174Z [inf]  
2025-10-29T03:03:53.773149256Z [inf]  Traceback (most recent call last):
2025-10-29T03:03:53.773152425Z [inf]  Traceback (most recent call last):
2025-10-29T03:03:53.773153517Z [inf]  During handling of the above exception, another exception occurred:
2025-10-29T03:03:53.773156056Z [inf]    File "/app/src/core/position_controller.py", line 171, in _fetch_all_positions
2025-10-29T03:03:53.773161086Z [inf]  
2025-10-29T03:03:53.773161388Z [inf]    File "/app/src/clients/binance_client.py", line 203, in _request
2025-10-29T03:03:53.773163919Z [inf]      raw_positions = await self.binance_client.get_position_info_async()
2025-10-29T03:03:53.773168793Z [inf]      result = await self.circuit_breaker.call_async(_do_request)
2025-10-29T03:03:53.773175457Z [inf]               ^^^^^^^^^^^^^^^^^^^^^^^^^^^^^^^^^^^^^^^^^^^^^^^^^^
2025-10-29T03:03:53.773176142Z [inf]                      ^^^^^^^^^^^^^^^^^^^^^^^^^^^^^^^^^^^^^^^^^^^^^^^^^^^
2025-10-29T03:03:53.773181957Z [inf]    File "/app/src/clients/binance_client.py", line 475, in get_position_info_async
2025-10-29T03:03:53.773183491Z [inf]    File "/app/src/core/circuit_breaker.py", line 327, in call_async
2025-10-29T03:03:53.773188487Z [inf]      account_info = await self.get_account_info()
2025-10-29T03:03:53.773190550Z [inf]      raise Exception(reason)
2025-10-29T03:03:53.773193677Z [inf]                     ^^^^^^^^^^^^^^^^^^^^^^^^^^^^^
2025-10-29T03:03:53.773198187Z [inf]    File "/app/src/clients/binance_client.py", line 455, in get_account_info
2025-10-29T03:03:53.773624238Z [inf]               ^^^^^^^^^^^^^^^^^^^^^^^^^^^^^^^^^^^^^^^^^^^^^^^^^^^^^^^^^^^
2025-10-29T03:03:53.773629662Z [inf]    File "/app/src/clients/binance_client.py", line 219, in _request
2025-10-29T03:03:53.773634671Z [inf]      raise BinanceRequestError(
2025-10-29T03:03:53.773639768Z [inf]  src.clients.binance_errors.BinanceRequestError: 熔斷器阻斷(失敗7次)，請4秒後重試
2025-10-29T03:03:55.721544891Z [inf]  2025-10-29 03:03:55,718 - src.core.circuit_breaker - ERROR - 🔴 熔斷器阻斷(失敗7次)，請2秒後重試 | 操作: generic | 優先級: NORMAL
2025-10-29T03:03:55.721574933Z [inf]  2025-10-29 03:03:55,719 - src.clients.binance_client - ERROR - API 請求失敗: /fapi/v2/account - 熔斷器阻斷(失敗7次)，請2秒後重試
2025-10-29T03:03:55.721582174Z [inf]  2025-10-29 03:03:55,719 - src.core.position_monitor_24x7 - ERROR - ❌ 獲取倉位失敗: 熔斷器阻斷(失敗7次)，請2秒後重試
2025-10-29T03:03:55.775802915Z [inf]  2025-10-29 03:03:55,772 - src.core.circuit_breaker - ERROR - 🔴 熔斷器阻斷(失敗7次)，請2秒後重試 | 操作: generic | 優先級: NORMAL
2025-10-29T03:03:55.775809736Z [inf]      result = await self.circuit_breaker.call_async(_do_request)
2025-10-29T03:03:55.775814147Z [inf]  2025-10-29 03:03:55,772 - src.clients.binance_client - ERROR - API 請求失敗: /fapi/v2/account - 熔斷器阻斷(失敗7次)，請2秒後重試
2025-10-29T03:03:55.775821655Z [inf]               ^^^^^^^^^^^^^^^^^^^^^^^^^^^^^^^^^^^^^^^^^^^^^^^^^^
2025-10-29T03:03:55.775822076Z [inf]  2025-10-29 03:03:55,772 - src.core.position_controller - ERROR - ❌ 獲取持倉失敗: 熔斷器阻斷(失敗7次)，請2秒後重試
2025-10-29T03:03:55.775827465Z [inf]  Traceback (most recent call last):
2025-10-29T03:03:55.775833939Z [inf]    File "/app/src/clients/binance_client.py", line 203, in _request
2025-10-29T03:03:55.775839657Z [inf]    File "/app/src/core/circuit_breaker.py", line 327, in call_async
2025-10-29T03:03:55.775847650Z [inf]      raise Exception(reason)
2025-10-29T03:03:55.775854707Z [inf]  Exception: 熔斷器阻斷(失敗7次)，請2秒後重試
2025-10-29T03:03:55.775862010Z [inf]  
2025-10-29T03:03:55.775869571Z [inf]  During handling of the above exception, another exception occurred:
2025-10-29T03:03:55.775875594Z [inf]  
2025-10-29T03:03:55.775881369Z [inf]  Traceback (most recent call last):
2025-10-29T03:03:55.775888132Z [inf]    File "/app/src/core/position_controller.py", line 171, in _fetch_all_positions
2025-10-29T03:03:55.775894469Z [inf]      raw_positions = await self.binance_client.get_position_info_async()
2025-10-29T03:03:55.775902022Z [inf]                      ^^^^^^^^^^^^^^^^^^^^^^^^^^^^^^^^^^^^^^^^^^^^^^^^^^^
2025-10-29T03:03:55.775907610Z [inf]    File "/app/src/clients/binance_client.py", line 475, in get_position_info_async
2025-10-29T03:03:55.775913918Z [inf]      account_info = await self.get_account_info()
2025-10-29T03:03:55.776971588Z [inf]                     ^^^^^^^^^^^^^^^^^^^^^^^^^^^^^
2025-10-29T03:03:55.776980752Z [inf]      raise BinanceRequestError(
2025-10-29T03:03:55.776980845Z [inf]    File "/app/src/clients/binance_client.py", line 455, in get_account_info
2025-10-29T03:03:55.776986873Z [inf]      result = await self._request("GET", "/fapi/v2/account", signed=True)
2025-10-29T03:03:55.776992618Z [inf]  src.clients.binance_errors.BinanceRequestError: 熔斷器阻斷(失敗7次)，請2秒後重試
2025-10-29T03:03:55.776994800Z [inf]               ^^^^^^^^^^^^^^^^^^^^^^^^^^^^^^^^^^^^^^^^^^^^^^^^^^^^^^^^^^^
2025-10-29T03:03:55.777001139Z [inf]    File "/app/src/clients/binance_client.py", line 219, in _request
2025-10-29T03:03:57.724458320Z [inf]  2025-10-29 03:03:57,721 - src.core.circuit_breaker - ERROR - 🔴 熔斷器阻斷(失敗7次)，請0秒後重試 | 操作: generic | 優先級: NORMAL
2025-10-29T03:03:57.724466204Z [inf]  2025-10-29 03:03:57,721 - src.clients.binance_client - ERROR - API 請求失敗: /fapi/v2/account - 熔斷器阻斷(失敗7次)，請0秒後重試
2025-10-29T03:03:57.724473048Z [inf]  2025-10-29 03:03:57,721 - src.core.position_monitor_24x7 - ERROR - ❌ 獲取倉位失敗: 熔斷器阻斷(失敗7次)，請0秒後重試
2025-10-29T03:03:57.778850591Z [inf]  2025-10-29 03:03:57,774 - src.core.circuit_breaker - ERROR - 🔴 熔斷器阻斷(失敗7次)，請0秒後重試 | 操作: generic | 優先級: NORMAL
2025-10-29T03:03:57.778862600Z [inf]  2025-10-29 03:03:57,775 - src.clients.binance_client - ERROR - API 請求失敗: /fapi/v2/account - 熔斷器阻斷(失敗7次)，請0秒後重試
2025-10-29T03:03:57.778866268Z [inf]  During handling of the above exception, another exception occurred:
2025-10-29T03:03:57.778873506Z [inf]  2025-10-29 03:03:57,775 - src.core.position_controller - ERROR - ❌ 獲取持倉失敗: 熔斷器阻斷(失敗7次)，請0秒後重試
2025-10-29T03:03:57.778882597Z [inf]  Traceback (most recent call last):
2025-10-29T03:03:57.778885099Z [inf]  
2025-10-29T03:03:57.778895281Z [inf]    File "/app/src/clients/binance_client.py", line 203, in _request
2025-10-29T03:03:57.778899159Z [inf]  Traceback (most recent call last):
2025-10-29T03:03:57.778908473Z [inf]      result = await self.circuit_breaker.call_async(_do_request)
2025-10-29T03:03:57.778913569Z [inf]    File "/app/src/core/position_controller.py", line 171, in _fetch_all_positions
2025-10-29T03:03:57.778920499Z [inf]               ^^^^^^^^^^^^^^^^^^^^^^^^^^^^^^^^^^^^^^^^^^^^^^^^^^
2025-10-29T03:03:57.778927116Z [inf]      raw_positions = await self.binance_client.get_position_info_async()
2025-10-29T03:03:57.778933071Z [inf]    File "/app/src/core/circuit_breaker.py", line 327, in call_async
2025-10-29T03:03:57.778943019Z [inf]                      ^^^^^^^^^^^^^^^^^^^^^^^^^^^^^^^^^^^^^^^^^^^^^^^^^^^
2025-10-29T03:03:57.778945124Z [inf]      raise Exception(reason)
2025-10-29T03:03:57.778958051Z [inf]  Exception: 熔斷器阻斷(失敗7次)，請0秒後重試
2025-10-29T03:03:57.778959491Z [inf]    File "/app/src/clients/binance_client.py", line 475, in get_position_info_async
2025-10-29T03:03:57.778968390Z [inf]  
2025-10-29T03:03:57.778972196Z [inf]      account_info = await self.get_account_info()
2025-10-29T03:03:57.780888022Z [inf]                     ^^^^^^^^^^^^^^^^^^^^^^^^^^^^^
2025-10-29T03:03:57.780899609Z [inf]    File "/app/src/clients/binance_client.py", line 455, in get_account_info
2025-10-29T03:03:57.780913977Z [inf]      result = await self._request("GET", "/fapi/v2/account", signed=True)
2025-10-29T03:03:57.780921535Z [inf]               ^^^^^^^^^^^^^^^^^^^^^^^^^^^^^^^^^^^^^^^^^^^^^^^^^^^^^^^^^^^
2025-10-29T03:03:57.780928443Z [inf]    File "/app/src/clients/binance_client.py", line 219, in _request
2025-10-29T03:03:57.780935470Z [inf]      raise BinanceRequestError(
2025-10-29T03:03:57.780941016Z [inf]  src.clients.binance_errors.BinanceRequestError: 熔斷器阻斷(失敗7次)，請0秒後重試
2025-10-29T03:03:57.930613898Z [inf]  2025-10-29 03:03:57,929 - src.core.unified_scheduler - INFO - ================================================================================
2025-10-29T03:03:57.930624688Z [inf]  2025-10-29 03:03:57,929 - src.core.unified_scheduler - INFO - 🔄 交易週期 #539 | 2025-10-29 03:03:57 UTC
2025-10-29T03:03:57.930646777Z [inf]  2025-10-29 03:03:57,929 - src.core.unified_scheduler - INFO - ================================================================================
2025-10-29T03:03:57.935207930Z [inf]  2025-10-29 03:03:57,929 - src.core.circuit_breaker - INFO - ✅ 熔斷器超時恢復: blocked → NORMAL (超時60秒)
2025-10-29T03:03:58.376053081Z [inf]  Traceback (most recent call last):
2025-10-29T03:03:58.376067611Z [inf]    File "/app/src/clients/binance_client.py", line 203, in _request
2025-10-29T03:03:58.376077393Z [inf]      result = await self.circuit_breaker.call_async(_do_request)
2025-10-29T03:03:58.376093222Z [inf]               ^^^^^^^^^^^^^^^^^^^^^^^^^^^^^^^^^^^^^^^^^^^^^^^^^^
2025-10-29T03:03:58.376272068Z [inf]  2025-10-29 03:03:58,016 - src.clients.binance_client - ERROR - Binance API 錯誤 429: code=-1003, msg=Too many requests; current limit of IP(208.77.246.15) is 2400 requests per minute. Please use the websocket for live updates to avoid polling the API., endpoint=/fapi/v2/account, params={'timestamp': 1761707037929}
2025-10-29T03:03:58.376286093Z [inf]  2025-10-29 03:03:58,016 - src.core.circuit_breaker - WARNING - 🔄 熔斷器級別變化: normal → warning (失敗次數: 1)
2025-10-29T03:03:58.376291993Z [inf]  2025-10-29 03:03:58,016 - src.clients.binance_client - ERROR - API 請求失敗: /fapi/v2/account - HTTP 429: Too Many Requests
2025-10-29T03:03:58.376297739Z [inf]  2025-10-29 03:03:58,016 - src.core.unified_scheduler - ERROR - ❌ 獲取持倉失敗: HTTP 429: Too Many Requests
2025-10-29T03:03:58.376305678Z [inf]  2025-10-29 03:03:58,016 - src.core.circuit_breaker - WARNING - ⚠️  熔斷器警告級: 失敗1次 (操作: generic, 優先級: NORMAL)
2025-10-29T03:03:58.376311177Z [inf]  2025-10-29 03:03:58,092 - src.clients.binance_client - ERROR - Binance API 錯誤 429: code=-1003, msg=Too many requests; current limit of IP(208.77.246.15) is 2400 requests per minute. Please use the websocket for live updates to avoid polling the API., endpoint=/fapi/v2/account, params={'timestamp': 1761707038016}
2025-10-29T03:03:58.376316169Z [inf]  2025-10-29 03:03:58,092 - src.clients.binance_client - ERROR - API 請求失敗: /fapi/v2/account - HTTP 429: Too Many Requests
2025-10-29T03:03:58.376320837Z [inf]  2025-10-29 03:03:58,092 - src.core.unified_scheduler - ERROR - ❌ 交易週期執行失敗: HTTP 429: Too Many Requests
2025-10-29T03:03:58.376875387Z [inf]    File "/app/src/core/circuit_breaker.py", line 339, in call_async
2025-10-29T03:03:58.376883155Z [inf]      raise e
2025-10-29T03:03:58.376888955Z [inf]    File "/app/src/core/circuit_breaker.py", line 334, in call_async
2025-10-29T03:03:58.376895347Z [inf]      result = await func(*args, **kwargs)
2025-10-29T03:03:58.376904256Z [inf]  During handling of the above exception, another exception occurred:
2025-10-29T03:03:58.376904662Z [inf]               ^^^^^^^^^^^^^^^^^^^^^^^^^^^
2025-10-29T03:03:58.376913702Z [inf]    File "/app/src/clients/binance_client.py", line 199, in _do_request
2025-10-29T03:03:58.376917702Z [inf]  
2025-10-29T03:03:58.376925013Z [inf]      response.raise_for_status()
2025-10-29T03:03:58.376929799Z [inf]  Traceback (most recent call last):
2025-10-29T03:03:58.376935210Z [inf]    File "/opt/venv/lib/python3.11/site-packages/aiohttp/client_reqrep.py", line 636, in raise_for_status
2025-10-29T03:03:58.376943219Z [inf]      raise ClientResponseError(
2025-10-29T03:03:58.376943860Z [inf]    File "/app/src/core/unified_scheduler.py", line 227, in _execute_trading_cycle
2025-10-29T03:03:58.376953400Z [inf]  aiohttp.client_exceptions.ClientResponseError: 429, message='Too Many Requests', url='https://fapi.binance.com/fapi/v2/account?timestamp=1761707038016&signature=faf4d5dfbb61595d9bf40784e70ef84d0620ca8e768a0c29b562567a92e4698e'
2025-10-29T03:03:58.376955756Z [inf]      account_info = await self.binance_client.get_account_balance()
2025-10-29T03:03:58.376962057Z [inf]  
2025-10-29T03:03:58.376965981Z [inf]                     ^^^^^^^^^^^^^^^^^^^^^^^^^^^^^^^^^^^^^^^^^^^^^^^
2025-10-29T03:03:58.376972578Z [inf]    File "/app/src/clients/binance_client.py", line 491, in get_account_balance
2025-10-29T03:03:58.376978492Z [inf]      account_info = await self.get_account_info()
2025-10-29T03:03:58.376988124Z [inf]                     ^^^^^^^^^^^^^^^^^^^^^^^^^^^^^
2025-10-29T03:03:58.378424966Z [inf]    File "/app/src/clients/binance_client.py", line 455, in get_account_info
2025-10-29T03:03:58.378434724Z [inf]      result = await self._request("GET", "/fapi/v2/account", signed=True)
2025-10-29T03:03:58.378442075Z [inf]               ^^^^^^^^^^^^^^^^^^^^^^^^^^^^^^^^^^^^^^^^^^^^^^^^^^^^^^^^^^^
2025-10-29T03:03:58.378448919Z [inf]    File "/app/src/clients/binance_client.py", line 207, in _request
2025-10-29T03:03:58.378456760Z [inf]      raise BinanceRequestError(
2025-10-29T03:03:58.378464366Z [inf]  src.clients.binance_errors.BinanceRequestError: HTTP 429: Too Many Requests
2025-10-29T03:03:59.734548098Z [inf]  2025-10-29 03:03:59,725 - src.core.circuit_breaker - WARNING - ⚠️  熔斷器警告級: 失敗2次 (操作: generic, 優先級: NORMAL)
2025-10-29T03:03:59.777799408Z [inf]  2025-10-29 03:03:59,776 - src.core.circuit_breaker - WARNING - ⚠️  熔斷器警告級: 失敗2次 (操作: generic, 優先級: NORMAL)
2025-10-29T03:03:59.806679916Z [inf]  2025-10-29 03:03:59,803 - src.clients.binance_client - ERROR - Binance API 錯誤 429: code=-1003, msg=Too many requests; current limit of IP(208.77.246.15) is 2400 requests per minute. Please use the websocket for live updates to avoid polling the API., endpoint=/fapi/v2/account, params={'timestamp': 1761707039725}
2025-10-29T03:03:59.806688569Z [inf]  2025-10-29 03:03:59,803 - src.clients.binance_client - ERROR - API 請求失敗: /fapi/v2/account - HTTP 429: Too Many Requests
2025-10-29T03:03:59.806697206Z [inf]  2025-10-29 03:03:59,803 - src.core.position_monitor_24x7 - ERROR - ❌ 獲取倉位失敗: HTTP 429: Too Many Requests
2025-10-29T03:03:59.870798125Z [inf]  2025-10-29 03:03:59,865 - src.clients.binance_client - ERROR - Binance API 錯誤 429: code=-1003, msg=Too many requests; current limit of IP(208.77.246.15) is 2400 requests per minute. Please use the websocket for live updates to avoid polling the API., endpoint=/fapi/v2/account, params={'timestamp': 1761707039776}
2025-10-29T03:03:59.870811193Z [inf]  2025-10-29 03:03:59,865 - src.core.circuit_breaker - WARNING - 🔄 熔斷器級別變化: warning → throttled (失敗次數: 4)
2025-10-29T03:03:59.870819815Z [inf]  2025-10-29 03:03:59,865 - src.clients.binance_client - ERROR - API 請求失敗: /fapi/v2/account - HTTP 429: Too Many Requests
2025-10-29T03:03:59.870826596Z [inf]  2025-10-29 03:03:59,865 - src.core.position_controller - ERROR - ❌ 獲取持倉失敗: HTTP 429: Too Many Requests
2025-10-29T03:03:59.870835417Z [inf]  Traceback (most recent call last):
2025-10-29T03:03:59.870842503Z [inf]    File "/app/src/clients/binance_client.py", line 203, in _request
2025-10-29T03:03:59.870849763Z [inf]      result = await self.circuit_breaker.call_async(_do_request)
2025-10-29T03:03:59.870859150Z [inf]               ^^^^^^^^^^^^^^^^^^^^^^^^^^^^^^^^^^^^^^^^^^^^^^^^^^
2025-10-29T03:03:59.870865930Z [inf]    File "/app/src/core/circuit_breaker.py", line 339, in call_async
2025-10-29T03:03:59.870872950Z [inf]      raise e
2025-10-29T03:03:59.870879350Z [inf]    File "/app/src/core/circuit_breaker.py", line 334, in call_async
2025-10-29T03:03:59.870887152Z [inf]      result = await func(*args, **kwargs)
2025-10-29T03:03:59.870894201Z [inf]               ^^^^^^^^^^^^^^^^^^^^^^^^^^^
2025-10-29T03:03:59.870900897Z [inf]    File "/app/src/clients/binance_client.py", line 199, in _do_request
2025-10-29T03:03:59.870908057Z [inf]      response.raise_for_status()
2025-10-29T03:03:59.870917890Z [inf]    File "/opt/venv/lib/python3.11/site-packages/aiohttp/client_reqrep.py", line 636, in raise_for_status
2025-10-29T03:03:59.873591022Z [inf]    File "/app/src/clients/binance_client.py", line 207, in _request
2025-10-29T03:03:59.873593437Z [inf]      raise ClientResponseError(
2025-10-29T03:03:59.873600768Z [inf]      raise BinanceRequestError(
2025-10-29T03:03:59.873608960Z [inf]  aiohttp.client_exceptions.ClientResponseError: 429, message='Too Many Requests', url='https://fapi.binance.com/fapi/v2/account?timestamp=1761707039776&signature=717d996e7b7e3430e1980deac364c7ae9e6f8238bfedd66960d547049f19e4a4'
2025-10-29T03:03:59.873611136Z [inf]  src.clients.binance_errors.BinanceRequestError: HTTP 429: Too Many Requests
2025-10-29T03:03:59.873615140Z [inf]    File "/app/src/clients/binance_client.py", line 475, in get_position_info_async
2025-10-29T03:03:59.873621003Z [inf]  
2025-10-29T03:03:59.873630579Z [inf]  During handling of the above exception, another exception occurred:
2025-10-29T03:03:59.873631851Z [inf]      account_info = await self.get_account_info()
2025-10-29T03:03:59.873641594Z [inf]  
2025-10-29T03:03:59.873642586Z [inf]                     ^^^^^^^^^^^^^^^^^^^^^^^^^^^^^
2025-10-29T03:03:59.873649602Z [inf]  Traceback (most recent call last):
2025-10-29T03:03:59.873654782Z [inf]    File "/app/src/clients/binance_client.py", line 455, in get_account_info
2025-10-29T03:03:59.873658000Z [inf]    File "/app/src/core/position_controller.py", line 171, in _fetch_all_positions
2025-10-29T03:03:59.873666001Z [inf]      raw_positions = await self.binance_client.get_position_info_async()
2025-10-29T03:03:59.873667032Z [inf]      result = await self._request("GET", "/fapi/v2/account", signed=True)
2025-10-29T03:03:59.873673478Z [inf]                      ^^^^^^^^^^^^^^^^^^^^^^^^^^^^^^^^^^^^^^^^^^^^^^^^^^^
2025-10-29T03:03:59.873678421Z [inf]               ^^^^^^^^^^^^^^^^^^^^^^^^^^^^^^^^^^^^^^^^^^^^^^^^^^^^^^^^^^^
2025-10-29T03:04:01.807797722Z [inf]  2025-10-29 03:04:01,806 - src.core.circuit_breaker - WARNING - 🔸 熔斷器限流: 增加2.0秒延遲 (失敗4次, 操作: generic)
2025-10-29T03:04:01.871668560Z [inf]  2025-10-29 03:04:01,866 - src.core.circuit_breaker - WARNING - 🔸 熔斷器限流: 增加2.0秒延遲 (失敗4次, 操作: generic)
2025-10-29T03:04:03.906142583Z [inf]  2025-10-29 03:04:03,901 - src.core.circuit_breaker - WARNING - 🔄 熔斷器級別變化: throttled → warning (失敗次數: 3)
2025-10-29T03:04:03.906151806Z [inf]  2025-10-29 03:04:03,902 - src.core.position_monitor_24x7 - WARNING - ⚠️ FXSUSDT 無法獲取風險金額，跳過檢查
2025-10-29T03:04:03.906156867Z [inf]  2025-10-29 03:04:03,902 - src.core.position_monitor_24x7 - WARNING - ⚠️ LTCUSDT 無法獲取風險金額，跳過檢查
2025-10-29T03:04:03.906161461Z [inf]  2025-10-29 03:04:03,902 - src.core.position_monitor_24x7 - WARNING - ⚠️ RLCUSDT 無法獲取風險金額，跳過檢查
2025-10-29T03:04:03.906167236Z [inf]  2025-10-29 03:04:03,902 - src.core.position_monitor_24x7 - WARNING - ⚠️ LINKUSDT 無法獲取風險金額，跳過檢查
2025-10-29T03:04:03.906172137Z [inf]  2025-10-29 03:04:03,902 - src.core.position_monitor_24x7 - WARNING - ⚠️ DYDXUSDT 無法獲取風險金額，跳過檢查
2025-10-29T03:04:05.905861101Z [inf]  2025-10-29 03:04:05,904 - src.core.position_monitor_24x7 - WARNING - ⚠️ FXSUSDT 無法獲取風險金額，跳過檢查
2025-10-29T03:04:05.905870365Z [inf]  2025-10-29 03:04:05,904 - src.core.position_monitor_24x7 - WARNING - ⚠️ LTCUSDT 無法獲取風險金額，跳過檢查
2025-10-29T03:04:05.905877188Z [inf]  2025-10-29 03:04:05,904 - src.core.position_monitor_24x7 - WARNING - ⚠️ RLCUSDT 無法獲取風險金額，跳過檢查
2025-10-29T03:04:05.905883863Z [inf]  2025-10-29 03:04:05,904 - src.core.position_monitor_24x7 - WARNING - ⚠️ LINKUSDT 無法獲取風險金額，跳過檢查
2025-10-29T03:04:05.905889790Z [inf]  2025-10-29 03:04:05,904 - src.core.position_monitor_24x7 - WARNING - ⚠️ DYDXUSDT 無法獲取風險金額，跳過檢查
2025-10-29T03:04:07.911655227Z [inf]  2025-10-29 03:04:07,908 - src.core.position_monitor_24x7 - WARNING - ⚠️ FXSUSDT 無法獲取風險金額，跳過檢查
2025-10-29T03:04:07.911660570Z [inf]  2025-10-29 03:04:07,908 - src.core.position_monitor_24x7 - WARNING - ⚠️ LTCUSDT 無法獲取風險金額，跳過檢查
2025-10-29T03:04:07.911665852Z [inf]  2025-10-29 03:04:07,908 - src.core.position_monitor_24x7 - WARNING - ⚠️ RLCUSDT 無法獲取風險金額，跳過檢查
2025-10-29T03:04:07.911672552Z [inf]  2025-10-29 03:04:07,908 - src.core.position_monitor_24x7 - WARNING - ⚠️ LINKUSDT 無法獲取風險金額，跳過檢查
2025-10-29T03:04:07.911678401Z [inf]  2025-10-29 03:04:07,908 - src.core.position_monitor_24x7 - WARNING - ⚠️ DYDXUSDT 無法獲取風險金額，跳過檢查
2025-10-29T03:04:09.913890333Z [inf]  2025-10-29 03:04:09,911 - src.core.position_monitor_24x7 - WARNING - ⚠️ FXSUSDT 無法獲取風險金額，跳過檢查
2025-10-29T03:04:09.913899114Z [inf]  2025-10-29 03:04:09,911 - src.core.position_monitor_24x7 - WARNING - ⚠️ LTCUSDT 無法獲取風險金額，跳過檢查
2025-10-29T03:04:09.913907388Z [inf]  2025-10-29 03:04:09,911 - src.core.position_monitor_24x7 - WARNING - ⚠️ RLCUSDT 無法獲取風險金額，跳過檢查
2025-10-29T03:04:09.913913991Z [inf]  2025-10-29 03:04:09,911 - src.core.position_monitor_24x7 - WARNING - ⚠️ LINKUSDT 無法獲取風險金額，跳過檢查
2025-10-29T03:04:09.913922902Z [inf]  2025-10-29 03:04:09,911 - src.core.position_monitor_24x7 - WARNING - ⚠️ DYDXUSDT 無法獲取風險金額，跳過檢查
2025-10-29T03:04:11.917899294Z [inf]  2025-10-29 03:04:11,914 - src.core.position_monitor_24x7 - WARNING - ⚠️ FXSUSDT 無法獲取風險金額，跳過檢查
2025-10-29T03:04:11.917906581Z [inf]  2025-10-29 03:04:11,915 - src.core.position_monitor_24x7 - WARNING - ⚠️ LTCUSDT 無法獲取風險金額，跳過檢查
2025-10-29T03:04:11.917912157Z [inf]  2025-10-29 03:04:11,915 - src.core.position_monitor_24x7 - WARNING - ⚠️ RLCUSDT 無法獲取風險金額，跳過檢查
2025-10-29T03:04:11.917917074Z [inf]  2025-10-29 03:04:11,915 - src.core.position_monitor_24x7 - WARNING - ⚠️ LINKUSDT 無法獲取風險金額，跳過檢查
2025-10-29T03:04:11.917921632Z [inf]  2025-10-29 03:04:11,915 - src.core.position_monitor_24x7 - WARNING - ⚠️ DYDXUSDT 無法獲取風險金額，跳過檢查
2025-10-29T03:04:13.919038583Z [inf]  2025-10-29 03:04:13,916 - src.core.position_monitor_24x7 - WARNING - ⚠️ FXSUSDT 無法獲取風險金額，跳過檢查
2025-10-29T03:04:13.919063875Z [inf]  2025-10-29 03:04:13,917 - src.core.position_monitor_24x7 - WARNING - ⚠️ LTCUSDT 無法獲取風險金額，跳過檢查
2025-10-29T03:04:13.919074878Z [inf]  2025-10-29 03:04:13,917 - src.core.position_monitor_24x7 - WARNING - ⚠️ RLCUSDT 無法獲取風險金額，跳過檢查
2025-10-29T03:04:13.919082914Z [inf]  2025-10-29 03:04:13,917 - src.core.position_monitor_24x7 - WARNING - ⚠️ LINKUSDT 無法獲取風險金額，跳過檢查
2025-10-29T03:04:13.919090960Z [inf]  2025-10-29 03:04:13,917 - src.core.position_monitor_24x7 - WARNING - ⚠️ DYDXUSDT 無法獲取風險金額，跳過檢查
2025-10-29T03:04:13.973934870Z [inf]  2025-10-29 03:04:13,971 - src.core.circuit_breaker - WARNING - ⚠️  熔斷器警告級: 失敗2次 (操作: generic, 優先級: NORMAL)
2025-10-29T03:04:15.922782906Z [inf]  2025-10-29 03:04:15,919 - src.core.position_monitor_24x7 - WARNING - ⚠️ FXSUSDT 無法獲取風險金額，跳過檢查
2025-10-29T03:04:15.922790404Z [inf]  2025-10-29 03:04:15,919 - src.core.position_monitor_24x7 - WARNING - ⚠️ LTCUSDT 無法獲取風險金額，跳過檢查
2025-10-29T03:04:15.922796555Z [inf]  2025-10-29 03:04:15,919 - src.core.position_monitor_24x7 - WARNING - ⚠️ RLCUSDT 無法獲取風險金額，跳過檢查
2025-10-29T03:04:15.922801118Z [inf]  2025-10-29 03:04:15,919 - src.core.position_monitor_24x7 - WARNING - ⚠️ LINKUSDT 無法獲取風險金額，跳過檢查
2025-10-29T03:04:15.922806579Z [inf]  2025-10-29 03:04:15,919 - src.core.position_monitor_24x7 - WARNING - ⚠️ DYDXUSDT 無法獲取風險金額，跳過檢查
2025-10-29T03:04:17.923997598Z [inf]  2025-10-29 03:04:17,922 - src.core.position_monitor_24x7 - WARNING - ⚠️ FXSUSDT 無法獲取風險金額，跳過檢查
2025-10-29T03:04:17.924008962Z [inf]  2025-10-29 03:04:17,922 - src.core.position_monitor_24x7 - WARNING - ⚠️ LTCUSDT 無法獲取風險金額，跳過檢查
2025-10-29T03:04:17.924017598Z [inf]  2025-10-29 03:04:17,922 - src.core.position_monitor_24x7 - WARNING - ⚠️ RLCUSDT 無法獲取風險金額，跳過檢查
2025-10-29T03:04:17.924025569Z [inf]  2025-10-29 03:04:17,922 - src.core.position_monitor_24x7 - WARNING - ⚠️ LINKUSDT 無法獲取風險金額，跳過檢查
2025-10-29T03:04:17.924034030Z [inf]  2025-10-29 03:04:17,922 - src.core.position_monitor_24x7 - WARNING - ⚠️ DYDXUSDT 無法獲取風險金額，跳過檢查
2025-10-29T03:04:19.926130220Z [inf]  2025-10-29 03:04:19,924 - src.core.position_monitor_24x7 - WARNING - ⚠️ FXSUSDT 無法獲取風險金額，跳過檢查
2025-10-29T03:04:19.926138095Z [inf]  2025-10-29 03:04:19,925 - src.core.position_monitor_24x7 - WARNING - ⚠️ LTCUSDT 無法獲取風險金額，跳過檢查
2025-10-29T03:04:19.926145495Z [inf]  2025-10-29 03:04:19,925 - src.core.position_monitor_24x7 - WARNING - ⚠️ RLCUSDT 無法獲取風險金額，跳過檢查
2025-10-29T03:04:19.926150867Z [inf]  2025-10-29 03:04:19,925 - src.core.position_monitor_24x7 - WARNING - ⚠️ LINKUSDT 無法獲取風險金額，跳過檢查
2025-10-29T03:04:19.926157021Z [inf]  2025-10-29 03:04:19,925 - src.core.position_monitor_24x7 - WARNING - ⚠️ DYDXUSDT 無法獲取風險金額，跳過檢查
2025-10-29T03:04:21.935475756Z [inf]  2025-10-29 03:04:21,928 - src.core.position_monitor_24x7 - WARNING - ⚠️ FXSUSDT 無法獲取風險金額，跳過檢查
2025-10-29T03:04:21.935489877Z [inf]  2025-10-29 03:04:21,928 - src.core.position_monitor_24x7 - WARNING - ⚠️ LTCUSDT 無法獲取風險金額，跳過檢查
2025-10-29T03:04:21.935498009Z [inf]  2025-10-29 03:04:21,928 - src.core.position_monitor_24x7 - WARNING - ⚠️ RLCUSDT 無法獲取風險金額，跳過檢查
2025-10-29T03:04:21.935506110Z [inf]  2025-10-29 03:04:21,928 - src.core.position_monitor_24x7 - WARNING - ⚠️ LINKUSDT 無法獲取風險金額，跳過檢查
2025-10-29T03:04:21.935513100Z [inf]  2025-10-29 03:04:21,928 - src.core.position_monitor_24x7 - WARNING - ⚠️ DYDXUSDT 無法獲取風險金額，跳過檢查
2025-10-29T03:04:23.932657439Z [inf]  2025-10-29 03:04:23,930 - src.core.position_monitor_24x7 - WARNING - ⚠️ FXSUSDT 無法獲取風險金額，跳過檢查
2025-10-29T03:04:23.932665827Z [inf]  2025-10-29 03:04:23,930 - src.core.position_monitor_24x7 - WARNING - ⚠️ LTCUSDT 無法獲取風險金額，跳過檢查
2025-10-29T03:04:23.932673182Z [inf]  2025-10-29 03:04:23,930 - src.core.position_monitor_24x7 - WARNING - ⚠️ RLCUSDT 無法獲取風險金額，跳過檢查
2025-10-29T03:04:23.932679072Z [inf]  2025-10-29 03:04:23,930 - src.core.position_monitor_24x7 - WARNING - ⚠️ LINKUSDT 無法獲取風險金額，跳過檢查
2025-10-29T03:04:23.932684000Z [inf]  2025-10-29 03:04:23,930 - src.core.position_monitor_24x7 - WARNING - ⚠️ DYDXUSDT 無法獲取風險金額，跳過檢查
2025-10-29T03:04:24.298867413Z [inf]  2025-10-29 03:04:24,077 - src.core.circuit_breaker - WARNING - ⚠️  熔斷器警告級: 失敗1次 (操作: generic, 優先級: NORMAL)
2025-10-29T03:04:24.298874940Z [inf]  2025-10-29 03:04:24,180 - src.core.circuit_breaker - WARNING - 🔄 熔斷器級別變化: warning → normal (失敗次數: 0)
2025-10-29T03:04:25.936235095Z [inf]  2025-10-29 03:04:25,934 - src.core.position_monitor_24x7 - WARNING - ⚠️ FXSUSDT 無法獲取風險金額，跳過檢查
2025-10-29T03:04:25.936245751Z [inf]  2025-10-29 03:04:25,934 - src.core.position_monitor_24x7 - WARNING - ⚠️ LTCUSDT 無法獲取風險金額，跳過檢查
2025-10-29T03:04:25.936254573Z [inf]  2025-10-29 03:04:25,934 - src.core.position_monitor_24x7 - WARNING - ⚠️ RLCUSDT 無法獲取風險金額，跳過檢查
2025-10-29T03:04:25.936261828Z [inf]  2025-10-29 03:04:25,934 - src.core.position_monitor_24x7 - WARNING - ⚠️ LINKUSDT 無法獲取風險金額，跳過檢查
2025-10-29T03:04:25.936267192Z [inf]  2025-10-29 03:04:25,934 - src.core.position_monitor_24x7 - WARNING - ⚠️ DYDXUSDT 無法獲取風險金額，跳過檢查
2025-10-29T03:04:27.942506181Z [inf]  2025-10-29 03:04:27,937 - src.core.position_monitor_24x7 - WARNING - ⚠️ FXSUSDT 無法獲取風險金額，跳過檢查
2025-10-29T03:04:27.942514171Z [inf]  2025-10-29 03:04:27,937 - src.core.position_monitor_24x7 - WARNING - ⚠️ LTCUSDT 無法獲取風險金額，跳過檢查
2025-10-29T03:04:27.942519563Z [inf]  2025-10-29 03:04:27,937 - src.core.position_monitor_24x7 - WARNING - ⚠️ RLCUSDT 無法獲取風險金額，跳過檢查
2025-10-29T03:04:27.942523996Z [inf]  2025-10-29 03:04:27,937 - src.core.position_monitor_24x7 - WARNING - ⚠️ LINKUSDT 無法獲取風險金額，跳過檢查
2025-10-29T03:04:27.942528604Z [inf]  2025-10-29 03:04:27,937 - src.core.position_monitor_24x7 - WARNING - ⚠️ DYDXUSDT 無法獲取風險金額，跳過檢查
2025-10-29T03:04:29.942983996Z [inf]  2025-10-29 03:04:29,939 - src.core.position_monitor_24x7 - WARNING - ⚠️ FXSUSDT 無法獲取風險金額，跳過檢查
2025-10-29T03:04:29.942994322Z [inf]  2025-10-29 03:04:29,939 - src.core.position_monitor_24x7 - WARNING - ⚠️ LTCUSDT 無法獲取風險金額，跳過檢查
2025-10-29T03:04:29.943000683Z [inf]  2025-10-29 03:04:29,939 - src.core.position_monitor_24x7 - WARNING - ⚠️ RLCUSDT 無法獲取風險金額，跳過檢查
2025-10-29T03:04:29.943006694Z [inf]  2025-10-29 03:04:29,939 - src.core.position_monitor_24x7 - WARNING - ⚠️ LINKUSDT 無法獲取風險金額，跳過檢查
2025-10-29T03:04:29.943011951Z [inf]  2025-10-29 03:04:29,939 - src.core.position_monitor_24x7 - WARNING - ⚠️ DYDXUSDT 無法獲取風險金額，跳過檢查
2025-10-29T03:04:31.953897330Z [inf]  2025-10-29 03:04:31,941 - src.core.position_monitor_24x7 - WARNING - ⚠️ FXSUSDT 無法獲取風險金額，跳過檢查
2025-10-29T03:04:31.953902736Z [inf]  2025-10-29 03:04:31,941 - src.core.position_monitor_24x7 - WARNING - ⚠️ LTCUSDT 無法獲取風險金額，跳過檢查
2025-10-29T03:04:31.953907401Z [inf]  2025-10-29 03:04:31,941 - src.core.position_monitor_24x7 - WARNING - ⚠️ RLCUSDT 無法獲取風險金額，跳過檢查
2025-10-29T03:04:31.953913578Z [inf]  2025-10-29 03:04:31,942 - src.core.position_monitor_24x7 - WARNING - ⚠️ LINKUSDT 無法獲取風險金額，跳過檢查
2025-10-29T03:04:31.953920562Z [inf]  2025-10-29 03:04:31,942 - src.core.position_monitor_24x7 - WARNING - ⚠️ DYDXUSDT 無法獲取風險金額，跳過檢查
2025-10-29T03:04:33.946230647Z [inf]  2025-10-29 03:04:33,944 - src.core.position_monitor_24x7 - WARNING - ⚠️ FXSUSDT 無法獲取風險金額，跳過檢查
2025-10-29T03:04:33.946239927Z [inf]  2025-10-29 03:04:33,945 - src.core.position_monitor_24x7 - WARNING - ⚠️ LTCUSDT 無法獲取風險金額，跳過檢查
2025-10-29T03:04:33.946246851Z [inf]  2025-10-29 03:04:33,945 - src.core.position_monitor_24x7 - WARNING - ⚠️ RLCUSDT 無法獲取風險金額，跳過檢查
2025-10-29T03:04:33.946252788Z [inf]  2025-10-29 03:04:33,945 - src.core.position_monitor_24x7 - WARNING - ⚠️ LINKUSDT 無法獲取風險金額，跳過檢查
2025-10-29T03:04:33.946259620Z [inf]  2025-10-29 03:04:33,945 - src.core.position_monitor_24x7 - WARNING - ⚠️ DYDXUSDT 無法獲取風險金額，跳過檢查
2025-10-29T03:04:35.951133271Z [inf]  2025-10-29 03:04:35,948 - src.core.position_monitor_24x7 - WARNING - ⚠️ FXSUSDT 無法獲取風險金額，跳過檢查
2025-10-29T03:04:35.951146144Z [inf]  2025-10-29 03:04:35,948 - src.core.position_monitor_24x7 - WARNING - ⚠️ LTCUSDT 無法獲取風險金額，跳過檢查
2025-10-29T03:04:35.951155400Z [inf]  2025-10-29 03:04:35,948 - src.core.position_monitor_24x7 - WARNING - ⚠️ RLCUSDT 無法獲取風險金額，跳過檢查
2025-10-29T03:04:35.951161805Z [inf]  2025-10-29 03:04:35,948 - src.core.position_monitor_24x7 - WARNING - ⚠️ LINKUSDT 無法獲取風險金額，跳過檢查
2025-10-29T03:04:35.951168523Z [inf]  2025-10-29 03:04:35,948 - src.core.position_monitor_24x7 - WARNING - ⚠️ DYDXUSDT 無法獲取風險金額，跳過檢查
2025-10-29T03:04:37.955285498Z [inf]  2025-10-29 03:04:37,952 - src.core.position_monitor_24x7 - WARNING - ⚠️ FXSUSDT 無法獲取風險金額，跳過檢查
2025-10-29T03:04:37.955293141Z [inf]  2025-10-29 03:04:37,953 - src.core.position_monitor_24x7 - WARNING - ⚠️ LTCUSDT 無法獲取風險金額，跳過檢查
2025-10-29T03:04:37.955298886Z [inf]  2025-10-29 03:04:37,953 - src.core.position_monitor_24x7 - WARNING - ⚠️ RLCUSDT 無法獲取風險金額，跳過檢查
2025-10-29T03:04:37.955304103Z [inf]  2025-10-29 03:04:37,953 - src.core.position_monitor_24x7 - WARNING - ⚠️ LINKUSDT 無法獲取風險金額，跳過檢查
2025-10-29T03:04:37.955310403Z [inf]  2025-10-29 03:04:37,953 - src.core.position_monitor_24x7 - WARNING - ⚠️ DYDXUSDT 無法獲取風險金額，跳過檢查
2025-10-29T03:04:39.967270022Z [inf]  2025-10-29 03:04:39,955 - src.core.position_monitor_24x7 - WARNING - ⚠️ FXSUSDT 無法獲取風險金額，跳過檢查
2025-10-29T03:04:39.967277400Z [inf]  2025-10-29 03:04:39,955 - src.core.position_monitor_24x7 - WARNING - ⚠️ LTCUSDT 無法獲取風險金額，跳過檢查
2025-10-29T03:04:39.967283850Z [inf]  2025-10-29 03:04:39,955 - src.core.position_monitor_24x7 - WARNING - ⚠️ RLCUSDT 無法獲取風險金額，跳過檢查
2025-10-29T03:04:39.967291177Z [inf]  2025-10-29 03:04:39,955 - src.core.position_monitor_24x7 - WARNING - ⚠️ LINKUSDT 無法獲取風險金額，跳過檢查
2025-10-29T03:04:39.967297540Z [inf]  2025-10-29 03:04:39,955 - src.core.position_monitor_24x7 - WARNING - ⚠️ DYDXUSDT 無法獲取風險金額，跳過檢查
2025-10-29T03:04:41.959723642Z [inf]  2025-10-29 03:04:41,957 - src.core.position_monitor_24x7 - WARNING - ⚠️ FXSUSDT 無法獲取風險金額，跳過檢查
2025-10-29T03:04:41.959732902Z [inf]  2025-10-29 03:04:41,958 - src.core.position_monitor_24x7 - WARNING - ⚠️ LTCUSDT 無法獲取風險金額，跳過檢查
2025-10-29T03:04:41.959738757Z [inf]  2025-10-29 03:04:41,958 - src.core.position_monitor_24x7 - WARNING - ⚠️ RLCUSDT 無法獲取風險金額，跳過檢查
2025-10-29T03:04:41.959745505Z [inf]  2025-10-29 03:04:41,958 - src.core.position_monitor_24x7 - WARNING - ⚠️ LINKUSDT 無法獲取風險金額，跳過檢查
2025-10-29T03:04:41.959752011Z [inf]  2025-10-29 03:04:41,958 - src.core.position_monitor_24x7 - WARNING - ⚠️ DYDXUSDT 無法獲取風險金額，跳過檢查
2025-10-29T03:04:43.962260364Z [inf]  2025-10-29 03:04:43,959 - src.core.position_monitor_24x7 - WARNING - ⚠️ FXSUSDT 無法獲取風險金額，跳過檢查
2025-10-29T03:04:43.962270655Z [inf]  2025-10-29 03:04:43,960 - src.core.position_monitor_24x7 - WARNING - ⚠️ LTCUSDT 無法獲取風險金額，跳過檢查
2025-10-29T03:04:43.962280617Z [inf]  2025-10-29 03:04:43,960 - src.core.position_monitor_24x7 - WARNING - ⚠️ RLCUSDT 無法獲取風險金額，跳過檢查
2025-10-29T03:04:43.962287060Z [inf]  2025-10-29 03:04:43,960 - src.core.position_monitor_24x7 - WARNING - ⚠️ LINKUSDT 無法獲取風險金額，跳過檢查
2025-10-29T03:04:43.962292784Z [inf]  2025-10-29 03:04:43,960 - src.core.position_monitor_24x7 - WARNING - ⚠️ DYDXUSDT 無法獲取風險金額，跳過檢查
2025-10-29T03:04:45.963931612Z [inf]  2025-10-29 03:04:45,961 - src.core.position_monitor_24x7 - WARNING - ⚠️ FXSUSDT 無法獲取風險金額，跳過檢查
2025-10-29T03:04:45.963938372Z [inf]  2025-10-29 03:04:45,961 - src.core.position_monitor_24x7 - WARNING - ⚠️ LTCUSDT 無法獲取風險金額，跳過檢查
2025-10-29T03:04:45.963944148Z [inf]  2025-10-29 03:04:45,961 - src.core.position_monitor_24x7 - WARNING - ⚠️ RLCUSDT 無法獲取風險金額，跳過檢查
2025-10-29T03:04:45.963949445Z [inf]  2025-10-29 03:04:45,961 - src.core.position_monitor_24x7 - WARNING - ⚠️ LINKUSDT 無法獲取風險金額，跳過檢查
2025-10-29T03:04:45.963955366Z [inf]  2025-10-29 03:04:45,961 - src.core.position_monitor_24x7 - WARNING - ⚠️ DYDXUSDT 無法獲取風險金額，跳過檢查
2025-10-29T03:04:47.971001506Z [inf]  2025-10-29 03:04:47,963 - src.core.position_monitor_24x7 - WARNING - ⚠️ FXSUSDT 無法獲取風險金額，跳過檢查
2025-10-29T03:04:47.971011606Z [inf]  2025-10-29 03:04:47,963 - src.core.position_monitor_24x7 - WARNING - ⚠️ LTCUSDT 無法獲取風險金額，跳過檢查
2025-10-29T03:04:47.971017310Z [inf]  2025-10-29 03:04:47,963 - src.core.position_monitor_24x7 - WARNING - ⚠️ RLCUSDT 無法獲取風險金額，跳過檢查
2025-10-29T03:04:47.971023145Z [inf]  2025-10-29 03:04:47,963 - src.core.position_monitor_24x7 - WARNING - ⚠️ LINKUSDT 無法獲取風險金額，跳過檢查
2025-10-29T03:04:47.971029294Z [inf]  2025-10-29 03:04:47,963 - src.core.position_monitor_24x7 - WARNING - ⚠️ DYDXUSDT 無法獲取風險金額，跳過檢查
2025-10-29T03:04:49.970769061Z [inf]  2025-10-29 03:04:49,965 - src.core.position_monitor_24x7 - WARNING - ⚠️ FXSUSDT 無法獲取風險金額，跳過檢查
2025-10-29T03:04:49.970775134Z [inf]  2025-10-29 03:04:49,966 - src.core.position_monitor_24x7 - WARNING - ⚠️ LTCUSDT 無法獲取風險金額，跳過檢查
2025-10-29T03:04:49.970780894Z [inf]  2025-10-29 03:04:49,966 - src.core.position_monitor_24x7 - WARNING - ⚠️ RLCUSDT 無法獲取風險金額，跳過檢查
2025-10-29T03:04:49.970786992Z [inf]  2025-10-29 03:04:49,966 - src.core.position_monitor_24x7 - WARNING - ⚠️ LINKUSDT 無法獲取風險金額，跳過檢查
2025-10-29T03:04:49.970792748Z [inf]  2025-10-29 03:04:49,966 - src.core.position_monitor_24x7 - WARNING - ⚠️ DYDXUSDT 無法獲取風險金額，跳過檢查
2025-10-29T03:04:51.971360152Z [inf]  2025-10-29 03:04:51,967 - src.core.position_monitor_24x7 - WARNING - ⚠️ FXSUSDT 無法獲取風險金額，跳過檢查
2025-10-29T03:04:51.971371483Z [inf]  2025-10-29 03:04:51,968 - src.core.position_monitor_24x7 - WARNING - ⚠️ LTCUSDT 無法獲取風險金額，跳過檢查
2025-10-29T03:04:51.971378024Z [inf]  2025-10-29 03:04:51,968 - src.core.position_monitor_24x7 - WARNING - ⚠️ RLCUSDT 無法獲取風險金額，跳過檢查
2025-10-29T03:04:51.971383583Z [inf]  2025-10-29 03:04:51,968 - src.core.position_monitor_24x7 - WARNING - ⚠️ LINKUSDT 無法獲取風險金額，跳過檢查
2025-10-29T03:04:51.971389087Z [inf]  2025-10-29 03:04:51,968 - src.core.position_monitor_24x7 - WARNING - ⚠️ DYDXUSDT 無法獲取風險金額，跳過檢查
2025-10-29T03:04:53.974115915Z [inf]  2025-10-29 03:04:53,971 - src.core.position_monitor_24x7 - WARNING - ⚠️ FXSUSDT 無法獲取風險金額，跳過檢查
2025-10-29T03:04:53.974130861Z [inf]  2025-10-29 03:04:53,971 - src.core.position_monitor_24x7 - WARNING - ⚠️ LTCUSDT 無法獲取風險金額，跳過檢查
2025-10-29T03:04:53.974138697Z [inf]  2025-10-29 03:04:53,971 - src.core.position_monitor_24x7 - WARNING - ⚠️ RLCUSDT 無法獲取風險金額，跳過檢查
2025-10-29T03:04:53.974145936Z [inf]  2025-10-29 03:04:53,971 - src.core.position_monitor_24x7 - WARNING - ⚠️ LINKUSDT 無法獲取風險金額，跳過檢查
2025-10-29T03:04:53.974154636Z [inf]  2025-10-29 03:04:53,971 - src.core.position_monitor_24x7 - WARNING - ⚠️ DYDXUSDT 無法獲取風險金額，跳過檢查
2025-10-29T03:04:54.470701993Z [inf]  2025-10-29 03:04:54,468 - src.clients.binance_client - ERROR - Binance API 錯誤 429: code=-1003, msg=Too many requests; current limit of IP(208.77.246.15) is 2400 requests per minute. Please use the websocket for live updates to avoid polling the API., endpoint=/fapi/v2/account, params={'timestamp': 1761707094394}
2025-10-29T03:04:54.470710788Z [inf]  2025-10-29 03:04:54,468 - src.core.circuit_breaker - WARNING - 🔄 熔斷器級別變化: normal → warning (失敗次數: 1)
2025-10-29T03:04:54.470716679Z [inf]  2025-10-29 03:04:54,468 - src.clients.binance_client - ERROR - API 請求失敗: /fapi/v2/account - HTTP 429: Too Many Requests
2025-10-29T03:04:54.473238425Z [inf]  2025-10-29 03:04:54,468 - src.core.position_controller - ERROR - ❌ 獲取持倉失敗: HTTP 429: Too Many Requests
2025-10-29T03:04:54.473252813Z [inf]  Traceback (most recent call last):
2025-10-29T03:04:54.473265727Z [inf]    File "/app/src/clients/binance_client.py", line 203, in _request
2025-10-29T03:04:54.473276341Z [inf]      result = await self.circuit_breaker.call_async(_do_request)
2025-10-29T03:04:54.473286618Z [inf]               ^^^^^^^^^^^^^^^^^^^^^^^^^^^^^^^^^^^^^^^^^^^^^^^^^^
2025-10-29T03:04:54.473294927Z [inf]    File "/app/src/core/circuit_breaker.py", line 339, in call_async
2025-10-29T03:04:54.473303264Z [inf]      raise e
2025-10-29T03:04:54.473310578Z [inf]    File "/app/src/core/circuit_breaker.py", line 334, in call_async
2025-10-29T03:04:54.473318271Z [inf]      result = await func(*args, **kwargs)
2025-10-29T03:04:54.473326322Z [inf]               ^^^^^^^^^^^^^^^^^^^^^^^^^^^
2025-10-29T03:04:54.473334094Z [inf]    File "/app/src/clients/binance_client.py", line 199, in _do_request
2025-10-29T03:04:54.473340745Z [inf]      response.raise_for_status()
2025-10-29T03:04:54.473348906Z [inf]    File "/opt/venv/lib/python3.11/site-packages/aiohttp/client_reqrep.py", line 636, in raise_for_status
2025-10-29T03:04:54.473355679Z [inf]      raise ClientResponseError(
2025-10-29T03:04:54.473362364Z [inf]  aiohttp.client_exceptions.ClientResponseError: 429, message='Too Many Requests', url='https://fapi.binance.com/fapi/v2/account?timestamp=1761707094394&signature=791e79c29bfd3206affc8e9a64ad4bb411317e9c774b16b9199b4689d55b6d79'
2025-10-29T03:04:54.473369169Z [inf]  
2025-10-29T03:04:54.473375043Z [inf]  During handling of the above exception, another exception occurred:
2025-10-29T03:04:54.473381896Z [inf]  
2025-10-29T03:04:54.473388541Z [inf]  Traceback (most recent call last):
2025-10-29T03:04:54.473395341Z [inf]    File "/app/src/core/position_controller.py", line 171, in _fetch_all_positions
2025-10-29T03:04:54.475180985Z [inf]      raw_positions = await self.binance_client.get_position_info_async()
2025-10-29T03:04:54.475190368Z [inf]                      ^^^^^^^^^^^^^^^^^^^^^^^^^^^^^^^^^^^^^^^^^^^^^^^^^^^
2025-10-29T03:04:54.475201234Z [inf]    File "/app/src/clients/binance_client.py", line 475, in get_position_info_async
2025-10-29T03:04:54.475208049Z [inf]      account_info = await self.get_account_info()
2025-10-29T03:04:54.475215657Z [inf]                     ^^^^^^^^^^^^^^^^^^^^^^^^^^^^^
2025-10-29T03:04:54.475221707Z [inf]    File "/app/src/clients/binance_client.py", line 455, in get_account_info
2025-10-29T03:04:54.475230541Z [inf]      result = await self._request("GET", "/fapi/v2/account", signed=True)
2025-10-29T03:04:54.475237084Z [inf]               ^^^^^^^^^^^^^^^^^^^^^^^^^^^^^^^^^^^^^^^^^^^^^^^^^^^^^^^^^^^
2025-10-29T03:04:54.475243141Z [inf]    File "/app/src/clients/binance_client.py", line 207, in _request
2025-10-29T03:04:54.475249448Z [inf]      raise BinanceRequestError(
2025-10-29T03:04:54.475256081Z [inf]  src.clients.binance_errors.BinanceRequestError: HTTP 429: Too Many Requests
2025-10-29T03:04:55.977787068Z [inf]  2025-10-29 03:04:55,973 - src.core.circuit_breaker - WARNING - ⚠️  熔斷器警告級: 失敗1次 (操作: generic, 優先級: NORMAL)
2025-10-29T03:04:56.051525995Z [inf]  2025-10-29 03:04:56,049 - src.clients.binance_client - ERROR - Binance API 錯誤 429: code=-1003, msg=Too many requests; current limit of IP(208.77.246.15) is 2400 requests per minute. Please use the websocket for live updates to avoid polling the API., endpoint=/fapi/v2/account, params={'timestamp': 1761707095973}
2025-10-29T03:04:56.051534450Z [inf]  2025-10-29 03:04:56,049 - src.clients.binance_client - ERROR - API 請求失敗: /fapi/v2/account - HTTP 429: Too Many Requests
2025-10-29T03:04:56.051544864Z [inf]  2025-10-29 03:04:56,049 - src.core.position_monitor_24x7 - ERROR - ❌ 獲取倉位失敗: HTTP 429: Too Many Requests
2025-10-29T03:04:56.497540908Z [inf]  2025-10-29 03:04:56,471 - src.core.circuit_breaker - WARNING - ⚠️  熔斷器警告級: 失敗2次 (操作: generic, 優先級: NORMAL)
2025-10-29T03:04:56.551260097Z [inf]  2025-10-29 03:04:56,548 - src.clients.binance_client - ERROR - Binance API 錯誤 429: code=-1003, msg=Too many requests; current limit of IP(208.77.246.15) is 2400 requests per minute. Please use the websocket for live updates to avoid polling the API., endpoint=/fapi/v2/account, params={'timestamp': 1761707096471}
2025-10-29T03:04:56.551272189Z [inf]  2025-10-29 03:04:56,548 - src.clients.binance_client - ERROR - API 請求失敗: /fapi/v2/account - HTTP 429: Too Many Requests
2025-10-29T03:04:56.552743555Z [inf]    File "/app/src/core/position_controller.py", line 171, in _fetch_all_positions
2025-10-29T03:04:56.552796195Z [inf]  2025-10-29 03:04:56,548 - src.core.position_controller - ERROR - ❌ 獲取持倉失敗: HTTP 429: Too Many Requests
2025-10-29T03:04:56.552916978Z [inf]  Traceback (most recent call last):
2025-10-29T03:04:56.552928343Z [inf]    File "/app/src/clients/binance_client.py", line 203, in _request
2025-10-29T03:04:56.552936300Z [inf]      result = await self.circuit_breaker.call_async(_do_request)
2025-10-29T03:04:56.552942141Z [inf]               ^^^^^^^^^^^^^^^^^^^^^^^^^^^^^^^^^^^^^^^^^^^^^^^^^^
2025-10-29T03:04:56.552948840Z [inf]    File "/app/src/core/circuit_breaker.py", line 339, in call_async
2025-10-29T03:04:56.552954358Z [inf]      raise e
2025-10-29T03:04:56.552959901Z [inf]    File "/app/src/core/circuit_breaker.py", line 334, in call_async
2025-10-29T03:04:56.552967039Z [inf]      result = await func(*args, **kwargs)
2025-10-29T03:04:56.552973286Z [inf]               ^^^^^^^^^^^^^^^^^^^^^^^^^^^
2025-10-29T03:04:56.552984617Z [inf]    File "/app/src/clients/binance_client.py", line 199, in _do_request
2025-10-29T03:04:56.552989648Z [inf]      response.raise_for_status()
2025-10-29T03:04:56.552996068Z [inf]    File "/opt/venv/lib/python3.11/site-packages/aiohttp/client_reqrep.py", line 636, in raise_for_status
2025-10-29T03:04:56.553001505Z [inf]      raise ClientResponseError(
2025-10-29T03:04:56.553007808Z [inf]  aiohttp.client_exceptions.ClientResponseError: 429, message='Too Many Requests', url='https://fapi.binance.com/fapi/v2/account?timestamp=1761707096471&signature=0ebb46ad2f8e4b06fdef77246283316bb4a0a76a64357c84333f8b537fec61ea'
2025-10-29T03:04:56.553014706Z [inf]  
2025-10-29T03:04:56.553021631Z [inf]  During handling of the above exception, another exception occurred:
2025-10-29T03:04:56.553029856Z [inf]  
2025-10-29T03:04:56.553036555Z [inf]  Traceback (most recent call last):
2025-10-29T03:04:56.553960836Z [inf]      raw_positions = await self.binance_client.get_position_info_async()
2025-10-29T03:04:56.553965799Z [inf]                      ^^^^^^^^^^^^^^^^^^^^^^^^^^^^^^^^^^^^^^^^^^^^^^^^^^^
2025-10-29T03:04:56.553970793Z [inf]    File "/app/src/clients/binance_client.py", line 475, in get_position_info_async
2025-10-29T03:04:56.553975681Z [inf]      account_info = await self.get_account_info()
2025-10-29T03:04:56.553980827Z [inf]                     ^^^^^^^^^^^^^^^^^^^^^^^^^^^^^
2025-10-29T03:04:56.553985580Z [inf]    File "/app/src/clients/binance_client.py", line 455, in get_account_info
2025-10-29T03:04:56.553989796Z [inf]      result = await self._request("GET", "/fapi/v2/account", signed=True)
2025-10-29T03:04:56.553994485Z [inf]               ^^^^^^^^^^^^^^^^^^^^^^^^^^^^^^^^^^^^^^^^^^^^^^^^^^^^^^^^^^^
2025-10-29T03:04:56.553998738Z [inf]    File "/app/src/clients/binance_client.py", line 207, in _request
2025-10-29T03:04:56.554004254Z [inf]      raise BinanceRequestError(
2025-10-29T03:04:56.554008532Z [inf]  src.clients.binance_errors.BinanceRequestError: HTTP 429: Too Many Requests
2025-10-29T03:04:58.054695389Z [inf]  2025-10-29 03:04:58,052 - src.core.circuit_breaker - WARNING - ⚠️  熔斷器警告級: 失敗3次 (操作: generic, 優先級: NORMAL)
2025-10-29T03:04:58.097880587Z [inf]  2025-10-29 03:04:58,095 - src.core.unified_scheduler - INFO - ================================================================================
2025-10-29T03:04:58.097891899Z [inf]  2025-10-29 03:04:58,095 - src.core.unified_scheduler - INFO - 🔄 交易週期 #540 | 2025-10-29 03:04:58 UTC
2025-10-29T03:04:58.097898759Z [inf]  2025-10-29 03:04:58,095 - src.core.unified_scheduler - INFO - ================================================================================
2025-10-29T03:04:58.097903855Z [inf]  2025-10-29 03:04:58,095 - src.core.circuit_breaker - WARNING - ⚠️  熔斷器警告級: 失敗3次 (操作: generic, 優先級: NORMAL)
2025-10-29T03:04:58.129765080Z [inf]  2025-10-29 03:04:58,127 - src.clients.binance_client - ERROR - Binance API 錯誤 429: code=-1003, msg=Too many requests; current limit of IP(208.77.246.15) is 2400 requests per minute. Please use the websocket for live updates to avoid polling the API., endpoint=/fapi/v2/account, params={'timestamp': 1761707098052}
2025-10-29T03:04:58.129793898Z [inf]  2025-10-29 03:04:58,127 - src.core.circuit_breaker - WARNING - 🔄 熔斷器級別變化: warning → throttled (失敗次數: 4)
2025-10-29T03:04:58.129803121Z [inf]  2025-10-29 03:04:58,127 - src.clients.binance_client - ERROR - API 請求失敗: /fapi/v2/account - HTTP 429: Too Many Requests
2025-10-29T03:04:58.129812432Z [inf]  2025-10-29 03:04:58,127 - src.core.position_monitor_24x7 - ERROR - ❌ 獲取倉位失敗: HTTP 429: Too Many Requests
2025-10-29T03:04:58.458330123Z [inf]    File "/app/src/clients/binance_client.py", line 203, in _request
2025-10-29T03:04:58.458340806Z [inf]  2025-10-29 03:04:58,185 - src.clients.binance_client - ERROR - Binance API 錯誤 429: code=-1003, msg=Too many requests; current limit of IP(208.77.246.15) is 2400 requests per minute. Please use the websocket for live updates to avoid polling the API., endpoint=/fapi/v2/account, params={'timestamp': 1761707098095}
2025-10-29T03:04:58.458342782Z [inf]      result = await self.circuit_breaker.call_async(_do_request)
2025-10-29T03:04:58.458351867Z [inf]               ^^^^^^^^^^^^^^^^^^^^^^^^^^^^^^^^^^^^^^^^^^^^^^^^^^
2025-10-29T03:04:58.458357221Z [inf]      raise Exception(reason)
2025-10-29T03:04:58.458363006Z [inf]    File "/app/src/core/circuit_breaker.py", line 327, in call_async
2025-10-29T03:04:58.458365485Z [inf]  2025-10-29 03:04:58,185 - src.core.circuit_breaker - WARNING - 🔄 熔斷器級別變化: throttled → blocked (失敗次數: 5)
2025-10-29T03:04:58.458366097Z [inf]  Exception: 熔斷器阻斷(失敗5次)，請60秒後重試
2025-10-29T03:04:58.458376836Z [inf]  2025-10-29 03:04:58,185 - src.clients.binance_client - ERROR - API 請求失敗: /fapi/v2/account - HTTP 429: Too Many Requests
2025-10-29T03:04:58.458382772Z [inf]  2025-10-29 03:04:58,185 - src.clients.binance_client - ERROR - API 請求失敗: /fapi/v2/account - 熔斷器阻斷(失敗5次)，請60秒後重試
2025-10-29T03:04:58.458385144Z [inf]  2025-10-29 03:04:58,185 - src.core.unified_scheduler - ERROR - ❌ 獲取持倉失敗: HTTP 429: Too Many Requests
2025-10-29T03:04:58.458393908Z [inf]  2025-10-29 03:04:58,185 - src.core.circuit_breaker - ERROR - 🔴 熔斷器阻斷(失敗5次)，請60秒後重試 | 操作: generic | 優先級: NORMAL
2025-10-29T03:04:58.458394037Z [inf]  2025-10-29 03:04:58,185 - src.core.unified_scheduler - ERROR - ❌ 交易週期執行失敗: 熔斷器阻斷(失敗5次)，請60秒後重試
2025-10-29T03:04:58.458402740Z [inf]  Traceback (most recent call last):
2025-10-29T03:04:58.459057352Z [inf]                     ^^^^^^^^^^^^^^^^^^^^^^^^^^^^^
2025-10-29T03:04:58.459059096Z [inf]    File "/app/src/clients/binance_client.py", line 219, in _request
2025-10-29T03:04:58.459067792Z [inf]    File "/app/src/clients/binance_client.py", line 455, in get_account_info
2025-10-29T03:04:58.459068073Z [inf]      raise BinanceRequestError(
2025-10-29T03:04:58.459077268Z [inf]  src.clients.binance_errors.BinanceRequestError: 熔斷器阻斷(失敗5次)，請60秒後重試
2025-10-29T03:04:58.459077586Z [inf]      result = await self._request("GET", "/fapi/v2/account", signed=True)
2025-10-29T03:04:58.459084934Z [inf]               ^^^^^^^^^^^^^^^^^^^^^^^^^^^^^^^^^^^^^^^^^^^^^^^^^^^^^^^^^^^
2025-10-29T03:04:58.459092452Z [inf]  During handling of the above exception, another exception occurred:
2025-10-29T03:04:58.459098663Z [inf]  
2025-10-29T03:04:58.459104373Z [inf]  Traceback (most recent call last):
2025-10-29T03:04:58.459125145Z [inf]    File "/app/src/core/unified_scheduler.py", line 227, in _execute_trading_cycle
2025-10-29T03:04:58.459130683Z [inf]      account_info = await self.binance_client.get_account_balance()
2025-10-29T03:04:58.459136693Z [inf]                     ^^^^^^^^^^^^^^^^^^^^^^^^^^^^^^^^^^^^^^^^^^^^^^^
2025-10-29T03:04:58.459142889Z [inf]    File "/app/src/clients/binance_client.py", line 491, in get_account_balance
2025-10-29T03:04:58.459149758Z [inf]  
2025-10-29T03:04:58.459150582Z [inf]      account_info = await self.get_account_info()
2025-10-29T03:04:58.554075377Z [inf]  2025-10-29 03:04:58,551 - src.core.circuit_breaker - ERROR - 🔴 熔斷器阻斷(失敗5次)，請60秒後重試 | 操作: generic | 優先級: NORMAL
2025-10-29T03:04:58.554078177Z [inf]      account_info = await self.get_account_info()
2025-10-29T03:04:58.554087029Z [inf]  2025-10-29 03:04:58,551 - src.clients.binance_client - ERROR - API 請求失敗: /fapi/v2/account - 熔斷器阻斷(失敗5次)，請60秒後重試
2025-10-29T03:04:58.554101702Z [inf]  2025-10-29 03:04:58,551 - src.core.position_controller - ERROR - ❌ 獲取持倉失敗: 熔斷器阻斷(失敗5次)，請60秒後重試
2025-10-29T03:04:58.554108830Z [inf]  Traceback (most recent call last):
2025-10-29T03:04:58.554116099Z [inf]    File "/app/src/clients/binance_client.py", line 203, in _request
2025-10-29T03:04:58.554123803Z [inf]      result = await self.circuit_breaker.call_async(_do_request)
2025-10-29T03:04:58.554131189Z [inf]               ^^^^^^^^^^^^^^^^^^^^^^^^^^^^^^^^^^^^^^^^^^^^^^^^^^
2025-10-29T03:04:58.554137603Z [inf]    File "/app/src/core/circuit_breaker.py", line 327, in call_async
2025-10-29T03:04:58.554145988Z [inf]      raise Exception(reason)
2025-10-29T03:04:58.554158413Z [inf]  Exception: 熔斷器阻斷(失敗5次)，請60秒後重試
2025-10-29T03:04:58.554165784Z [inf]  
2025-10-29T03:04:58.554171912Z [inf]  During handling of the above exception, another exception occurred:
2025-10-29T03:04:58.554177829Z [inf]  
2025-10-29T03:04:58.554184601Z [inf]  Traceback (most recent call last):
2025-10-29T03:04:58.554193282Z [inf]    File "/app/src/core/position_controller.py", line 171, in _fetch_all_positions
2025-10-29T03:04:58.554199436Z [inf]      raw_positions = await self.binance_client.get_position_info_async()
2025-10-29T03:04:58.554206138Z [inf]                      ^^^^^^^^^^^^^^^^^^^^^^^^^^^^^^^^^^^^^^^^^^^^^^^^^^^
2025-10-29T03:04:58.554212829Z [inf]    File "/app/src/clients/binance_client.py", line 475, in get_position_info_async
2025-10-29T03:04:58.555830915Z [inf]                     ^^^^^^^^^^^^^^^^^^^^^^^^^^^^^
2025-10-29T03:04:58.555836531Z [inf]    File "/app/src/clients/binance_client.py", line 455, in get_account_info
2025-10-29T03:04:58.555840482Z [inf]      result = await self._request("GET", "/fapi/v2/account", signed=True)
2025-10-29T03:04:58.555844811Z [inf]               ^^^^^^^^^^^^^^^^^^^^^^^^^^^^^^^^^^^^^^^^^^^^^^^^^^^^^^^^^^^
2025-10-29T03:04:58.555849150Z [inf]    File "/app/src/clients/binance_client.py", line 219, in _request
2025-10-29T03:04:58.555853643Z [inf]      raise BinanceRequestError(
2025-10-29T03:04:58.555858256Z [inf]  src.clients.binance_errors.BinanceRequestError: 熔斷器阻斷(失敗5次)，請60秒後重試
2025-10-29T03:05:00.133200972Z [inf]  2025-10-29 03:05:00,130 - src.core.circuit_breaker - ERROR - 🔴 熔斷器阻斷(失敗5次)，請58秒後重試 | 操作: generic | 優先級: NORMAL
2025-10-29T03:05:00.133209145Z [inf]  2025-10-29 03:05:00,130 - src.clients.binance_client - ERROR - API 請求失敗: /fapi/v2/account - 熔斷器阻斷(失敗5次)，請58秒後重試
2025-10-29T03:05:00.133215412Z [inf]  2025-10-29 03:05:00,130 - src.core.position_monitor_24x7 - ERROR - ❌ 獲取倉位失敗: 熔斷器阻斷(失敗5次)，請58秒後重試
2025-10-29T03:05:00.622020925Z [inf]    File "/app/src/core/circuit_breaker.py", line 327, in call_async
2025-10-29T03:05:00.622032717Z [inf]      raise Exception(reason)
2025-10-29T03:05:00.622040690Z [inf]  Exception: 熔斷器阻斷(失敗5次)，請58秒後重試
2025-10-29T03:05:00.622045331Z [inf]  2025-10-29 03:05:00,553 - src.core.circuit_breaker - ERROR - 🔴 熔斷器阻斷(失敗5次)，請58秒後重試 | 操作: generic | 優先級: NORMAL
2025-10-29T03:05:00.622052889Z [inf]  During handling of the above exception, another exception occurred:
2025-10-29T03:05:00.622053898Z [inf]  2025-10-29 03:05:00,553 - src.clients.binance_client - ERROR - API 請求失敗: /fapi/v2/account - 熔斷器阻斷(失敗5次)，請58秒後重試
2025-10-29T03:05:00.622054508Z [inf]  
2025-10-29T03:05:00.622061264Z [inf]  2025-10-29 03:05:00,553 - src.core.position_controller - ERROR - ❌ 獲取持倉失敗: 熔斷器阻斷(失敗5次)，請58秒後重試
2025-10-29T03:05:00.622067107Z [inf]  
2025-10-29T03:05:00.622078781Z [inf]  Traceback (most recent call last):
2025-10-29T03:05:00.622088383Z [inf]    File "/app/src/core/position_controller.py", line 171, in _fetch_all_positions
2025-10-29T03:05:00.622096245Z [inf]      raw_positions = await self.binance_client.get_position_info_async()
2025-10-29T03:05:00.622103855Z [inf]                      ^^^^^^^^^^^^^^^^^^^^^^^^^^^^^^^^^^^^^^^^^^^^^^^^^^^
2025-10-29T03:05:00.622111092Z [inf]    File "/app/src/clients/binance_client.py", line 475, in get_position_info_async
2025-10-29T03:05:00.622117780Z [inf]      account_info = await self.get_account_info()
2025-10-29T03:05:00.622186203Z [inf]  Traceback (most recent call last):
2025-10-29T03:05:00.622209898Z [inf]    File "/app/src/clients/binance_client.py", line 203, in _request
2025-10-29T03:05:00.622222274Z [inf]      result = await self.circuit_breaker.call_async(_do_request)
2025-10-29T03:05:00.622233087Z [inf]               ^^^^^^^^^^^^^^^^^^^^^^^^^^^^^^^^^^^^^^^^^^^^^^^^^^
2025-10-29T03:05:00.626953717Z [inf]                     ^^^^^^^^^^^^^^^^^^^^^^^^^^^^^
2025-10-29T03:05:00.626959070Z [inf]    File "/app/src/clients/binance_client.py", line 455, in get_account_info
2025-10-29T03:05:00.626964785Z [inf]      result = await self._request("GET", "/fapi/v2/account", signed=True)
2025-10-29T03:05:00.626969739Z [inf]               ^^^^^^^^^^^^^^^^^^^^^^^^^^^^^^^^^^^^^^^^^^^^^^^^^^^^^^^^^^^
2025-10-29T03:05:00.626975552Z [inf]    File "/app/src/clients/binance_client.py", line 219, in _request
2025-10-29T03:05:00.626981115Z [inf]      raise BinanceRequestError(
2025-10-29T03:05:00.626986433Z [inf]  src.clients.binance_errors.BinanceRequestError: 熔斷器阻斷(失敗5次)，請58秒後重試
2025-10-29T03:05:02.134181906Z [inf]  2025-10-29 03:05:02,132 - src.core.circuit_breaker - ERROR - 🔴 熔斷器阻斷(失敗5次)，請56秒後重試 | 操作: generic | 優先級: NORMAL
2025-10-29T03:05:02.134191216Z [inf]  2025-10-29 03:05:02,132 - src.clients.binance_client - ERROR - API 請求失敗: /fapi/v2/account - 熔斷器阻斷(失敗5次)，請56秒後重試
2025-10-29T03:05:02.134200406Z [inf]  2025-10-29 03:05:02,132 - src.core.position_monitor_24x7 - ERROR - ❌ 獲取倉位失敗: 熔斷器阻斷(失敗5次)，請56秒後重試
2025-10-29T03:05:02.559351220Z [inf]  2025-10-29 03:05:02,555 - src.core.circuit_breaker - ERROR - 🔴 熔斷器阻斷(失敗5次)，請56秒後重試 | 操作: generic | 優先級: NORMAL
2025-10-29T03:05:02.559360232Z [inf]  2025-10-29 03:05:02,555 - src.clients.binance_client - ERROR - API 請求失敗: /fapi/v2/account - 熔斷器阻斷(失敗5次)，請56秒後重試
2025-10-29T03:05:02.559365356Z [inf]  2025-10-29 03:05:02,555 - src.core.position_controller - ERROR - ❌ 獲取持倉失敗: 熔斷器阻斷(失敗5次)，請56秒後重試
2025-10-29T03:05:02.559370530Z [inf]  Traceback (most recent call last):
2025-10-29T03:05:02.559375943Z [inf]    File "/app/src/clients/binance_client.py", line 203, in _request
2025-10-29T03:05:02.559380521Z [inf]      result = await self.circuit_breaker.call_async(_do_request)
2025-10-29T03:05:02.559385769Z [inf]               ^^^^^^^^^^^^^^^^^^^^^^^^^^^^^^^^^^^^^^^^^^^^^^^^^^
2025-10-29T03:05:02.559391740Z [inf]    File "/app/src/core/circuit_breaker.py", line 327, in call_async
2025-10-29T03:05:02.559397474Z [inf]      raise Exception(reason)
2025-10-29T03:05:02.559403742Z [inf]  Exception: 熔斷器阻斷(失敗5次)，請56秒後重試
2025-10-29T03:05:02.559409961Z [inf]  
2025-10-29T03:05:02.559417717Z [inf]  During handling of the above exception, another exception occurred:
2025-10-29T03:05:02.559424804Z [inf]  
2025-10-29T03:05:02.559431434Z [inf]  Traceback (most recent call last):
2025-10-29T03:05:02.559437454Z [inf]    File "/app/src/core/position_controller.py", line 171, in _fetch_all_positions
2025-10-29T03:05:02.559445118Z [inf]      raw_positions = await self.binance_client.get_position_info_async()
2025-10-29T03:05:02.559452516Z [inf]                      ^^^^^^^^^^^^^^^^^^^^^^^^^^^^^^^^^^^^^^^^^^^^^^^^^^^
2025-10-29T03:05:02.559458017Z [inf]    File "/app/src/clients/binance_client.py", line 475, in get_position_info_async
2025-10-29T03:05:02.559463894Z [inf]      account_info = await self.get_account_info()
2025-10-29T03:05:02.563309175Z [inf]                     ^^^^^^^^^^^^^^^^^^^^^^^^^^^^^
2025-10-29T03:05:02.563314493Z [inf]    File "/app/src/clients/binance_client.py", line 455, in get_account_info
2025-10-29T03:05:02.563319924Z [inf]      result = await self._request("GET", "/fapi/v2/account", signed=True)
2025-10-29T03:05:02.563324934Z [inf]               ^^^^^^^^^^^^^^^^^^^^^^^^^^^^^^^^^^^^^^^^^^^^^^^^^^^^^^^^^^^
2025-10-29T03:05:02.563330228Z [inf]    File "/app/src/clients/binance_client.py", line 219, in _request
2025-10-29T03:05:02.563339118Z [inf]      raise BinanceRequestError(
2025-10-29T03:05:02.563344546Z [inf]  src.clients.binance_errors.BinanceRequestError: 熔斷器阻斷(失敗5次)，請56秒後重試
2025-10-29T03:05:04.136924755Z [inf]  2025-10-29 03:05:04,134 - src.core.circuit_breaker - ERROR - 🔴 熔斷器阻斷(失敗5次)，請54秒後重試 | 操作: generic | 優先級: NORMAL
2025-10-29T03:05:04.136933014Z [inf]  2025-10-29 03:05:04,135 - src.clients.binance_client - ERROR - API 請求失敗: /fapi/v2/account - 熔斷器阻斷(失敗5次)，請54秒後重試
2025-10-29T03:05:04.136940211Z [inf]  2025-10-29 03:05:04,135 - src.core.position_monitor_24x7 - ERROR - ❌ 獲取倉位失敗: 熔斷器阻斷(失敗5次)，請54秒後重試
2025-10-29T03:05:04.559585112Z [inf]  2025-10-29 03:05:04,556 - src.core.circuit_breaker - ERROR - 🔴 熔斷器阻斷(失敗5次)，請54秒後重試 | 操作: generic | 優先級: NORMAL
2025-10-29T03:05:04.559596957Z [inf]  2025-10-29 03:05:04,556 - src.clients.binance_client - ERROR - API 請求失敗: /fapi/v2/account - 熔斷器阻斷(失敗5次)，請54秒後重試
2025-10-29T03:05:04.559604438Z [inf]  2025-10-29 03:05:04,557 - src.core.position_controller - ERROR - ❌ 獲取持倉失敗: 熔斷器阻斷(失敗5次)，請54秒後重試
2025-10-29T03:05:04.559615237Z [inf]  Traceback (most recent call last):
2025-10-29T03:05:04.559623874Z [inf]    File "/app/src/clients/binance_client.py", line 203, in _request
2025-10-29T03:05:04.559631511Z [inf]      result = await self.circuit_breaker.call_async(_do_request)
2025-10-29T03:05:04.559640130Z [inf]               ^^^^^^^^^^^^^^^^^^^^^^^^^^^^^^^^^^^^^^^^^^^^^^^^^^
2025-10-29T03:05:04.559646976Z [inf]    File "/app/src/core/circuit_breaker.py", line 327, in call_async
2025-10-29T03:05:04.559653469Z [inf]      raise Exception(reason)
2025-10-29T03:05:04.559660849Z [inf]  Exception: 熔斷器阻斷(失敗5次)，請54秒後重試
2025-10-29T03:05:04.559667103Z [inf]  
2025-10-29T03:05:04.559673669Z [inf]  During handling of the above exception, another exception occurred:
2025-10-29T03:05:04.559680223Z [inf]  
2025-10-29T03:05:04.559686491Z [inf]  Traceback (most recent call last):
2025-10-29T03:05:04.559692746Z [inf]    File "/app/src/core/position_controller.py", line 171, in _fetch_all_positions
2025-10-29T03:05:04.559700873Z [inf]      raw_positions = await self.binance_client.get_position_info_async()
2025-10-29T03:05:04.559707658Z [inf]                      ^^^^^^^^^^^^^^^^^^^^^^^^^^^^^^^^^^^^^^^^^^^^^^^^^^^
2025-10-29T03:05:04.559714812Z [inf]    File "/app/src/clients/binance_client.py", line 475, in get_position_info_async
2025-10-29T03:05:04.559720948Z [inf]      account_info = await self.get_account_info()
2025-10-29T03:05:04.560569132Z [inf]                     ^^^^^^^^^^^^^^^^^^^^^^^^^^^^^
2025-10-29T03:05:04.560584278Z [inf]    File "/app/src/clients/binance_client.py", line 455, in get_account_info
2025-10-29T03:05:04.560593034Z [inf]      result = await self._request("GET", "/fapi/v2/account", signed=True)
2025-10-29T03:05:04.560602027Z [inf]               ^^^^^^^^^^^^^^^^^^^^^^^^^^^^^^^^^^^^^^^^^^^^^^^^^^^^^^^^^^^
2025-10-29T03:05:04.560609735Z [inf]    File "/app/src/clients/binance_client.py", line 219, in _request
2025-10-29T03:05:04.560617613Z [inf]      raise BinanceRequestError(
2025-10-29T03:05:04.560629582Z [inf]  src.clients.binance_errors.BinanceRequestError: 熔斷器阻斷(失敗5次)，請54秒後重試
2025-10-29T03:05:06.520613867Z [inf]  2025-10-29 03:05:06,137 - src.core.circuit_breaker - ERROR - 🔴 熔斷器阻斷(失敗5次)，請52秒後重試 | 操作: generic | 優先級: NORMAL
2025-10-29T03:05:06.520621431Z [inf]  2025-10-29 03:05:06,137 - src.clients.binance_client - ERROR - API 請求失敗: /fapi/v2/account - 熔斷器阻斷(失敗5次)，請52秒後重試
2025-10-29T03:05:06.520628036Z [inf]  2025-10-29 03:05:06,137 - src.core.position_monitor_24x7 - ERROR - ❌ 獲取倉位失敗: 熔斷器阻斷(失敗5次)，請52秒後重試
2025-10-29T03:05:06.563257905Z [inf]  2025-10-29 03:05:06,558 - src.core.circuit_breaker - ERROR - 🔴 熔斷器阻斷(失敗5次)，請52秒後重試 | 操作: generic | 優先級: NORMAL
2025-10-29T03:05:06.563267970Z [inf]  2025-10-29 03:05:06,559 - src.clients.binance_client - ERROR - API 請求失敗: /fapi/v2/account - 熔斷器阻斷(失敗5次)，請52秒後重試
2025-10-29T03:05:06.563274902Z [inf]  2025-10-29 03:05:06,559 - src.core.position_controller - ERROR - ❌ 獲取持倉失敗: 熔斷器阻斷(失敗5次)，請52秒後重試
2025-10-29T03:05:06.563282099Z [inf]  Traceback (most recent call last):
2025-10-29T03:05:06.563289188Z [inf]    File "/app/src/clients/binance_client.py", line 203, in _request
2025-10-29T03:05:06.563296136Z [inf]      result = await self.circuit_breaker.call_async(_do_request)
2025-10-29T03:05:06.563303686Z [inf]               ^^^^^^^^^^^^^^^^^^^^^^^^^^^^^^^^^^^^^^^^^^^^^^^^^^
2025-10-29T03:05:06.563313218Z [inf]    File "/app/src/core/circuit_breaker.py", line 327, in call_async
2025-10-29T03:05:06.563319941Z [inf]      raise Exception(reason)
2025-10-29T03:05:06.563326492Z [inf]  Exception: 熔斷器阻斷(失敗5次)，請52秒後重試
2025-10-29T03:05:06.563333420Z [inf]  
2025-10-29T03:05:06.563339166Z [inf]  During handling of the above exception, another exception occurred:
2025-10-29T03:05:06.563345329Z [inf]  
2025-10-29T03:05:06.563351800Z [inf]  Traceback (most recent call last):
2025-10-29T03:05:06.563358772Z [inf]    File "/app/src/core/position_controller.py", line 171, in _fetch_all_positions
2025-10-29T03:05:06.563365025Z [inf]      raw_positions = await self.binance_client.get_position_info_async()
2025-10-29T03:05:06.563371194Z [inf]                      ^^^^^^^^^^^^^^^^^^^^^^^^^^^^^^^^^^^^^^^^^^^^^^^^^^^
2025-10-29T03:05:06.563377502Z [inf]    File "/app/src/clients/binance_client.py", line 475, in get_position_info_async
2025-10-29T03:05:06.563383827Z [inf]      account_info = await self.get_account_info()
2025-10-29T03:05:06.565600024Z [inf]      result = await self._request("GET", "/fapi/v2/account", signed=True)
2025-10-29T03:05:06.565611878Z [inf]                     ^^^^^^^^^^^^^^^^^^^^^^^^^^^^^
2025-10-29T03:05:06.565612903Z [inf]               ^^^^^^^^^^^^^^^^^^^^^^^^^^^^^^^^^^^^^^^^^^^^^^^^^^^^^^^^^^^
2025-10-29T03:05:06.565621970Z [inf]  src.clients.binance_errors.BinanceRequestError: 熔斷器阻斷(失敗5次)，請52秒後重試
2025-10-29T03:05:06.565623020Z [inf]    File "/app/src/clients/binance_client.py", line 219, in _request
2025-10-29T03:05:06.565626644Z [inf]    File "/app/src/clients/binance_client.py", line 455, in get_account_info
2025-10-29T03:05:06.565631354Z [inf]      raise BinanceRequestError(
2025-10-29T03:05:08.518236620Z [inf]  2025-10-29 03:05:08,140 - src.core.circuit_breaker - ERROR - 🔴 熔斷器阻斷(失敗5次)，請50秒後重試 | 操作: generic | 優先級: NORMAL
2025-10-29T03:05:08.518243968Z [inf]  2025-10-29 03:05:08,140 - src.clients.binance_client - ERROR - API 請求失敗: /fapi/v2/account - 熔斷器阻斷(失敗5次)，請50秒後重試
2025-10-29T03:05:08.518273745Z [inf]  2025-10-29 03:05:08,140 - src.core.position_monitor_24x7 - ERROR - ❌ 獲取倉位失敗: 熔斷器阻斷(失敗5次)，請50秒後重試
2025-10-29T03:05:08.564402437Z [inf]      account_info = await self.get_account_info()
2025-10-29T03:05:08.564423756Z [inf]  2025-10-29 03:05:08,560 - src.core.circuit_breaker - ERROR - 🔴 熔斷器阻斷(失敗5次)，請50秒後重試 | 操作: generic | 優先級: NORMAL
2025-10-29T03:05:08.564430420Z [inf]  2025-10-29 03:05:08,560 - src.clients.binance_client - ERROR - API 請求失敗: /fapi/v2/account - 熔斷器阻斷(失敗5次)，請50秒後重試
2025-10-29T03:05:08.564437698Z [inf]  2025-10-29 03:05:08,560 - src.core.position_controller - ERROR - ❌ 獲取持倉失敗: 熔斷器阻斷(失敗5次)，請50秒後重試
2025-10-29T03:05:08.564444540Z [inf]  Traceback (most recent call last):
2025-10-29T03:05:08.564451618Z [inf]    File "/app/src/clients/binance_client.py", line 203, in _request
2025-10-29T03:05:08.564457603Z [inf]      result = await self.circuit_breaker.call_async(_do_request)
2025-10-29T03:05:08.564463337Z [inf]               ^^^^^^^^^^^^^^^^^^^^^^^^^^^^^^^^^^^^^^^^^^^^^^^^^^
2025-10-29T03:05:08.564469882Z [inf]    File "/app/src/core/circuit_breaker.py", line 327, in call_async
2025-10-29T03:05:08.564476189Z [inf]      raise Exception(reason)
2025-10-29T03:05:08.564482320Z [inf]  Exception: 熔斷器阻斷(失敗5次)，請50秒後重試
2025-10-29T03:05:08.564486820Z [inf]  
2025-10-29T03:05:08.564492085Z [inf]  During handling of the above exception, another exception occurred:
2025-10-29T03:05:08.564497228Z [inf]  
2025-10-29T03:05:08.564503617Z [inf]  Traceback (most recent call last):
2025-10-29T03:05:08.564508003Z [inf]    File "/app/src/core/position_controller.py", line 171, in _fetch_all_positions
2025-10-29T03:05:08.564512212Z [inf]      raw_positions = await self.binance_client.get_position_info_async()
2025-10-29T03:05:08.564516710Z [inf]                      ^^^^^^^^^^^^^^^^^^^^^^^^^^^^^^^^^^^^^^^^^^^^^^^^^^^
2025-10-29T03:05:08.564521540Z [inf]    File "/app/src/clients/binance_client.py", line 475, in get_position_info_async
2025-10-29T03:05:08.567193496Z [inf]                     ^^^^^^^^^^^^^^^^^^^^^^^^^^^^^
2025-10-29T03:05:08.567199424Z [inf]    File "/app/src/clients/binance_client.py", line 455, in get_account_info
2025-10-29T03:05:08.567204967Z [inf]      result = await self._request("GET", "/fapi/v2/account", signed=True)
2025-10-29T03:05:08.567211135Z [inf]               ^^^^^^^^^^^^^^^^^^^^^^^^^^^^^^^^^^^^^^^^^^^^^^^^^^^^^^^^^^^
2025-10-29T03:05:08.567215957Z [inf]    File "/app/src/clients/binance_client.py", line 219, in _request
2025-10-29T03:05:08.567222620Z [inf]      raise BinanceRequestError(
2025-10-29T03:05:08.567228781Z [inf]  src.clients.binance_errors.BinanceRequestError: 熔斷器阻斷(失敗5次)，請50秒後重試
2025-10-29T03:05:10.515965330Z [inf]  2025-10-29 03:05:10,143 - src.core.circuit_breaker - ERROR - 🔴 熔斷器阻斷(失敗5次)，請48秒後重試 | 操作: generic | 優先級: NORMAL
2025-10-29T03:05:10.515972905Z [inf]  2025-10-29 03:05:10,143 - src.clients.binance_client - ERROR - API 請求失敗: /fapi/v2/account - 熔斷器阻斷(失敗5次)，請48秒後重試
2025-10-29T03:05:10.515978949Z [inf]  2025-10-29 03:05:10,143 - src.core.position_monitor_24x7 - ERROR - ❌ 獲取倉位失敗: 熔斷器阻斷(失敗5次)，請48秒後重試
2025-10-29T03:05:10.564565130Z [inf]      raw_positions = await self.binance_client.get_position_info_async()
2025-10-29T03:05:10.564573860Z [inf]                      ^^^^^^^^^^^^^^^^^^^^^^^^^^^^^^^^^^^^^^^^^^^^^^^^^^^
2025-10-29T03:05:10.564579590Z [inf]    File "/app/src/clients/binance_client.py", line 475, in get_position_info_async
2025-10-29T03:05:10.564588938Z [inf]      account_info = await self.get_account_info()
2025-10-29T03:05:10.564590534Z [inf]  2025-10-29 03:05:10,562 - src.core.circuit_breaker - ERROR - 🔴 熔斷器阻斷(失敗5次)，請48秒後重試 | 操作: generic | 優先級: NORMAL
2025-10-29T03:05:10.564599661Z [inf]  2025-10-29 03:05:10,562 - src.clients.binance_client - ERROR - API 請求失敗: /fapi/v2/account - 熔斷器阻斷(失敗5次)，請48秒後重試
2025-10-29T03:05:10.564605138Z [inf]  2025-10-29 03:05:10,562 - src.core.position_controller - ERROR - ❌ 獲取持倉失敗: 熔斷器阻斷(失敗5次)，請48秒後重試
2025-10-29T03:05:10.564610238Z [inf]  Traceback (most recent call last):
2025-10-29T03:05:10.564615226Z [inf]    File "/app/src/clients/binance_client.py", line 203, in _request
2025-10-29T03:05:10.564619767Z [inf]      result = await self.circuit_breaker.call_async(_do_request)
2025-10-29T03:05:10.564625464Z [inf]               ^^^^^^^^^^^^^^^^^^^^^^^^^^^^^^^^^^^^^^^^^^^^^^^^^^
2025-10-29T03:05:10.564630622Z [inf]    File "/app/src/core/circuit_breaker.py", line 327, in call_async
2025-10-29T03:05:10.564636199Z [inf]      raise Exception(reason)
2025-10-29T03:05:10.564640832Z [inf]  Exception: 熔斷器阻斷(失敗5次)，請48秒後重試
2025-10-29T03:05:10.564645295Z [inf]  
2025-10-29T03:05:10.564649773Z [inf]  During handling of the above exception, another exception occurred:
2025-10-29T03:05:10.564655786Z [inf]  
2025-10-29T03:05:10.564660377Z [inf]  Traceback (most recent call last):
2025-10-29T03:05:10.564665537Z [inf]    File "/app/src/core/position_controller.py", line 171, in _fetch_all_positions
2025-10-29T03:05:10.566937002Z [inf]                     ^^^^^^^^^^^^^^^^^^^^^^^^^^^^^
2025-10-29T03:05:10.566948490Z [inf]    File "/app/src/clients/binance_client.py", line 455, in get_account_info
2025-10-29T03:05:10.566954863Z [inf]      result = await self._request("GET", "/fapi/v2/account", signed=True)
2025-10-29T03:05:10.566961117Z [inf]               ^^^^^^^^^^^^^^^^^^^^^^^^^^^^^^^^^^^^^^^^^^^^^^^^^^^^^^^^^^^
2025-10-29T03:05:10.566971838Z [inf]    File "/app/src/clients/binance_client.py", line 219, in _request
2025-10-29T03:05:10.566983604Z [inf]      raise BinanceRequestError(
2025-10-29T03:05:10.566992955Z [inf]  src.clients.binance_errors.BinanceRequestError: 熔斷器阻斷(失敗5次)，請48秒後重試
2025-10-29T03:05:12.506053723Z [inf]  2025-10-29 03:05:12,145 - src.core.circuit_breaker - ERROR - 🔴 熔斷器阻斷(失敗5次)，請46秒後重試 | 操作: generic | 優先級: NORMAL
2025-10-29T03:05:12.506062865Z [inf]  2025-10-29 03:05:12,145 - src.clients.binance_client - ERROR - API 請求失敗: /fapi/v2/account - 熔斷器阻斷(失敗5次)，請46秒後重試
2025-10-29T03:05:12.506071765Z [inf]  2025-10-29 03:05:12,145 - src.core.position_monitor_24x7 - ERROR - ❌ 獲取倉位失敗: 熔斷器阻斷(失敗5次)，請46秒後重試
2025-10-29T03:05:12.565986082Z [inf]  2025-10-29 03:05:12,564 - src.core.circuit_breaker - ERROR - 🔴 熔斷器阻斷(失敗5次)，請46秒後重試 | 操作: generic | 優先級: NORMAL
2025-10-29T03:05:12.565998320Z [inf]  2025-10-29 03:05:12,564 - src.clients.binance_client - ERROR - API 請求失敗: /fapi/v2/account - 熔斷器阻斷(失敗5次)，請46秒後重試
2025-10-29T03:05:12.568607996Z [inf]      account_info = await self.get_account_info()
2025-10-29T03:05:12.568617281Z [inf]  2025-10-29 03:05:12,564 - src.core.position_controller - ERROR - ❌ 獲取持倉失敗: 熔斷器阻斷(失敗5次)，請46秒後重試
2025-10-29T03:05:12.568623422Z [inf]                     ^^^^^^^^^^^^^^^^^^^^^^^^^^^^^
2025-10-29T03:05:12.568630499Z [inf]  Traceback (most recent call last):
2025-10-29T03:05:12.568635038Z [inf]    File "/app/src/clients/binance_client.py", line 455, in get_account_info
2025-10-29T03:05:12.568642664Z [inf]    File "/app/src/clients/binance_client.py", line 203, in _request
2025-10-29T03:05:12.568645296Z [inf]      result = await self._request("GET", "/fapi/v2/account", signed=True)
2025-10-29T03:05:12.568652357Z [inf]      result = await self.circuit_breaker.call_async(_do_request)
2025-10-29T03:05:12.568660171Z [inf]               ^^^^^^^^^^^^^^^^^^^^^^^^^^^^^^^^^^^^^^^^^^^^^^^^^^
2025-10-29T03:05:12.568671389Z [inf]    File "/app/src/core/circuit_breaker.py", line 327, in call_async
2025-10-29T03:05:12.568678804Z [inf]      raise Exception(reason)
2025-10-29T03:05:12.568686318Z [inf]  Exception: 熔斷器阻斷(失敗5次)，請46秒後重試
2025-10-29T03:05:12.568694705Z [inf]  
2025-10-29T03:05:12.568703805Z [inf]  During handling of the above exception, another exception occurred:
2025-10-29T03:05:12.568712171Z [inf]  
2025-10-29T03:05:12.568719115Z [inf]  Traceback (most recent call last):
2025-10-29T03:05:12.568727906Z [inf]    File "/app/src/core/position_controller.py", line 171, in _fetch_all_positions
2025-10-29T03:05:12.568736594Z [inf]      raw_positions = await self.binance_client.get_position_info_async()
2025-10-29T03:05:12.568746886Z [inf]                      ^^^^^^^^^^^^^^^^^^^^^^^^^^^^^^^^^^^^^^^^^^^^^^^^^^^
2025-10-29T03:05:12.568755319Z [inf]    File "/app/src/clients/binance_client.py", line 475, in get_position_info_async
2025-10-29T03:05:12.570555343Z [inf]               ^^^^^^^^^^^^^^^^^^^^^^^^^^^^^^^^^^^^^^^^^^^^^^^^^^^^^^^^^^^
2025-10-29T03:05:12.570567446Z [inf]    File "/app/src/clients/binance_client.py", line 219, in _request
2025-10-29T03:05:12.570574090Z [inf]      raise BinanceRequestError(
2025-10-29T03:05:12.570582669Z [inf]  src.clients.binance_errors.BinanceRequestError: 熔斷器阻斷(失敗5次)，請46秒後重試
2025-10-29T03:05:14.556442394Z [inf]  2025-10-29 03:05:14,146 - src.core.circuit_breaker - ERROR - 🔴 熔斷器阻斷(失敗5次)，請44秒後重試 | 操作: generic | 優先級: NORMAL
2025-10-29T03:05:14.556449419Z [inf]  2025-10-29 03:05:14,146 - src.clients.binance_client - ERROR - API 請求失敗: /fapi/v2/account - 熔斷器阻斷(失敗5次)，請44秒後重試
2025-10-29T03:05:14.556455892Z [inf]  2025-10-29 03:05:14,146 - src.core.position_monitor_24x7 - ERROR - ❌ 獲取倉位失敗: 熔斷器阻斷(失敗5次)，請44秒後重試
2025-10-29T03:05:14.571744127Z [inf]  2025-10-29 03:05:14,567 - src.core.circuit_breaker - ERROR - 🔴 熔斷器阻斷(失敗5次)，請44秒後重試 | 操作: generic | 優先級: NORMAL
2025-10-29T03:05:14.571745668Z [inf]  
2025-10-29T03:05:14.571751627Z [inf]  2025-10-29 03:05:14,567 - src.clients.binance_client - ERROR - API 請求失敗: /fapi/v2/account - 熔斷器阻斷(失敗5次)，請44秒後重試
2025-10-29T03:05:14.571758557Z [inf]  2025-10-29 03:05:14,567 - src.core.position_controller - ERROR - ❌ 獲取持倉失敗: 熔斷器阻斷(失敗5次)，請44秒後重試
2025-10-29T03:05:14.571760241Z [inf]  Traceback (most recent call last):
2025-10-29T03:05:14.571764905Z [inf]  Traceback (most recent call last):
2025-10-29T03:05:14.571770182Z [inf]    File "/app/src/core/position_controller.py", line 171, in _fetch_all_positions
2025-10-29T03:05:14.571770946Z [inf]    File "/app/src/clients/binance_client.py", line 203, in _request
2025-10-29T03:05:14.571776714Z [inf]      result = await self.circuit_breaker.call_async(_do_request)
2025-10-29T03:05:14.571780245Z [inf]      raw_positions = await self.binance_client.get_position_info_async()
2025-10-29T03:05:14.571783079Z [inf]               ^^^^^^^^^^^^^^^^^^^^^^^^^^^^^^^^^^^^^^^^^^^^^^^^^^
2025-10-29T03:05:14.571788929Z [inf]                      ^^^^^^^^^^^^^^^^^^^^^^^^^^^^^^^^^^^^^^^^^^^^^^^^^^^
2025-10-29T03:05:14.571789496Z [inf]    File "/app/src/core/circuit_breaker.py", line 327, in call_async
2025-10-29T03:05:14.571795963Z [inf]      raise Exception(reason)
2025-10-29T03:05:14.571797975Z [inf]    File "/app/src/clients/binance_client.py", line 475, in get_position_info_async
2025-10-29T03:05:14.571802098Z [inf]  Exception: 熔斷器阻斷(失敗5次)，請44秒後重試
2025-10-29T03:05:14.571806611Z [inf]      account_info = await self.get_account_info()
2025-10-29T03:05:14.571809593Z [inf]  
2025-10-29T03:05:14.571814752Z [inf]  During handling of the above exception, another exception occurred:
2025-10-29T03:05:14.574945867Z [inf]                     ^^^^^^^^^^^^^^^^^^^^^^^^^^^^^
2025-10-29T03:05:14.574954265Z [inf]    File "/app/src/clients/binance_client.py", line 455, in get_account_info
2025-10-29T03:05:14.574961503Z [inf]      result = await self._request("GET", "/fapi/v2/account", signed=True)
2025-10-29T03:05:14.574969401Z [inf]               ^^^^^^^^^^^^^^^^^^^^^^^^^^^^^^^^^^^^^^^^^^^^^^^^^^^^^^^^^^^
2025-10-29T03:05:14.574977845Z [inf]    File "/app/src/clients/binance_client.py", line 219, in _request
2025-10-29T03:05:14.574984475Z [inf]      raise BinanceRequestError(
2025-10-29T03:05:14.574991254Z [inf]  src.clients.binance_errors.BinanceRequestError: 熔斷器阻斷(失敗5次)，請44秒後重試
2025-10-29T03:05:16.523671065Z [inf]  2025-10-29 03:05:16,149 - src.core.circuit_breaker - ERROR - 🔴 熔斷器阻斷(失敗5次)，請42秒後重試 | 操作: generic | 優先級: NORMAL
2025-10-29T03:05:16.523676167Z [inf]  2025-10-29 03:05:16,149 - src.clients.binance_client - ERROR - API 請求失敗: /fapi/v2/account - 熔斷器阻斷(失敗5次)，請42秒後重試
2025-10-29T03:05:16.523680287Z [inf]  2025-10-29 03:05:16,149 - src.core.position_monitor_24x7 - ERROR - ❌ 獲取倉位失敗: 熔斷器阻斷(失敗5次)，請42秒後重試
2025-10-29T03:05:16.572266899Z [inf]  
2025-10-29T03:05:16.572277074Z [inf]  Traceback (most recent call last):
2025-10-29T03:05:16.572283875Z [inf]    File "/app/src/core/position_controller.py", line 171, in _fetch_all_positions
2025-10-29T03:05:16.572289858Z [inf]      raw_positions = await self.binance_client.get_position_info_async()
2025-10-29T03:05:16.572296609Z [inf]  2025-10-29 03:05:16,569 - src.core.circuit_breaker - ERROR - 🔴 熔斷器阻斷(失敗5次)，請42秒後重試 | 操作: generic | 優先級: NORMAL
2025-10-29T03:05:16.572297002Z [inf]                      ^^^^^^^^^^^^^^^^^^^^^^^^^^^^^^^^^^^^^^^^^^^^^^^^^^^
2025-10-29T03:05:16.572303598Z [inf]    File "/app/src/clients/binance_client.py", line 475, in get_position_info_async
2025-10-29T03:05:16.572307909Z [inf]  2025-10-29 03:05:16,569 - src.clients.binance_client - ERROR - API 請求失敗: /fapi/v2/account - 熔斷器阻斷(失敗5次)，請42秒後重試
2025-10-29T03:05:16.572310464Z [inf]      account_info = await self.get_account_info()
2025-10-29T03:05:16.572316576Z [inf]  2025-10-29 03:05:16,569 - src.core.position_controller - ERROR - ❌ 獲取持倉失敗: 熔斷器阻斷(失敗5次)，請42秒後重試
2025-10-29T03:05:16.572322395Z [inf]  Traceback (most recent call last):
2025-10-29T03:05:16.572328006Z [inf]    File "/app/src/clients/binance_client.py", line 203, in _request
2025-10-29T03:05:16.572335121Z [inf]      result = await self.circuit_breaker.call_async(_do_request)
2025-10-29T03:05:16.572342755Z [inf]               ^^^^^^^^^^^^^^^^^^^^^^^^^^^^^^^^^^^^^^^^^^^^^^^^^^
2025-10-29T03:05:16.572350973Z [inf]    File "/app/src/core/circuit_breaker.py", line 327, in call_async
2025-10-29T03:05:16.572358429Z [inf]      raise Exception(reason)
2025-10-29T03:05:16.572366044Z [inf]  Exception: 熔斷器阻斷(失敗5次)，請42秒後重試
2025-10-29T03:05:16.572372316Z [inf]  
2025-10-29T03:05:16.572379947Z [inf]  During handling of the above exception, another exception occurred:
2025-10-29T03:05:16.574302612Z [inf]                     ^^^^^^^^^^^^^^^^^^^^^^^^^^^^^
2025-10-29T03:05:16.574310055Z [inf]    File "/app/src/clients/binance_client.py", line 455, in get_account_info
2025-10-29T03:05:16.574316512Z [inf]      result = await self._request("GET", "/fapi/v2/account", signed=True)
2025-10-29T03:05:16.574321068Z [inf]               ^^^^^^^^^^^^^^^^^^^^^^^^^^^^^^^^^^^^^^^^^^^^^^^^^^^^^^^^^^^
2025-10-29T03:05:16.574326323Z [inf]    File "/app/src/clients/binance_client.py", line 219, in _request
2025-10-29T03:05:16.574331931Z [inf]      raise BinanceRequestError(
2025-10-29T03:05:16.574337084Z [inf]  src.clients.binance_errors.BinanceRequestError: 熔斷器阻斷(失敗5次)，請42秒後重試
2025-10-29T03:05:18.464410171Z [inf]  2025-10-29 03:05:18,150 - src.core.position_monitor_24x7 - ERROR - ❌ 獲取倉位失敗: 熔斷器阻斷(失敗5次)，請40秒後重試
2025-10-29T03:05:18.464539086Z [inf]  2025-10-29 03:05:18,150 - src.core.circuit_breaker - ERROR - 🔴 熔斷器阻斷(失敗5次)，請40秒後重試 | 操作: generic | 優先級: NORMAL
2025-10-29T03:05:18.464547424Z [inf]  2025-10-29 03:05:18,150 - src.clients.binance_client - ERROR - API 請求失敗: /fapi/v2/account - 熔斷器阻斷(失敗5次)，請40秒後重試
2025-10-29T03:05:18.578209201Z [inf]  
2025-10-29T03:05:18.578223692Z [inf]  During handling of the above exception, another exception occurred:
2025-10-29T03:05:18.578232317Z [inf]  2025-10-29 03:05:18,571 - src.core.circuit_breaker - ERROR - 🔴 熔斷器阻斷(失敗5次)，請40秒後重試 | 操作: generic | 優先級: NORMAL
2025-10-29T03:05:18.578236384Z [inf]  
2025-10-29T03:05:18.578247664Z [inf]  Traceback (most recent call last):
2025-10-29T03:05:18.578250986Z [inf]  2025-10-29 03:05:18,571 - src.clients.binance_client - ERROR - API 請求失敗: /fapi/v2/account - 熔斷器阻斷(失敗5次)，請40秒後重試
2025-10-29T03:05:18.578257300Z [inf]    File "/app/src/core/position_controller.py", line 171, in _fetch_all_positions
2025-10-29T03:05:18.578265238Z [inf]  2025-10-29 03:05:18,572 - src.core.position_controller - ERROR - ❌ 獲取持倉失敗: 熔斷器阻斷(失敗5次)，請40秒後重試
2025-10-29T03:05:18.578273377Z [inf]      raw_positions = await self.binance_client.get_position_info_async()
2025-10-29T03:05:18.578283542Z [inf]                      ^^^^^^^^^^^^^^^^^^^^^^^^^^^^^^^^^^^^^^^^^^^^^^^^^^^
2025-10-29T03:05:18.578284331Z [inf]  Traceback (most recent call last):
2025-10-29T03:05:18.578293950Z [inf]    File "/app/src/clients/binance_client.py", line 475, in get_position_info_async
2025-10-29T03:05:18.578297320Z [inf]    File "/app/src/clients/binance_client.py", line 203, in _request
2025-10-29T03:05:18.578303501Z [inf]      account_info = await self.get_account_info()
2025-10-29T03:05:18.578308428Z [inf]      result = await self.circuit_breaker.call_async(_do_request)
2025-10-29T03:05:18.578317093Z [inf]               ^^^^^^^^^^^^^^^^^^^^^^^^^^^^^^^^^^^^^^^^^^^^^^^^^^
2025-10-29T03:05:18.578324862Z [inf]    File "/app/src/core/circuit_breaker.py", line 327, in call_async
2025-10-29T03:05:18.578333282Z [inf]      raise Exception(reason)
2025-10-29T03:05:18.578340485Z [inf]  Exception: 熔斷器阻斷(失敗5次)，請40秒後重試
2025-10-29T03:05:18.578958446Z [inf]                     ^^^^^^^^^^^^^^^^^^^^^^^^^^^^^
2025-10-29T03:05:18.578967593Z [inf]    File "/app/src/clients/binance_client.py", line 455, in get_account_info
2025-10-29T03:05:18.578973830Z [inf]      result = await self._request("GET", "/fapi/v2/account", signed=True)
2025-10-29T03:05:18.578980802Z [inf]               ^^^^^^^^^^^^^^^^^^^^^^^^^^^^^^^^^^^^^^^^^^^^^^^^^^^^^^^^^^^
2025-10-29T03:05:18.578987083Z [inf]    File "/app/src/clients/binance_client.py", line 219, in _request
2025-10-29T03:05:18.578991685Z [inf]      raise BinanceRequestError(
2025-10-29T03:05:18.578995991Z [inf]  src.clients.binance_errors.BinanceRequestError: 熔斷器阻斷(失敗5次)，請40秒後重試
2025-10-29T03:05:20.487829977Z [inf]  2025-10-29 03:05:20,153 - src.core.circuit_breaker - ERROR - 🔴 熔斷器阻斷(失敗5次)，請38秒後重試 | 操作: generic | 優先級: NORMAL
2025-10-29T03:05:20.487838661Z [inf]  2025-10-29 03:05:20,153 - src.clients.binance_client - ERROR - API 請求失敗: /fapi/v2/account - 熔斷器阻斷(失敗5次)，請38秒後重試
2025-10-29T03:05:20.487845730Z [inf]  2025-10-29 03:05:20,153 - src.core.position_monitor_24x7 - ERROR - ❌ 獲取倉位失敗: 熔斷器阻斷(失敗5次)，請38秒後重試
2025-10-29T03:05:20.575826013Z [inf]  2025-10-29 03:05:20,574 - src.core.circuit_breaker - ERROR - 🔴 熔斷器阻斷(失敗5次)，請38秒後重試 | 操作: generic | 優先級: NORMAL
2025-10-29T03:05:20.575835651Z [inf]  2025-10-29 03:05:20,574 - src.clients.binance_client - ERROR - API 請求失敗: /fapi/v2/account - 熔斷器阻斷(失敗5次)，請38秒後重試
2025-10-29T03:05:20.578776907Z [inf]  Traceback (most recent call last):
2025-10-29T03:05:20.578780275Z [inf]  2025-10-29 03:05:20,574 - src.core.position_controller - ERROR - ❌ 獲取持倉失敗: 熔斷器阻斷(失敗5次)，請38秒後重試
2025-10-29T03:05:20.578785867Z [inf]  Traceback (most recent call last):
2025-10-29T03:05:20.578791069Z [inf]    File "/app/src/core/position_controller.py", line 171, in _fetch_all_positions
2025-10-29T03:05:20.578791647Z [inf]    File "/app/src/clients/binance_client.py", line 203, in _request
2025-10-29T03:05:20.578796735Z [inf]      result = await self.circuit_breaker.call_async(_do_request)
2025-10-29T03:05:20.578801570Z [inf]      raw_positions = await self.binance_client.get_position_info_async()
2025-10-29T03:05:20.578803088Z [inf]               ^^^^^^^^^^^^^^^^^^^^^^^^^^^^^^^^^^^^^^^^^^^^^^^^^^
2025-10-29T03:05:20.578808325Z [inf]    File "/app/src/core/circuit_breaker.py", line 327, in call_async
2025-10-29T03:05:20.578811419Z [inf]                      ^^^^^^^^^^^^^^^^^^^^^^^^^^^^^^^^^^^^^^^^^^^^^^^^^^^
2025-10-29T03:05:20.578813571Z [inf]      raise Exception(reason)
2025-10-29T03:05:20.578818367Z [inf]  Exception: 熔斷器阻斷(失敗5次)，請38秒後重試
2025-10-29T03:05:20.578820300Z [inf]    File "/app/src/clients/binance_client.py", line 475, in get_position_info_async
2025-10-29T03:05:20.578824628Z [inf]  
2025-10-29T03:05:20.578828893Z [inf]  During handling of the above exception, another exception occurred:
2025-10-29T03:05:20.578832979Z [inf]  
2025-10-29T03:05:20.578838559Z [inf]      account_info = await self.get_account_info()
2025-10-29T03:05:20.578845674Z [inf]                     ^^^^^^^^^^^^^^^^^^^^^^^^^^^^^
2025-10-29T03:05:20.578851213Z [inf]    File "/app/src/clients/binance_client.py", line 455, in get_account_info
2025-10-29T03:05:20.578856976Z [inf]      result = await self._request("GET", "/fapi/v2/account", signed=True)
2025-10-29T03:05:20.580597613Z [inf]               ^^^^^^^^^^^^^^^^^^^^^^^^^^^^^^^^^^^^^^^^^^^^^^^^^^^^^^^^^^^
2025-10-29T03:05:20.580605540Z [inf]    File "/app/src/clients/binance_client.py", line 219, in _request
2025-10-29T03:05:20.580611907Z [inf]      raise BinanceRequestError(
2025-10-29T03:05:20.580618157Z [inf]  src.clients.binance_errors.BinanceRequestError: 熔斷器阻斷(失敗5次)，請38秒後重試
2025-10-29T03:05:22.488912844Z [inf]  2025-10-29 03:05:22,156 - src.core.circuit_breaker - ERROR - 🔴 熔斷器阻斷(失敗5次)，請36秒後重試 | 操作: generic | 優先級: NORMAL
2025-10-29T03:05:22.488922784Z [inf]  2025-10-29 03:05:22,156 - src.clients.binance_client - ERROR - API 請求失敗: /fapi/v2/account - 熔斷器阻斷(失敗5次)，請36秒後重試
2025-10-29T03:05:22.488943270Z [inf]  2025-10-29 03:05:22,156 - src.core.position_monitor_24x7 - ERROR - ❌ 獲取倉位失敗: 熔斷器阻斷(失敗5次)，請36秒後重試
2025-10-29T03:05:22.585830225Z [inf]      raw_positions = await self.binance_client.get_position_info_async()
2025-10-29T03:05:22.585839297Z [inf]  2025-10-29 03:05:22,576 - src.core.circuit_breaker - ERROR - 🔴 熔斷器阻斷(失敗5次)，請36秒後重試 | 操作: generic | 優先級: NORMAL
2025-10-29T03:05:22.585859572Z [inf]                      ^^^^^^^^^^^^^^^^^^^^^^^^^^^^^^^^^^^^^^^^^^^^^^^^^^^
2025-10-29T03:05:22.585859728Z [inf]  2025-10-29 03:05:22,576 - src.clients.binance_client - ERROR - API 請求失敗: /fapi/v2/account - 熔斷器阻斷(失敗5次)，請36秒後重試
2025-10-29T03:05:22.585873329Z [inf]    File "/app/src/clients/binance_client.py", line 475, in get_position_info_async
2025-10-29T03:05:22.585873542Z [inf]  2025-10-29 03:05:22,576 - src.core.position_controller - ERROR - ❌ 獲取持倉失敗: 熔斷器阻斷(失敗5次)，請36秒後重試
2025-10-29T03:05:22.585887482Z [inf]      account_info = await self.get_account_info()
2025-10-29T03:05:22.585891942Z [inf]  Traceback (most recent call last):
2025-10-29T03:05:22.585901194Z [inf]    File "/app/src/clients/binance_client.py", line 203, in _request
2025-10-29T03:05:22.585914060Z [inf]      result = await self.circuit_breaker.call_async(_do_request)
2025-10-29T03:05:22.585924821Z [inf]               ^^^^^^^^^^^^^^^^^^^^^^^^^^^^^^^^^^^^^^^^^^^^^^^^^^
2025-10-29T03:05:22.585934192Z [inf]    File "/app/src/core/circuit_breaker.py", line 327, in call_async
2025-10-29T03:05:22.585947117Z [inf]      raise Exception(reason)
2025-10-29T03:05:22.585956333Z [inf]  Exception: 熔斷器阻斷(失敗5次)，請36秒後重試
2025-10-29T03:05:22.585964474Z [inf]  
2025-10-29T03:05:22.585974319Z [inf]  During handling of the above exception, another exception occurred:
2025-10-29T03:05:22.585981006Z [inf]  
2025-10-29T03:05:22.585987568Z [inf]  Traceback (most recent call last):
2025-10-29T03:05:22.585996120Z [inf]    File "/app/src/core/position_controller.py", line 171, in _fetch_all_positions
2025-10-29T03:05:22.587171157Z [inf]                     ^^^^^^^^^^^^^^^^^^^^^^^^^^^^^
2025-10-29T03:05:22.587176519Z [inf]    File "/app/src/clients/binance_client.py", line 455, in get_account_info
2025-10-29T03:05:22.587181529Z [inf]      result = await self._request("GET", "/fapi/v2/account", signed=True)
2025-10-29T03:05:22.587186271Z [inf]               ^^^^^^^^^^^^^^^^^^^^^^^^^^^^^^^^^^^^^^^^^^^^^^^^^^^^^^^^^^^
2025-10-29T03:05:22.587190938Z [inf]    File "/app/src/clients/binance_client.py", line 219, in _request
2025-10-29T03:05:22.587195335Z [inf]      raise BinanceRequestError(
2025-10-29T03:05:22.587199847Z [inf]  src.clients.binance_errors.BinanceRequestError: 熔斷器阻斷(失敗5次)，請36秒後重試
2025-10-29T03:05:24.497501002Z [inf]  2025-10-29 03:05:24,158 - src.core.circuit_breaker - ERROR - 🔴 熔斷器阻斷(失敗5次)，請34秒後重試 | 操作: generic | 優先級: NORMAL
2025-10-29T03:05:24.497508656Z [inf]  2025-10-29 03:05:24,159 - src.clients.binance_client - ERROR - API 請求失敗: /fapi/v2/account - 熔斷器阻斷(失敗5次)，請34秒後重試
2025-10-29T03:05:24.497515920Z [inf]  2025-10-29 03:05:24,159 - src.core.position_monitor_24x7 - ERROR - ❌ 獲取倉位失敗: 熔斷器阻斷(失敗5次)，請34秒後重試
2025-10-29T03:05:24.580377218Z [inf]  2025-10-29 03:05:24,578 - src.core.circuit_breaker - ERROR - 🔴 熔斷器阻斷(失敗5次)，請34秒後重試 | 操作: generic | 優先級: NORMAL
2025-10-29T03:05:24.580383353Z [inf]  2025-10-29 03:05:24,579 - src.clients.binance_client - ERROR - API 請求失敗: /fapi/v2/account - 熔斷器阻斷(失敗5次)，請34秒後重試
2025-10-29T03:05:24.582745631Z [inf]  2025-10-29 03:05:24,579 - src.core.position_controller - ERROR - ❌ 獲取持倉失敗: 熔斷器阻斷(失敗5次)，請34秒後重試
2025-10-29T03:05:24.582748837Z [inf]      result = await self._request("GET", "/fapi/v2/account", signed=True)
2025-10-29T03:05:24.582754735Z [inf]  Traceback (most recent call last):
2025-10-29T03:05:24.582760759Z [inf]    File "/app/src/clients/binance_client.py", line 203, in _request
2025-10-29T03:05:24.582766422Z [inf]      result = await self.circuit_breaker.call_async(_do_request)
2025-10-29T03:05:24.582772105Z [inf]               ^^^^^^^^^^^^^^^^^^^^^^^^^^^^^^^^^^^^^^^^^^^^^^^^^^
2025-10-29T03:05:24.582789521Z [inf]    File "/app/src/core/circuit_breaker.py", line 327, in call_async
2025-10-29T03:05:24.582795847Z [inf]      raise Exception(reason)
2025-10-29T03:05:24.582801466Z [inf]  Exception: 熔斷器阻斷(失敗5次)，請34秒後重試
2025-10-29T03:05:24.582807753Z [inf]  
2025-10-29T03:05:24.582812941Z [inf]  During handling of the above exception, another exception occurred:
2025-10-29T03:05:24.582818305Z [inf]  
2025-10-29T03:05:24.582824398Z [inf]  Traceback (most recent call last):
2025-10-29T03:05:24.582830749Z [inf]    File "/app/src/core/position_controller.py", line 171, in _fetch_all_positions
2025-10-29T03:05:24.582836241Z [inf]      raw_positions = await self.binance_client.get_position_info_async()
2025-10-29T03:05:24.582841940Z [inf]                      ^^^^^^^^^^^^^^^^^^^^^^^^^^^^^^^^^^^^^^^^^^^^^^^^^^^
2025-10-29T03:05:24.582847487Z [inf]    File "/app/src/clients/binance_client.py", line 475, in get_position_info_async
2025-10-29T03:05:24.582853085Z [inf]      account_info = await self.get_account_info()
2025-10-29T03:05:24.582859735Z [inf]                     ^^^^^^^^^^^^^^^^^^^^^^^^^^^^^
2025-10-29T03:05:24.582864561Z [inf]    File "/app/src/clients/binance_client.py", line 455, in get_account_info
2025-10-29T03:05:24.583604960Z [inf]               ^^^^^^^^^^^^^^^^^^^^^^^^^^^^^^^^^^^^^^^^^^^^^^^^^^^^^^^^^^^
2025-10-29T03:05:24.583610642Z [inf]    File "/app/src/clients/binance_client.py", line 219, in _request
2025-10-29T03:05:24.583615612Z [inf]      raise BinanceRequestError(
2025-10-29T03:05:24.583620234Z [inf]  src.clients.binance_errors.BinanceRequestError: 熔斷器阻斷(失敗5次)，請34秒後重試
2025-10-29T03:05:26.496415789Z [inf]  2025-10-29 03:05:26,161 - src.core.circuit_breaker - ERROR - 🔴 熔斷器阻斷(失敗5次)，請32秒後重試 | 操作: generic | 優先級: NORMAL
2025-10-29T03:05:26.496423185Z [inf]  2025-10-29 03:05:26,161 - src.clients.binance_client - ERROR - API 請求失敗: /fapi/v2/account - 熔斷器阻斷(失敗5次)，請32秒後重試
2025-10-29T03:05:26.496430596Z [inf]  2025-10-29 03:05:26,161 - src.core.position_monitor_24x7 - ERROR - ❌ 獲取倉位失敗: 熔斷器阻斷(失敗5次)，請32秒後重試
2025-10-29T03:05:26.583040664Z [inf]  2025-10-29 03:05:26,581 - src.core.circuit_breaker - ERROR - 🔴 熔斷器阻斷(失敗5次)，請32秒後重試 | 操作: generic | 優先級: NORMAL
2025-10-29T03:05:26.583047456Z [inf]  2025-10-29 03:05:26,581 - src.clients.binance_client - ERROR - API 請求失敗: /fapi/v2/account - 熔斷器阻斷(失敗5次)，請32秒後重試
2025-10-29T03:05:26.585263348Z [inf]  2025-10-29 03:05:26,581 - src.core.position_controller - ERROR - ❌ 獲取持倉失敗: 熔斷器阻斷(失敗5次)，請32秒後重試
2025-10-29T03:05:26.585269379Z [inf]    File "/app/src/core/position_controller.py", line 171, in _fetch_all_positions
2025-10-29T03:05:26.585272650Z [inf]  Traceback (most recent call last):
2025-10-29T03:05:26.585279279Z [inf]    File "/app/src/clients/binance_client.py", line 203, in _request
2025-10-29T03:05:26.585285722Z [inf]      result = await self.circuit_breaker.call_async(_do_request)
2025-10-29T03:05:26.585288249Z [inf]      raw_positions = await self.binance_client.get_position_info_async()
2025-10-29T03:05:26.585292920Z [inf]               ^^^^^^^^^^^^^^^^^^^^^^^^^^^^^^^^^^^^^^^^^^^^^^^^^^
2025-10-29T03:05:26.585300016Z [inf]    File "/app/src/core/circuit_breaker.py", line 327, in call_async
2025-10-29T03:05:26.585302161Z [inf]                      ^^^^^^^^^^^^^^^^^^^^^^^^^^^^^^^^^^^^^^^^^^^^^^^^^^^
2025-10-29T03:05:26.585311274Z [inf]    File "/app/src/clients/binance_client.py", line 475, in get_position_info_async
2025-10-29T03:05:26.585318907Z [inf]      account_info = await self.get_account_info()
2025-10-29T03:05:26.585326231Z [inf]                     ^^^^^^^^^^^^^^^^^^^^^^^^^^^^^
2025-10-29T03:05:26.585333462Z [inf]    File "/app/src/clients/binance_client.py", line 455, in get_account_info
2025-10-29T03:05:26.585338579Z [inf]      result = await self._request("GET", "/fapi/v2/account", signed=True)
2025-10-29T03:05:26.585342269Z [inf]      raise Exception(reason)
2025-10-29T03:05:26.585349337Z [inf]  Exception: 熔斷器阻斷(失敗5次)，請32秒後重試
2025-10-29T03:05:26.585355581Z [inf]  
2025-10-29T03:05:26.585362326Z [inf]  During handling of the above exception, another exception occurred:
2025-10-29T03:05:26.585368088Z [inf]  
2025-10-29T03:05:26.585374272Z [inf]  Traceback (most recent call last):
2025-10-29T03:05:26.586269444Z [inf]               ^^^^^^^^^^^^^^^^^^^^^^^^^^^^^^^^^^^^^^^^^^^^^^^^^^^^^^^^^^^
2025-10-29T03:05:26.586277819Z [inf]    File "/app/src/clients/binance_client.py", line 219, in _request
2025-10-29T03:05:26.586284252Z [inf]      raise BinanceRequestError(
2025-10-29T03:05:26.586289548Z [inf]  src.clients.binance_errors.BinanceRequestError: 熔斷器阻斷(失敗5次)，請32秒後重試
2025-10-29T03:05:28.165463377Z [inf]  2025-10-29 03:05:28,163 - src.core.circuit_breaker - ERROR - 🔴 熔斷器阻斷(失敗5次)，請30秒後重試 | 操作: generic | 優先級: NORMAL
2025-10-29T03:05:28.165474211Z [inf]  2025-10-29 03:05:28,163 - src.clients.binance_client - ERROR - API 請求失敗: /fapi/v2/account - 熔斷器阻斷(失敗5次)，請30秒後重試
2025-10-29T03:05:28.165481153Z [inf]  2025-10-29 03:05:28,163 - src.core.position_monitor_24x7 - ERROR - ❌ 獲取倉位失敗: 熔斷器阻斷(失敗5次)，請30秒後重試
2025-10-29T03:05:28.586358480Z [inf]  2025-10-29 03:05:28,583 - src.core.circuit_breaker - ERROR - 🔴 熔斷器阻斷(失敗5次)，請30秒後重試 | 操作: generic | 優先級: NORMAL
2025-10-29T03:05:28.586369884Z [inf]  2025-10-29 03:05:28,583 - src.clients.binance_client - ERROR - API 請求失敗: /fapi/v2/account - 熔斷器阻斷(失敗5次)，請30秒後重試
2025-10-29T03:05:28.586377150Z [inf]  2025-10-29 03:05:28,584 - src.core.position_controller - ERROR - ❌ 獲取持倉失敗: 熔斷器阻斷(失敗5次)，請30秒後重試
2025-10-29T03:05:28.586385098Z [inf]  Traceback (most recent call last):
2025-10-29T03:05:28.586392640Z [inf]    File "/app/src/clients/binance_client.py", line 203, in _request
2025-10-29T03:05:28.586397933Z [inf]      result = await self.circuit_breaker.call_async(_do_request)
2025-10-29T03:05:28.586402911Z [inf]               ^^^^^^^^^^^^^^^^^^^^^^^^^^^^^^^^^^^^^^^^^^^^^^^^^^
2025-10-29T03:05:28.586408335Z [inf]    File "/app/src/core/circuit_breaker.py", line 327, in call_async
2025-10-29T03:05:28.586414393Z [inf]      raise Exception(reason)
2025-10-29T03:05:28.586419644Z [inf]  Exception: 熔斷器阻斷(失敗5次)，請30秒後重試
2025-10-29T03:05:28.586442402Z [inf]  
2025-10-29T03:05:28.586464121Z [inf]  During handling of the above exception, another exception occurred:
2025-10-29T03:05:28.586481033Z [inf]  
2025-10-29T03:05:28.586494614Z [inf]  Traceback (most recent call last):
2025-10-29T03:05:28.586506313Z [inf]    File "/app/src/core/position_controller.py", line 171, in _fetch_all_positions
2025-10-29T03:05:28.586515875Z [inf]      raw_positions = await self.binance_client.get_position_info_async()
2025-10-29T03:05:28.586524019Z [inf]                      ^^^^^^^^^^^^^^^^^^^^^^^^^^^^^^^^^^^^^^^^^^^^^^^^^^^
2025-10-29T03:05:28.586533760Z [inf]    File "/app/src/clients/binance_client.py", line 475, in get_position_info_async
2025-10-29T03:05:28.586542048Z [inf]      account_info = await self.get_account_info()
2025-10-29T03:05:28.588030054Z [inf]                     ^^^^^^^^^^^^^^^^^^^^^^^^^^^^^
2025-10-29T03:05:28.588038159Z [inf]    File "/app/src/clients/binance_client.py", line 455, in get_account_info
2025-10-29T03:05:28.588044223Z [inf]      result = await self._request("GET", "/fapi/v2/account", signed=True)
2025-10-29T03:05:28.588050741Z [inf]               ^^^^^^^^^^^^^^^^^^^^^^^^^^^^^^^^^^^^^^^^^^^^^^^^^^^^^^^^^^^
2025-10-29T03:05:28.588058728Z [inf]    File "/app/src/clients/binance_client.py", line 219, in _request
2025-10-29T03:05:28.588065262Z [inf]      raise BinanceRequestError(
2025-10-29T03:05:28.588071903Z [inf]  src.clients.binance_errors.BinanceRequestError: 熔斷器阻斷(失敗5次)，請30秒後重試
2025-10-29T03:05:30.482167279Z [inf]  2025-10-29 03:05:30,165 - src.core.circuit_breaker - ERROR - 🔴 熔斷器阻斷(失敗5次)，請28秒後重試 | 操作: generic | 優先級: NORMAL
2025-10-29T03:05:30.482174267Z [inf]  2025-10-29 03:05:30,165 - src.clients.binance_client - ERROR - API 請求失敗: /fapi/v2/account - 熔斷器阻斷(失敗5次)，請28秒後重試
2025-10-29T03:05:30.482183072Z [inf]  2025-10-29 03:05:30,165 - src.core.position_monitor_24x7 - ERROR - ❌ 獲取倉位失敗: 熔斷器阻斷(失敗5次)，請28秒後重試
2025-10-29T03:05:30.592172842Z [inf]  2025-10-29 03:05:30,586 - src.core.circuit_breaker - ERROR - 🔴 熔斷器阻斷(失敗5次)，請28秒後重試 | 操作: generic | 優先級: NORMAL
2025-10-29T03:05:30.592179505Z [inf]  2025-10-29 03:05:30,586 - src.clients.binance_client - ERROR - API 請求失敗: /fapi/v2/account - 熔斷器阻斷(失敗5次)，請28秒後重試
2025-10-29T03:05:30.592184249Z [inf]  2025-10-29 03:05:30,586 - src.core.position_controller - ERROR - ❌ 獲取持倉失敗: 熔斷器阻斷(失敗5次)，請28秒後重試
2025-10-29T03:05:30.592193068Z [inf]  Traceback (most recent call last):
2025-10-29T03:05:30.592198341Z [inf]    File "/app/src/clients/binance_client.py", line 203, in _request
2025-10-29T03:05:30.592203405Z [inf]      result = await self.circuit_breaker.call_async(_do_request)
2025-10-29T03:05:30.592208013Z [inf]               ^^^^^^^^^^^^^^^^^^^^^^^^^^^^^^^^^^^^^^^^^^^^^^^^^^
2025-10-29T03:05:30.592212813Z [inf]    File "/app/src/core/circuit_breaker.py", line 327, in call_async
2025-10-29T03:05:30.592219494Z [inf]      raise Exception(reason)
2025-10-29T03:05:30.592225150Z [inf]  Exception: 熔斷器阻斷(失敗5次)，請28秒後重試
2025-10-29T03:05:30.592231047Z [inf]  
2025-10-29T03:05:30.592236391Z [inf]  During handling of the above exception, another exception occurred:
2025-10-29T03:05:30.592421700Z [inf]  
2025-10-29T03:05:30.592429958Z [inf]  Traceback (most recent call last):
2025-10-29T03:05:30.592434718Z [inf]    File "/app/src/core/position_controller.py", line 171, in _fetch_all_positions
2025-10-29T03:05:30.592439153Z [inf]      raw_positions = await self.binance_client.get_position_info_async()
2025-10-29T03:05:30.592444179Z [inf]                      ^^^^^^^^^^^^^^^^^^^^^^^^^^^^^^^^^^^^^^^^^^^^^^^^^^^
2025-10-29T03:05:30.592448683Z [inf]    File "/app/src/clients/binance_client.py", line 475, in get_position_info_async
2025-10-29T03:05:30.592516740Z [inf]      account_info = await self.get_account_info()
2025-10-29T03:05:30.595375520Z [inf]                     ^^^^^^^^^^^^^^^^^^^^^^^^^^^^^
2025-10-29T03:05:30.595384574Z [inf]    File "/app/src/clients/binance_client.py", line 455, in get_account_info
2025-10-29T03:05:30.595393883Z [inf]      result = await self._request("GET", "/fapi/v2/account", signed=True)
2025-10-29T03:05:30.595400849Z [inf]               ^^^^^^^^^^^^^^^^^^^^^^^^^^^^^^^^^^^^^^^^^^^^^^^^^^^^^^^^^^^
2025-10-29T03:05:30.595406388Z [inf]    File "/app/src/clients/binance_client.py", line 219, in _request
2025-10-29T03:05:30.595413318Z [inf]      raise BinanceRequestError(
2025-10-29T03:05:30.595418231Z [inf]  src.clients.binance_errors.BinanceRequestError: 熔斷器阻斷(失敗5次)，請28秒後重試
2025-10-29T03:05:32.172531982Z [inf]  2025-10-29 03:05:32,166 - src.core.circuit_breaker - ERROR - 🔴 熔斷器阻斷(失敗5次)，請26秒後重試 | 操作: generic | 優先級: NORMAL
2025-10-29T03:05:32.172540474Z [inf]  2025-10-29 03:05:32,166 - src.clients.binance_client - ERROR - API 請求失敗: /fapi/v2/account - 熔斷器阻斷(失敗5次)，請26秒後重試
2025-10-29T03:05:32.172545239Z [inf]  2025-10-29 03:05:32,167 - src.core.position_monitor_24x7 - ERROR - ❌ 獲取倉位失敗: 熔斷器阻斷(失敗5次)，請26秒後重試
2025-10-29T03:05:32.591642576Z [inf]  2025-10-29 03:05:32,588 - src.core.circuit_breaker - ERROR - 🔴 熔斷器阻斷(失敗5次)，請26秒後重試 | 操作: generic | 優先級: NORMAL
2025-10-29T03:05:32.591653049Z [inf]  2025-10-29 03:05:32,588 - src.clients.binance_client - ERROR - API 請求失敗: /fapi/v2/account - 熔斷器阻斷(失敗5次)，請26秒後重試
2025-10-29T03:05:32.591659839Z [inf]  2025-10-29 03:05:32,588 - src.core.position_controller - ERROR - ❌ 獲取持倉失敗: 熔斷器阻斷(失敗5次)，請26秒後重試
2025-10-29T03:05:32.591672682Z [inf]  Traceback (most recent call last):
2025-10-29T03:05:32.591678930Z [inf]    File "/app/src/clients/binance_client.py", line 203, in _request
2025-10-29T03:05:32.591685196Z [inf]      result = await self.circuit_breaker.call_async(_do_request)
2025-10-29T03:05:32.591727658Z [inf]               ^^^^^^^^^^^^^^^^^^^^^^^^^^^^^^^^^^^^^^^^^^^^^^^^^^
2025-10-29T03:05:32.591733957Z [inf]    File "/app/src/core/circuit_breaker.py", line 327, in call_async
2025-10-29T03:05:32.591746932Z [inf]      raise Exception(reason)
2025-10-29T03:05:32.591753642Z [inf]  Exception: 熔斷器阻斷(失敗5次)，請26秒後重試
2025-10-29T03:05:32.591766594Z [inf]  
2025-10-29T03:05:32.591781444Z [inf]  During handling of the above exception, another exception occurred:
2025-10-29T03:05:32.591787912Z [inf]  
2025-10-29T03:05:32.591807356Z [inf]  Traceback (most recent call last):
2025-10-29T03:05:32.591814252Z [inf]    File "/app/src/core/position_controller.py", line 171, in _fetch_all_positions
2025-10-29T03:05:32.591861504Z [inf]      raw_positions = await self.binance_client.get_position_info_async()
2025-10-29T03:05:32.591868239Z [inf]                      ^^^^^^^^^^^^^^^^^^^^^^^^^^^^^^^^^^^^^^^^^^^^^^^^^^^
2025-10-29T03:05:32.591875163Z [inf]    File "/app/src/clients/binance_client.py", line 475, in get_position_info_async
2025-10-29T03:05:32.591887769Z [inf]      account_info = await self.get_account_info()
2025-10-29T03:05:32.592523005Z [inf]                     ^^^^^^^^^^^^^^^^^^^^^^^^^^^^^
2025-10-29T03:05:32.592529420Z [inf]    File "/app/src/clients/binance_client.py", line 455, in get_account_info
2025-10-29T03:05:32.592534520Z [inf]      result = await self._request("GET", "/fapi/v2/account", signed=True)
2025-10-29T03:05:32.592538944Z [inf]               ^^^^^^^^^^^^^^^^^^^^^^^^^^^^^^^^^^^^^^^^^^^^^^^^^^^^^^^^^^^
2025-10-29T03:05:32.592544323Z [inf]    File "/app/src/clients/binance_client.py", line 219, in _request
2025-10-29T03:05:32.592549286Z [inf]      raise BinanceRequestError(
2025-10-29T03:05:32.592554536Z [inf]  src.clients.binance_errors.BinanceRequestError: 熔斷器阻斷(失敗5次)，請26秒後重試
2025-10-29T03:05:34.180594061Z [inf]  2025-10-29 03:05:34,168 - src.core.circuit_breaker - ERROR - 🔴 熔斷器阻斷(失敗5次)，請24秒後重試 | 操作: generic | 優先級: NORMAL
2025-10-29T03:05:34.180602866Z [inf]  2025-10-29 03:05:34,168 - src.clients.binance_client - ERROR - API 請求失敗: /fapi/v2/account - 熔斷器阻斷(失敗5次)，請24秒後重試
2025-10-29T03:05:34.180608990Z [inf]  2025-10-29 03:05:34,168 - src.core.position_monitor_24x7 - ERROR - ❌ 獲取倉位失敗: 熔斷器阻斷(失敗5次)，請24秒後重試
2025-10-29T03:05:34.615786798Z [inf]                     ^^^^^^^^^^^^^^^^^^^^^^^^^^^^^
2025-10-29T03:05:34.615793583Z [inf]    File "/app/src/clients/binance_client.py", line 455, in get_account_info
2025-10-29T03:05:34.615800776Z [inf]      result = await self._request("GET", "/fapi/v2/account", signed=True)
2025-10-29T03:05:34.615807700Z [inf]               ^^^^^^^^^^^^^^^^^^^^^^^^^^^^^^^^^^^^^^^^^^^^^^^^^^^^^^^^^^^
2025-10-29T03:05:34.615816093Z [inf]    File "/app/src/clients/binance_client.py", line 219, in _request
2025-10-29T03:05:34.615822828Z [inf]      raise BinanceRequestError(
2025-10-29T03:05:34.615829458Z [inf]  src.clients.binance_errors.BinanceRequestError: 熔斷器阻斷(失敗5次)，請24秒後重試
2025-10-29T03:05:34.615913787Z [inf]  2025-10-29 03:05:34,590 - src.core.circuit_breaker - ERROR - 🔴 熔斷器阻斷(失敗5次)，請24秒後重試 | 操作: generic | 優先級: NORMAL
2025-10-29T03:05:34.615921464Z [inf]  2025-10-29 03:05:34,590 - src.clients.binance_client - ERROR - API 請求失敗: /fapi/v2/account - 熔斷器阻斷(失敗5次)，請24秒後重試
2025-10-29T03:05:34.615941457Z [inf]  2025-10-29 03:05:34,590 - src.core.position_controller - ERROR - ❌ 獲取持倉失敗: 熔斷器阻斷(失敗5次)，請24秒後重試
2025-10-29T03:05:34.615948391Z [inf]  Traceback (most recent call last):
2025-10-29T03:05:34.615957841Z [inf]    File "/app/src/clients/binance_client.py", line 203, in _request
2025-10-29T03:05:34.615967100Z [inf]      result = await self.circuit_breaker.call_async(_do_request)
2025-10-29T03:05:34.615975992Z [inf]               ^^^^^^^^^^^^^^^^^^^^^^^^^^^^^^^^^^^^^^^^^^^^^^^^^^
2025-10-29T03:05:34.615984983Z [inf]    File "/app/src/core/circuit_breaker.py", line 327, in call_async
2025-10-29T03:05:34.615991415Z [inf]      raise Exception(reason)
2025-10-29T03:05:34.615998625Z [inf]  Exception: 熔斷器阻斷(失敗5次)，請24秒後重試
2025-10-29T03:05:34.616004933Z [inf]  
2025-10-29T03:05:34.616011796Z [inf]  During handling of the above exception, another exception occurred:
2025-10-29T03:05:34.616020886Z [inf]  
2025-10-29T03:05:34.616027278Z [inf]  Traceback (most recent call last):
2025-10-29T03:05:34.616035451Z [inf]    File "/app/src/core/position_controller.py", line 171, in _fetch_all_positions
2025-10-29T03:05:34.616041829Z [inf]      raw_positions = await self.binance_client.get_position_info_async()
2025-10-29T03:05:34.616048443Z [inf]                      ^^^^^^^^^^^^^^^^^^^^^^^^^^^^^^^^^^^^^^^^^^^^^^^^^^^
2025-10-29T03:05:34.616054898Z [inf]    File "/app/src/clients/binance_client.py", line 475, in get_position_info_async
2025-10-29T03:05:34.616064680Z [inf]      account_info = await self.get_account_info()
2025-10-29T03:05:38.177871844Z [inf]  2025-10-29 03:05:38,173 - src.core.circuit_breaker - ERROR - 🔴 熔斷器阻斷(失敗5次)，請20秒後重試 | 操作: generic | 優先級: NORMAL
2025-10-29T03:05:38.177882032Z [inf]  2025-10-29 03:05:38,173 - src.clients.binance_client - ERROR - API 請求失敗: /fapi/v2/account - 熔斷器阻斷(失敗5次)，請20秒後重試
2025-10-29T03:05:38.177889010Z [inf]  2025-10-29 03:05:38,173 - src.core.position_monitor_24x7 - ERROR - ❌ 獲取倉位失敗: 熔斷器阻斷(失敗5次)，請20秒後重試
2025-10-29T03:05:38.598731890Z [inf]  
2025-10-29T03:05:38.598736647Z [inf]  2025-10-29 03:05:38,594 - src.core.circuit_breaker - ERROR - 🔴 熔斷器阻斷(失敗5次)，請20秒後重試 | 操作: generic | 優先級: NORMAL
2025-10-29T03:05:38.598742118Z [inf]  Traceback (most recent call last):
2025-10-29T03:05:38.598747475Z [inf]  2025-10-29 03:05:38,594 - src.clients.binance_client - ERROR - API 請求失敗: /fapi/v2/account - 熔斷器阻斷(失敗5次)，請20秒後重試
2025-10-29T03:05:38.598749331Z [inf]    File "/app/src/core/position_controller.py", line 171, in _fetch_all_positions
2025-10-29T03:05:38.598755359Z [inf]      raw_positions = await self.binance_client.get_position_info_async()
2025-10-29T03:05:38.598756064Z [inf]  2025-10-29 03:05:38,594 - src.core.position_controller - ERROR - ❌ 獲取持倉失敗: 熔斷器阻斷(失敗5次)，請20秒後重試
2025-10-29T03:05:38.598761280Z [inf]                      ^^^^^^^^^^^^^^^^^^^^^^^^^^^^^^^^^^^^^^^^^^^^^^^^^^^
2025-10-29T03:05:38.598764094Z [inf]  Traceback (most recent call last):
2025-10-29T03:05:38.598767801Z [inf]    File "/app/src/clients/binance_client.py", line 475, in get_position_info_async
2025-10-29T03:05:38.598772073Z [inf]    File "/app/src/clients/binance_client.py", line 203, in _request
2025-10-29T03:05:38.598774815Z [inf]      account_info = await self.get_account_info()
2025-10-29T03:05:38.598779610Z [inf]      result = await self.circuit_breaker.call_async(_do_request)
2025-10-29T03:05:38.598786738Z [inf]               ^^^^^^^^^^^^^^^^^^^^^^^^^^^^^^^^^^^^^^^^^^^^^^^^^^
2025-10-29T03:05:38.598791919Z [inf]    File "/app/src/core/circuit_breaker.py", line 327, in call_async
2025-10-29T03:05:38.598798153Z [inf]      raise Exception(reason)
2025-10-29T03:05:38.598804371Z [inf]  Exception: 熔斷器阻斷(失敗5次)，請20秒後重試
2025-10-29T03:05:38.598810791Z [inf]  
2025-10-29T03:05:38.598816813Z [inf]  During handling of the above exception, another exception occurred:
2025-10-29T03:05:38.600487248Z [inf]                     ^^^^^^^^^^^^^^^^^^^^^^^^^^^^^
2025-10-29T03:05:38.600497044Z [inf]    File "/app/src/clients/binance_client.py", line 455, in get_account_info
2025-10-29T03:05:38.600503660Z [inf]      result = await self._request("GET", "/fapi/v2/account", signed=True)
2025-10-29T03:05:38.600510182Z [inf]               ^^^^^^^^^^^^^^^^^^^^^^^^^^^^^^^^^^^^^^^^^^^^^^^^^^^^^^^^^^^
2025-10-29T03:05:38.600516656Z [inf]    File "/app/src/clients/binance_client.py", line 219, in _request
2025-10-29T03:05:38.600526547Z [inf]      raise BinanceRequestError(
2025-10-29T03:05:38.600546611Z [inf]  src.clients.binance_errors.BinanceRequestError: 熔斷器阻斷(失敗5次)，請20秒後重試