2025-10-28T12:13:50.003772518Z [inf]    File "/app/src/clients/binance_client.py", line 197, in _request
2025-10-28T12:13:50.003777765Z [inf]      result = await self.circuit_breaker.call_async(_do_request)
2025-10-28T12:13:50.003782140Z [inf]               ^^^^^^^^^^^^^^^^^^^^^^^^^^^^^^^^^^^^^^^^^^^^^^^^^^
2025-10-28T12:13:50.005435884Z [inf]    File "/app/src/core/circuit_breaker.py", line 327, in call_async
2025-10-28T12:13:50.005442420Z [inf]      raise Exception(reason)
2025-10-28T12:13:50.005447468Z [inf]  Exception: 熔斷器阻斷(失敗5次)，請14秒後重試
2025-10-28T12:13:50.005449416Z [inf]               ^^^^^^^^^^^^^^^^^^^^^^^^^^^^^^^^^^^^^^^^^^^^^^^^^^^^^^^^^^^
2025-10-28T12:13:50.005454199Z [inf]  
2025-10-28T12:13:50.005458809Z [inf]    File "/app/src/clients/binance_client.py", line 213, in _request
2025-10-28T12:13:50.005461860Z [inf]  During handling of the above exception, another exception occurred:
2025-10-28T12:13:50.005465835Z [inf]      raise BinanceRequestError(
2025-10-28T12:13:50.005469181Z [inf]  
2025-10-28T12:13:50.005472460Z [inf]  src.clients.binance_errors.BinanceRequestError: 熔斷器阻斷(失敗5次)，請14秒後重試
2025-10-28T12:13:50.005476291Z [inf]  Traceback (most recent call last):
2025-10-28T12:13:50.005482221Z [inf]    File "/app/src/core/unified_scheduler.py", line 212, in _execute_trading_cycle
2025-10-28T12:13:50.005487113Z [inf]      account_info = await self.binance_client.get_account_info()
2025-10-28T12:13:50.005492587Z [inf]                     ^^^^^^^^^^^^^^^^^^^^^^^^^^^^^^^^^^^^^^^^^^^^
2025-10-28T12:13:50.005497980Z [inf]    File "/app/src/clients/binance_client.py", line 449, in get_account_info
2025-10-28T12:13:50.005503570Z [inf]      result = await self._request("GET", "/fapi/v2/account", signed=True)
2025-10-28T12:13:50.803190554Z [inf]  During handling of the above exception, another exception occurred:
2025-10-28T12:13:50.803208194Z [inf]  
2025-10-28T12:13:50.803218877Z [inf]  Traceback (most recent call last):
2025-10-28T12:13:50.803227416Z [inf]    File "/app/src/core/position_controller.py", line 135, in _fetch_all_positions
2025-10-28T12:13:50.803236943Z [inf]      raw_positions = await self.binance_client.get_position_info_async()
2025-10-28T12:13:50.803239123Z [inf]  2025-10-28 12:13:50,551 - src.core.circuit_breaker - ERROR - 🔴 熔斷器阻斷(失敗5次)，請14秒後重試 | 操作: generic | 優先級: NORMAL
2025-10-28T12:13:50.803247571Z [inf]                      ^^^^^^^^^^^^^^^^^^^^^^^^^^^^^^^^^^^^^^^^^^^^^^^^^^^
2025-10-28T12:13:50.803247926Z [inf]  2025-10-28 12:13:50,551 - src.clients.binance_client - ERROR - API 請求失敗: /fapi/v2/account - 熔斷器阻斷(失敗5次)，請14秒後重試
2025-10-28T12:13:50.803257141Z [inf]  2025-10-28 12:13:50,551 - src.core.position_controller - ERROR - ❌ 獲取持倉失敗: 熔斷器阻斷(失敗5次)，請14秒後重試
2025-10-28T12:13:50.803258095Z [inf]    File "/app/src/clients/binance_client.py", line 469, in get_position_info_async
2025-10-28T12:13:50.803266617Z [inf]  Traceback (most recent call last):
2025-10-28T12:13:50.803271545Z [inf]      account_info = await self.get_account_info()
2025-10-28T12:13:50.803276156Z [inf]    File "/app/src/clients/binance_client.py", line 197, in _request
2025-10-28T12:13:50.803281607Z [inf]      result = await self.circuit_breaker.call_async(_do_request)
2025-10-28T12:13:50.803286129Z [inf]               ^^^^^^^^^^^^^^^^^^^^^^^^^^^^^^^^^^^^^^^^^^^^^^^^^^
2025-10-28T12:13:50.803290778Z [inf]    File "/app/src/core/circuit_breaker.py", line 327, in call_async
2025-10-28T12:13:50.803295622Z [inf]      raise Exception(reason)
2025-10-28T12:13:50.803301847Z [inf]  Exception: 熔斷器阻斷(失敗5次)，請14秒後重試
2025-10-28T12:13:50.803306857Z [inf]  
2025-10-28T12:13:50.803665588Z [inf]                     ^^^^^^^^^^^^^^^^^^^^^^^^^^^^^
2025-10-28T12:13:50.803675079Z [inf]    File "/app/src/clients/binance_client.py", line 449, in get_account_info
2025-10-28T12:13:50.803680496Z [inf]      result = await self._request("GET", "/fapi/v2/account", signed=True)
2025-10-28T12:13:50.803684964Z [inf]               ^^^^^^^^^^^^^^^^^^^^^^^^^^^^^^^^^^^^^^^^^^^^^^^^^^^^^^^^^^^
2025-10-28T12:13:50.803689474Z [inf]    File "/app/src/clients/binance_client.py", line 213, in _request
2025-10-28T12:13:50.803695322Z [inf]      raise BinanceRequestError(
2025-10-28T12:13:50.803699574Z [inf]  src.clients.binance_errors.BinanceRequestError: 熔斷器阻斷(失敗5次)，請14秒後重試
2025-10-28T12:13:52.984961119Z [inf]  2025-10-28 12:13:52,554 - src.core.circuit_breaker - ERROR - 🔴 熔斷器阻斷(失敗5次)，請12秒後重試 | 操作: generic | 優先級: NORMAL
2025-10-28T12:13:52.984967902Z [inf]  2025-10-28 12:13:52,554 - src.clients.binance_client - ERROR - API 請求失敗: /fapi/v2/account - 熔斷器阻斷(失敗5次)，請12秒後重試
2025-10-28T12:13:52.984974649Z [inf]  2025-10-28 12:13:52,554 - src.core.position_controller - ERROR - ❌ 獲取持倉失敗: 熔斷器阻斷(失敗5次)，請12秒後重試
2025-10-28T12:13:52.984981075Z [inf]  Traceback (most recent call last):
2025-10-28T12:13:52.984988348Z [inf]    File "/app/src/clients/binance_client.py", line 197, in _request
2025-10-28T12:13:52.984994880Z [inf]      result = await self.circuit_breaker.call_async(_do_request)
2025-10-28T12:13:52.985001163Z [inf]               ^^^^^^^^^^^^^^^^^^^^^^^^^^^^^^^^^^^^^^^^^^^^^^^^^^
2025-10-28T12:13:52.985007974Z [inf]    File "/app/src/core/circuit_breaker.py", line 327, in call_async
2025-10-28T12:13:52.985014248Z [inf]      raise Exception(reason)
2025-10-28T12:13:52.985020650Z [inf]  Exception: 熔斷器阻斷(失敗5次)，請12秒後重試
2025-10-28T12:13:52.985027525Z [inf]  
2025-10-28T12:13:52.985034172Z [inf]  During handling of the above exception, another exception occurred:
2025-10-28T12:13:52.985040558Z [inf]  
2025-10-28T12:13:52.985046795Z [inf]  Traceback (most recent call last):
2025-10-28T12:13:52.985053433Z [inf]    File "/app/src/core/position_controller.py", line 135, in _fetch_all_positions
2025-10-28T12:13:52.985059079Z [inf]      raw_positions = await self.binance_client.get_position_info_async()
2025-10-28T12:13:52.985066851Z [inf]                      ^^^^^^^^^^^^^^^^^^^^^^^^^^^^^^^^^^^^^^^^^^^^^^^^^^^
2025-10-28T12:13:52.985073224Z [inf]    File "/app/src/clients/binance_client.py", line 469, in get_position_info_async
2025-10-28T12:13:52.985079482Z [inf]      account_info = await self.get_account_info()
2025-10-28T12:13:52.985085984Z [inf]                     ^^^^^^^^^^^^^^^^^^^^^^^^^^^^^
2025-10-28T12:13:52.985092095Z [inf]    File "/app/src/clients/binance_client.py", line 449, in get_account_info
2025-10-28T12:13:52.985098006Z [inf]      result = await self._request("GET", "/fapi/v2/account", signed=True)
2025-10-28T12:13:52.985103989Z [inf]               ^^^^^^^^^^^^^^^^^^^^^^^^^^^^^^^^^^^^^^^^^^^^^^^^^^^^^^^^^^^
2025-10-28T12:13:52.985110366Z [inf]    File "/app/src/clients/binance_client.py", line 213, in _request
2025-10-28T12:13:52.985117728Z [inf]      raise BinanceRequestError(
2025-10-28T12:13:52.985124958Z [inf]  src.clients.binance_errors.BinanceRequestError: 熔斷器阻斷(失敗5次)，請12秒後重試
2025-10-28T12:13:54.581858433Z [inf]  2025-10-28 12:13:54,557 - src.core.circuit_breaker - ERROR - 🔴 熔斷器阻斷(失敗5次)，請10秒後重試 | 操作: generic | 優先級: NORMAL
2025-10-28T12:13:54.581868152Z [inf]  2025-10-28 12:13:54,557 - src.clients.binance_client - ERROR - API 請求失敗: /fapi/v2/account - 熔斷器阻斷(失敗5次)，請10秒後重試
2025-10-28T12:13:54.581874784Z [inf]  2025-10-28 12:13:54,557 - src.core.position_controller - ERROR - ❌ 獲取持倉失敗: 熔斷器阻斷(失敗5次)，請10秒後重試
2025-10-28T12:13:54.581881356Z [inf]  Traceback (most recent call last):
2025-10-28T12:13:54.581886894Z [inf]    File "/app/src/clients/binance_client.py", line 197, in _request
2025-10-28T12:13:54.581893253Z [inf]      result = await self.circuit_breaker.call_async(_do_request)
2025-10-28T12:13:54.581901833Z [inf]               ^^^^^^^^^^^^^^^^^^^^^^^^^^^^^^^^^^^^^^^^^^^^^^^^^^
2025-10-28T12:13:54.581908054Z [inf]    File "/app/src/core/circuit_breaker.py", line 327, in call_async
2025-10-28T12:13:54.581914292Z [inf]      raise Exception(reason)
2025-10-28T12:13:54.581920700Z [inf]  Exception: 熔斷器阻斷(失敗5次)，請10秒後重試
2025-10-28T12:13:54.581926906Z [inf]  
2025-10-28T12:13:54.581933279Z [inf]  During handling of the above exception, another exception occurred:
2025-10-28T12:13:54.581939196Z [inf]  
2025-10-28T12:13:54.581944855Z [inf]  Traceback (most recent call last):
2025-10-28T12:13:54.581950753Z [inf]    File "/app/src/core/position_controller.py", line 135, in _fetch_all_positions
2025-10-28T12:13:54.581958377Z [inf]      raw_positions = await self.binance_client.get_position_info_async()
2025-10-28T12:13:54.581965280Z [inf]                      ^^^^^^^^^^^^^^^^^^^^^^^^^^^^^^^^^^^^^^^^^^^^^^^^^^^
2025-10-28T12:13:54.581970963Z [inf]    File "/app/src/clients/binance_client.py", line 469, in get_position_info_async
2025-10-28T12:13:54.581976676Z [inf]      account_info = await self.get_account_info()
2025-10-28T12:13:54.584474133Z [inf]                     ^^^^^^^^^^^^^^^^^^^^^^^^^^^^^
2025-10-28T12:13:54.584484287Z [inf]    File "/app/src/clients/binance_client.py", line 449, in get_account_info
2025-10-28T12:13:54.584490303Z [inf]      result = await self._request("GET", "/fapi/v2/account", signed=True)
2025-10-28T12:13:54.584498505Z [inf]               ^^^^^^^^^^^^^^^^^^^^^^^^^^^^^^^^^^^^^^^^^^^^^^^^^^^^^^^^^^^
2025-10-28T12:13:54.584504438Z [inf]    File "/app/src/clients/binance_client.py", line 213, in _request
2025-10-28T12:13:54.584510421Z [inf]      raise BinanceRequestError(
2025-10-28T12:13:54.584516071Z [inf]  src.clients.binance_errors.BinanceRequestError: 熔斷器阻斷(失敗5次)，請10秒後重試
2025-10-28T12:13:56.568959762Z [inf]  2025-10-28 12:13:56,560 - src.core.circuit_breaker - ERROR - 🔴 熔斷器阻斷(失敗5次)，請8秒後重試 | 操作: generic | 優先級: NORMAL
2025-10-28T12:13:56.568980682Z [inf]  2025-10-28 12:13:56,560 - src.clients.binance_client - ERROR - API 請求失敗: /fapi/v2/account - 熔斷器阻斷(失敗5次)，請8秒後重試
2025-10-28T12:13:56.569028056Z [inf]  2025-10-28 12:13:56,560 - src.core.position_controller - ERROR - ❌ 獲取持倉失敗: 熔斷器阻斷(失敗5次)，請8秒後重試
2025-10-28T12:13:56.569035335Z [inf]  Traceback (most recent call last):
2025-10-28T12:13:56.569042875Z [inf]    File "/app/src/clients/binance_client.py", line 197, in _request
2025-10-28T12:13:56.569050229Z [inf]      result = await self.circuit_breaker.call_async(_do_request)
2025-10-28T12:13:56.569056149Z [inf]               ^^^^^^^^^^^^^^^^^^^^^^^^^^^^^^^^^^^^^^^^^^^^^^^^^^
2025-10-28T12:13:56.569165959Z [inf]    File "/app/src/core/circuit_breaker.py", line 327, in call_async
2025-10-28T12:13:56.569171716Z [inf]      raise Exception(reason)
2025-10-28T12:13:56.569178527Z [inf]  Exception: 熔斷器阻斷(失敗5次)，請8秒後重試
2025-10-28T12:13:56.569185430Z [inf]  
2025-10-28T12:13:56.569191479Z [inf]  During handling of the above exception, another exception occurred:
2025-10-28T12:13:56.569197779Z [inf]  
2025-10-28T12:13:56.569202536Z [inf]  Traceback (most recent call last):
2025-10-28T12:13:56.569207023Z [inf]    File "/app/src/core/position_controller.py", line 135, in _fetch_all_positions
2025-10-28T12:13:56.569211860Z [inf]      raw_positions = await self.binance_client.get_position_info_async()
2025-10-28T12:13:56.569218822Z [inf]                      ^^^^^^^^^^^^^^^^^^^^^^^^^^^^^^^^^^^^^^^^^^^^^^^^^^^
2025-10-28T12:13:56.569225876Z [inf]    File "/app/src/clients/binance_client.py", line 469, in get_position_info_async
2025-10-28T12:13:56.569232352Z [inf]      account_info = await self.get_account_info()
2025-10-28T12:13:56.570978647Z [inf]                     ^^^^^^^^^^^^^^^^^^^^^^^^^^^^^
2025-10-28T12:13:56.570987714Z [inf]    File "/app/src/clients/binance_client.py", line 449, in get_account_info
2025-10-28T12:13:56.570992543Z [inf]      result = await self._request("GET", "/fapi/v2/account", signed=True)
2025-10-28T12:13:56.570996419Z [inf]               ^^^^^^^^^^^^^^^^^^^^^^^^^^^^^^^^^^^^^^^^^^^^^^^^^^^^^^^^^^^
2025-10-28T12:13:56.571002064Z [inf]    File "/app/src/clients/binance_client.py", line 213, in _request
2025-10-28T12:13:56.571007364Z [inf]      raise BinanceRequestError(
2025-10-28T12:13:56.571011407Z [inf]  src.clients.binance_errors.BinanceRequestError: 熔斷器阻斷(失敗5次)，請8秒後重試
2025-10-28T12:13:58.565719229Z [inf]      raise Exception(reason)
2025-10-28T12:13:58.565732062Z [inf]  Exception: 熔斷器阻斷(失敗5次)，請6秒後重試
2025-10-28T12:13:58.565740703Z [inf]  
2025-10-28T12:13:58.565741114Z [inf]  2025-10-28 12:13:58,563 - src.core.circuit_breaker - ERROR - 🔴 熔斷器阻斷(失敗5次)，請6秒後重試 | 操作: generic | 優先級: NORMAL
2025-10-28T12:13:58.565748565Z [inf]  During handling of the above exception, another exception occurred:
2025-10-28T12:13:58.565752647Z [inf]  2025-10-28 12:13:58,563 - src.clients.binance_client - ERROR - API 請求失敗: /fapi/v2/account - 熔斷器阻斷(失敗5次)，請6秒後重試
2025-10-28T12:13:58.565756960Z [inf]  
2025-10-28T12:13:58.565759400Z [inf]  2025-10-28 12:13:58,563 - src.core.position_controller - ERROR - ❌ 獲取持倉失敗: 熔斷器阻斷(失敗5次)，請6秒後重試
2025-10-28T12:13:58.565764204Z [inf]  Traceback (most recent call last):
2025-10-28T12:13:58.565768450Z [inf]  Traceback (most recent call last):
2025-10-28T12:13:58.565771382Z [inf]    File "/app/src/core/position_controller.py", line 135, in _fetch_all_positions
2025-10-28T12:13:58.565777629Z [inf]      raw_positions = await self.binance_client.get_position_info_async()
2025-10-28T12:13:58.565784000Z [inf]    File "/app/src/clients/binance_client.py", line 197, in _request
2025-10-28T12:13:58.565784236Z [inf]                      ^^^^^^^^^^^^^^^^^^^^^^^^^^^^^^^^^^^^^^^^^^^^^^^^^^^
2025-10-28T12:13:58.565792730Z [inf]      result = await self.circuit_breaker.call_async(_do_request)
2025-10-28T12:13:58.565800016Z [inf]               ^^^^^^^^^^^^^^^^^^^^^^^^^^^^^^^^^^^^^^^^^^^^^^^^^^
2025-10-28T12:13:58.565801164Z [inf]    File "/app/src/clients/binance_client.py", line 469, in get_position_info_async
2025-10-28T12:13:58.565807238Z [inf]    File "/app/src/core/circuit_breaker.py", line 327, in call_async
2025-10-28T12:13:58.565817587Z [inf]      account_info = await self.get_account_info()
2025-10-28T12:13:58.566962625Z [inf]  src.clients.binance_errors.BinanceRequestError: 熔斷器阻斷(失敗5次)，請6秒後重試
2025-10-28T12:13:58.566971883Z [inf]                     ^^^^^^^^^^^^^^^^^^^^^^^^^^^^^
2025-10-28T12:13:58.566977458Z [inf]    File "/app/src/clients/binance_client.py", line 449, in get_account_info
2025-10-28T12:13:58.566982530Z [inf]      result = await self._request("GET", "/fapi/v2/account", signed=True)
2025-10-28T12:13:58.566987273Z [inf]               ^^^^^^^^^^^^^^^^^^^^^^^^^^^^^^^^^^^^^^^^^^^^^^^^^^^^^^^^^^^
2025-10-28T12:13:58.566995005Z [inf]    File "/app/src/clients/binance_client.py", line 213, in _request
2025-10-28T12:13:58.567001057Z [inf]      raise BinanceRequestError(
2025-10-28T12:14:00.570950109Z [inf]      raw_positions = await self.binance_client.get_position_info_async()
2025-10-28T12:14:00.570963609Z [inf]                      ^^^^^^^^^^^^^^^^^^^^^^^^^^^^^^^^^^^^^^^^^^^^^^^^^^^
2025-10-28T12:14:00.570969694Z [inf]  2025-10-28 12:14:00,566 - src.core.circuit_breaker - ERROR - 🔴 熔斷器阻斷(失敗5次)，請4秒後重試 | 操作: generic | 優先級: NORMAL
2025-10-28T12:14:00.570974288Z [inf]    File "/app/src/clients/binance_client.py", line 469, in get_position_info_async
2025-10-28T12:14:00.570976532Z [inf]  2025-10-28 12:14:00,566 - src.clients.binance_client - ERROR - API 請求失敗: /fapi/v2/account - 熔斷器阻斷(失敗5次)，請4秒後重試
2025-10-28T12:14:00.570983434Z [inf]  2025-10-28 12:14:00,566 - src.core.position_controller - ERROR - ❌ 獲取持倉失敗: 熔斷器阻斷(失敗5次)，請4秒後重試
2025-10-28T12:14:00.570989240Z [inf]  Traceback (most recent call last):
2025-10-28T12:14:00.570994995Z [inf]    File "/app/src/clients/binance_client.py", line 197, in _request
2025-10-28T12:14:00.570999243Z [inf]      result = await self.circuit_breaker.call_async(_do_request)
2025-10-28T12:14:00.571003584Z [inf]               ^^^^^^^^^^^^^^^^^^^^^^^^^^^^^^^^^^^^^^^^^^^^^^^^^^
2025-10-28T12:14:00.571007782Z [inf]    File "/app/src/core/circuit_breaker.py", line 327, in call_async
2025-10-28T12:14:00.571012122Z [inf]      raise Exception(reason)
2025-10-28T12:14:00.571017436Z [inf]  Exception: 熔斷器阻斷(失敗5次)，請4秒後重試
2025-10-28T12:14:00.571023947Z [inf]  
2025-10-28T12:14:00.571028441Z [inf]  During handling of the above exception, another exception occurred:
2025-10-28T12:14:00.571032746Z [inf]      account_info = await self.get_account_info()
2025-10-28T12:14:00.571034033Z [inf]  
2025-10-28T12:14:00.571038939Z [inf]  Traceback (most recent call last):
2025-10-28T12:14:00.571044529Z [inf]    File "/app/src/core/position_controller.py", line 135, in _fetch_all_positions
2025-10-28T12:14:00.572071509Z [inf]                     ^^^^^^^^^^^^^^^^^^^^^^^^^^^^^
2025-10-28T12:14:00.572077105Z [inf]    File "/app/src/clients/binance_client.py", line 449, in get_account_info
2025-10-28T12:14:00.572081904Z [inf]      result = await self._request("GET", "/fapi/v2/account", signed=True)
2025-10-28T12:14:00.572087990Z [inf]               ^^^^^^^^^^^^^^^^^^^^^^^^^^^^^^^^^^^^^^^^^^^^^^^^^^^^^^^^^^^
2025-10-28T12:14:00.572092726Z [inf]    File "/app/src/clients/binance_client.py", line 213, in _request
2025-10-28T12:14:00.572099320Z [inf]      raise BinanceRequestError(
2025-10-28T12:14:00.572106030Z [inf]  src.clients.binance_errors.BinanceRequestError: 熔斷器阻斷(失敗5次)，請4秒後重試
2025-10-28T12:14:02.711023924Z [inf]  2025-10-28 12:14:02,568 - src.core.circuit_breaker - ERROR - 🔴 熔斷器阻斷(失敗5次)，請2秒後重試 | 操作: generic | 優先級: NORMAL
2025-10-28T12:14:02.711041688Z [inf]  2025-10-28 12:14:02,568 - src.clients.binance_client - ERROR - API 請求失敗: /fapi/v2/account - 熔斷器阻斷(失敗5次)，請2秒後重試
2025-10-28T12:14:02.711049687Z [inf]  2025-10-28 12:14:02,568 - src.core.position_controller - ERROR - ❌ 獲取持倉失敗: 熔斷器阻斷(失敗5次)，請2秒後重試
2025-10-28T12:14:02.711057344Z [inf]  Traceback (most recent call last):
2025-10-28T12:14:02.711065415Z [inf]    File "/app/src/clients/binance_client.py", line 197, in _request
2025-10-28T12:14:02.711074212Z [inf]      result = await self.circuit_breaker.call_async(_do_request)
2025-10-28T12:14:02.711081578Z [inf]               ^^^^^^^^^^^^^^^^^^^^^^^^^^^^^^^^^^^^^^^^^^^^^^^^^^
2025-10-28T12:14:02.711088229Z [inf]    File "/app/src/core/circuit_breaker.py", line 327, in call_async
2025-10-28T12:14:02.711095830Z [inf]      raise Exception(reason)
2025-10-28T12:14:02.711102738Z [inf]  Exception: 熔斷器阻斷(失敗5次)，請2秒後重試
2025-10-28T12:14:02.711110259Z [inf]  
2025-10-28T12:14:02.711117635Z [inf]  During handling of the above exception, another exception occurred:
2025-10-28T12:14:02.711124786Z [inf]  
2025-10-28T12:14:02.711133411Z [inf]  Traceback (most recent call last):
2025-10-28T12:14:02.711140211Z [inf]    File "/app/src/core/position_controller.py", line 135, in _fetch_all_positions
2025-10-28T12:14:02.711145946Z [inf]      raw_positions = await self.binance_client.get_position_info_async()
2025-10-28T12:14:02.711153189Z [inf]                      ^^^^^^^^^^^^^^^^^^^^^^^^^^^^^^^^^^^^^^^^^^^^^^^^^^^
2025-10-28T12:14:02.711162114Z [inf]    File "/app/src/clients/binance_client.py", line 469, in get_position_info_async
2025-10-28T12:14:02.711179008Z [inf]      account_info = await self.get_account_info()
2025-10-28T12:14:02.711204393Z [inf]                     ^^^^^^^^^^^^^^^^^^^^^^^^^^^^^
2025-10-28T12:14:02.711211020Z [inf]    File "/app/src/clients/binance_client.py", line 449, in get_account_info
2025-10-28T12:14:02.711219862Z [inf]      result = await self._request("GET", "/fapi/v2/account", signed=True)
2025-10-28T12:14:02.711236585Z [inf]               ^^^^^^^^^^^^^^^^^^^^^^^^^^^^^^^^^^^^^^^^^^^^^^^^^^^^^^^^^^^
2025-10-28T12:14:02.711242946Z [inf]    File "/app/src/clients/binance_client.py", line 213, in _request
2025-10-28T12:14:02.711249300Z [inf]      raise BinanceRequestError(
2025-10-28T12:14:02.711254815Z [inf]  src.clients.binance_errors.BinanceRequestError: 熔斷器阻斷(失敗5次)，請2秒後重試
2025-10-28T12:14:04.573167798Z [inf]  2025-10-28 12:14:04,571 - src.core.circuit_breaker - INFO - ✅ 熔斷器超時恢復: blocked → NORMAL (超時60秒)
2025-10-28T12:14:04.933734869Z [inf]    File "/app/src/core/circuit_breaker.py", line 334, in call_async
2025-10-28T12:14:04.933747265Z [inf]      result = await func(*args, **kwargs)
2025-10-28T12:14:04.933753652Z [inf]               ^^^^^^^^^^^^^^^^^^^^^^^^^^^
2025-10-28T12:14:04.933762403Z [inf]    File "/app/src/clients/binance_client.py", line 193, in _do_request
2025-10-28T12:14:04.933769277Z [inf]      response.raise_for_status()
2025-10-28T12:14:04.933778491Z [inf]    File "/opt/venv/lib/python3.11/site-packages/aiohttp/client_reqrep.py", line 636, in raise_for_status
2025-10-28T12:14:04.933783958Z [inf]      raise ClientResponseError(
2025-10-28T12:14:04.933957143Z [inf]  2025-10-28 12:14:04,663 - src.clients.binance_client - ERROR - Binance API 錯誤 400: code=-1022, msg=Signature for this request is not valid., endpoint=/fapi/v2/account, params={'timestamp': 1761653644571, 'signature': '7ae75458e6f1b54b1adf0a5b8ed60135a62815dc5945686b4dc3a94209475545'}
2025-10-28T12:14:04.933962283Z [inf]  2025-10-28 12:14:04,663 - src.core.circuit_breaker - WARNING - 🔄 熔斷器級別變化: normal → warning (失敗次數: 1)
2025-10-28T12:14:04.933967509Z [inf]  2025-10-28 12:14:04,663 - src.clients.binance_client - ERROR - API 請求失敗: /fapi/v2/account - HTTP 400: Bad Request
2025-10-28T12:14:04.933973830Z [inf]  2025-10-28 12:14:04,663 - src.core.position_controller - ERROR - ❌ 獲取持倉失敗: HTTP 400: Bad Request
2025-10-28T12:14:04.933980802Z [inf]  Traceback (most recent call last):
2025-10-28T12:14:04.933986848Z [inf]    File "/app/src/clients/binance_client.py", line 197, in _request
2025-10-28T12:14:04.933993563Z [inf]      result = await self.circuit_breaker.call_async(_do_request)
2025-10-28T12:14:04.933999956Z [inf]               ^^^^^^^^^^^^^^^^^^^^^^^^^^^^^^^^^^^^^^^^^^^^^^^^^^
2025-10-28T12:14:04.934006918Z [inf]    File "/app/src/core/circuit_breaker.py", line 339, in call_async
2025-10-28T12:14:04.934013949Z [inf]      raise e
2025-10-28T12:14:04.936155851Z [inf]  aiohttp.client_exceptions.ClientResponseError: 400, message='Bad Request', url='https://fapi.binance.com/fapi/v2/account?signature=7ae75458e6f1b54b1adf0a5b8ed60135a62815dc5945686b4dc3a94209475545&timestamp=1761653644571'
2025-10-28T12:14:04.936163383Z [inf]  
2025-10-28T12:14:04.936168535Z [inf]  During handling of the above exception, another exception occurred:
2025-10-28T12:14:04.936174838Z [inf]  
2025-10-28T12:14:04.936180428Z [inf]  Traceback (most recent call last):
2025-10-28T12:14:04.936186473Z [inf]    File "/app/src/core/position_controller.py", line 135, in _fetch_all_positions
2025-10-28T12:14:04.936191723Z [inf]      raw_positions = await self.binance_client.get_position_info_async()
2025-10-28T12:14:04.936197941Z [inf]                      ^^^^^^^^^^^^^^^^^^^^^^^^^^^^^^^^^^^^^^^^^^^^^^^^^^^
2025-10-28T12:14:04.936204313Z [inf]    File "/app/src/clients/binance_client.py", line 469, in get_position_info_async
2025-10-28T12:14:04.936211204Z [inf]      account_info = await self.get_account_info()
2025-10-28T12:14:04.936217411Z [inf]                     ^^^^^^^^^^^^^^^^^^^^^^^^^^^^^
2025-10-28T12:14:04.936224361Z [inf]    File "/app/src/clients/binance_client.py", line 449, in get_account_info
2025-10-28T12:14:04.936229057Z [inf]      result = await self._request("GET", "/fapi/v2/account", signed=True)
2025-10-28T12:14:04.936235373Z [inf]               ^^^^^^^^^^^^^^^^^^^^^^^^^^^^^^^^^^^^^^^^^^^^^^^^^^^^^^^^^^^
2025-10-28T12:14:04.936240697Z [inf]    File "/app/src/clients/binance_client.py", line 201, in _request
2025-10-28T12:14:04.936248856Z [inf]      raise BinanceRequestError(
2025-10-28T12:14:04.936255658Z [inf]  src.clients.binance_errors.BinanceRequestError: HTTP 400: Bad Request
2025-10-28T12:14:06.672636470Z [inf]  2025-10-28 12:14:06,666 - src.core.circuit_breaker - WARNING - ⚠️  熔斷器警告級: 失敗1次 (操作: generic, 優先級: NORMAL)
2025-10-28T12:14:06.991596410Z [inf]    File "/app/src/core/circuit_breaker.py", line 339, in call_async
2025-10-28T12:14:06.991611314Z [inf]      raise e
2025-10-28T12:14:06.991627434Z [inf]    File "/app/src/core/circuit_breaker.py", line 334, in call_async
2025-10-28T12:14:06.991636681Z [inf]      result = await func(*args, **kwargs)
2025-10-28T12:14:06.991645197Z [inf]               ^^^^^^^^^^^^^^^^^^^^^^^^^^^
2025-10-28T12:14:06.991654742Z [inf]    File "/app/src/clients/binance_client.py", line 193, in _do_request
2025-10-28T12:14:06.991665931Z [inf]      response.raise_for_status()
2025-10-28T12:14:06.991676245Z [inf]    File "/opt/venv/lib/python3.11/site-packages/aiohttp/client_reqrep.py", line 636, in raise_for_status
2025-10-28T12:14:06.991687575Z [inf]      raise ClientResponseError(
2025-10-28T12:14:06.991697976Z [inf]  aiohttp.client_exceptions.ClientResponseError: 400, message='Bad Request', url='https://fapi.binance.com/fapi/v2/account?signature=465f136123ce7f26504f75a7d02c4c45375b26c0a62921711942d2f10e5434e9&timestamp=1761653646666'
2025-10-28T12:14:06.991763945Z [inf]  2025-10-28 12:14:06,742 - src.clients.binance_client - ERROR - Binance API 錯誤 400: code=-1022, msg=Signature for this request is not valid., endpoint=/fapi/v2/account, params={'timestamp': 1761653646666, 'signature': '465f136123ce7f26504f75a7d02c4c45375b26c0a62921711942d2f10e5434e9'}
2025-10-28T12:14:06.991768735Z [inf]  2025-10-28 12:14:06,742 - src.clients.binance_client - ERROR - API 請求失敗: /fapi/v2/account - HTTP 400: Bad Request
2025-10-28T12:14:06.991774495Z [inf]  2025-10-28 12:14:06,742 - src.core.position_controller - ERROR - ❌ 獲取持倉失敗: HTTP 400: Bad Request
2025-10-28T12:14:06.991784675Z [inf]  Traceback (most recent call last):
2025-10-28T12:14:06.991789824Z [inf]    File "/app/src/clients/binance_client.py", line 197, in _request
2025-10-28T12:14:06.991794474Z [inf]      result = await self.circuit_breaker.call_async(_do_request)
2025-10-28T12:14:06.991799815Z [inf]               ^^^^^^^^^^^^^^^^^^^^^^^^^^^^^^^^^^^^^^^^^^^^^^^^^^
2025-10-28T12:14:06.993076344Z [inf]  
2025-10-28T12:14:06.993085508Z [inf]  During handling of the above exception, another exception occurred:
2025-10-28T12:14:06.993094555Z [inf]  
2025-10-28T12:14:06.993102964Z [inf]  Traceback (most recent call last):
2025-10-28T12:14:06.993112778Z [inf]    File "/app/src/core/position_controller.py", line 135, in _fetch_all_positions
2025-10-28T12:14:06.993122172Z [inf]      raw_positions = await self.binance_client.get_position_info_async()
2025-10-28T12:14:06.993130871Z [inf]                      ^^^^^^^^^^^^^^^^^^^^^^^^^^^^^^^^^^^^^^^^^^^^^^^^^^^
2025-10-28T12:14:06.993139516Z [inf]    File "/app/src/clients/binance_client.py", line 469, in get_position_info_async
2025-10-28T12:14:06.993148085Z [inf]      account_info = await self.get_account_info()
2025-10-28T12:14:06.993157097Z [inf]                     ^^^^^^^^^^^^^^^^^^^^^^^^^^^^^
2025-10-28T12:14:06.993166457Z [inf]    File "/app/src/clients/binance_client.py", line 449, in get_account_info
2025-10-28T12:14:06.993175617Z [inf]      result = await self._request("GET", "/fapi/v2/account", signed=True)
2025-10-28T12:14:06.993184206Z [inf]               ^^^^^^^^^^^^^^^^^^^^^^^^^^^^^^^^^^^^^^^^^^^^^^^^^^^^^^^^^^^
2025-10-28T12:14:06.993193278Z [inf]    File "/app/src/clients/binance_client.py", line 201, in _request
2025-10-28T12:14:06.993201165Z [inf]      raise BinanceRequestError(
2025-10-28T12:14:06.993208983Z [inf]  src.clients.binance_errors.BinanceRequestError: HTTP 400: Bad Request
2025-10-28T12:14:09.015570105Z [inf]      result = await func(*args, **kwargs)
2025-10-28T12:14:09.015579803Z [inf]               ^^^^^^^^^^^^^^^^^^^^^^^^^^^
2025-10-28T12:14:09.015586193Z [inf]    File "/app/src/clients/binance_client.py", line 193, in _do_request
2025-10-28T12:14:09.015591261Z [inf]    File "/app/src/clients/binance_client.py", line 197, in _request
2025-10-28T12:14:09.015592165Z [inf]      response.raise_for_status()
2025-10-28T12:14:09.015598770Z [inf]    File "/opt/venv/lib/python3.11/site-packages/aiohttp/client_reqrep.py", line 636, in raise_for_status
2025-10-28T12:14:09.015604539Z [inf]      result = await self.circuit_breaker.call_async(_do_request)
2025-10-28T12:14:09.015606982Z [inf]      raise ClientResponseError(
2025-10-28T12:14:09.015609389Z [inf]    File "/app/src/core/circuit_breaker.py", line 339, in call_async
2025-10-28T12:14:09.015610045Z [inf]               ^^^^^^^^^^^^^^^^^^^^^^^^^^^^^^^^^^^^^^^^^^^^^^^^^^
2025-10-28T12:14:09.015622780Z [inf]      raise e
2025-10-28T12:14:09.015632209Z [inf]    File "/app/src/core/circuit_breaker.py", line 334, in call_async
2025-10-28T12:14:09.015660649Z [inf]  2025-10-28 12:14:08,746 - src.core.circuit_breaker - WARNING - ⚠️  熔斷器警告級: 失敗2次 (操作: generic, 優先級: NORMAL)
2025-10-28T12:14:09.015667305Z [inf]  2025-10-28 12:14:08,824 - src.clients.binance_client - ERROR - Binance API 錯誤 400: code=-1022, msg=Signature for this request is not valid., endpoint=/fapi/v2/account, params={'timestamp': 1761653648746, 'signature': '30c61a2160d5f79b7884f7b7c2fab0beedf79f6453f1ab8cb72f450526a768f1'}
2025-10-28T12:14:09.015674020Z [inf]  2025-10-28 12:14:08,824 - src.clients.binance_client - ERROR - API 請求失敗: /fapi/v2/account - HTTP 400: Bad Request
2025-10-28T12:14:09.015680972Z [inf]  2025-10-28 12:14:08,825 - src.core.position_controller - ERROR - ❌ 獲取持倉失敗: HTTP 400: Bad Request
2025-10-28T12:14:09.015686883Z [inf]  Traceback (most recent call last):
2025-10-28T12:14:09.162958074Z [inf]  aiohttp.client_exceptions.ClientResponseError: 400, message='Bad Request', url='https://fapi.binance.com/fapi/v2/account?signature=30c61a2160d5f79b7884f7b7c2fab0beedf79f6453f1ab8cb72f450526a768f1&timestamp=1761653648746'
2025-10-28T12:14:09.162964030Z [inf]  
2025-10-28T12:14:09.162969813Z [inf]  During handling of the above exception, another exception occurred:
2025-10-28T12:14:09.162975151Z [inf]  
2025-10-28T12:14:09.162981481Z [inf]  Traceback (most recent call last):
2025-10-28T12:14:09.162986874Z [inf]    File "/app/src/core/position_controller.py", line 135, in _fetch_all_positions
2025-10-28T12:14:09.162991922Z [inf]      raw_positions = await self.binance_client.get_position_info_async()
2025-10-28T12:14:09.162997914Z [inf]                      ^^^^^^^^^^^^^^^^^^^^^^^^^^^^^^^^^^^^^^^^^^^^^^^^^^^
2025-10-28T12:14:09.163004335Z [inf]    File "/app/src/clients/binance_client.py", line 469, in get_position_info_async
2025-10-28T12:14:09.163012715Z [inf]      account_info = await self.get_account_info()
2025-10-28T12:14:09.163023349Z [inf]                     ^^^^^^^^^^^^^^^^^^^^^^^^^^^^^
2025-10-28T12:14:09.163030755Z [inf]    File "/app/src/clients/binance_client.py", line 449, in get_account_info
2025-10-28T12:14:09.163037539Z [inf]      result = await self._request("GET", "/fapi/v2/account", signed=True)
2025-10-28T12:14:09.163044326Z [inf]               ^^^^^^^^^^^^^^^^^^^^^^^^^^^^^^^^^^^^^^^^^^^^^^^^^^^^^^^^^^^
2025-10-28T12:14:09.163050429Z [inf]    File "/app/src/clients/binance_client.py", line 201, in _request
2025-10-28T12:14:09.163057358Z [inf]      raise BinanceRequestError(
2025-10-28T12:14:09.163062107Z [inf]  src.clients.binance_errors.BinanceRequestError: HTTP 400: Bad Request
2025-10-28T12:14:11.069177443Z [inf]  2025-10-28 12:14:10,901 - src.clients.binance_client - ERROR - API 請求失敗: /fapi/v2/account - HTTP 400: Bad Request
2025-10-28T12:14:11.069188417Z [inf]  2025-10-28 12:14:10,901 - src.core.position_controller - ERROR - ❌ 獲取持倉失敗: HTTP 400: Bad Request
2025-10-28T12:14:11.069194280Z [inf]  Traceback (most recent call last):
2025-10-28T12:14:11.069199414Z [inf]    File "/app/src/clients/binance_client.py", line 197, in _request
2025-10-28T12:14:11.069204604Z [inf]      result = await self.circuit_breaker.call_async(_do_request)
2025-10-28T12:14:11.069209490Z [inf]               ^^^^^^^^^^^^^^^^^^^^^^^^^^^^^^^^^^^^^^^^^^^^^^^^^^
2025-10-28T12:14:11.069214031Z [inf]    File "/app/src/core/circuit_breaker.py", line 339, in call_async
2025-10-28T12:14:11.069218596Z [inf]      raise e
2025-10-28T12:14:11.069223061Z [inf]    File "/app/src/core/circuit_breaker.py", line 334, in call_async
2025-10-28T12:14:11.069230252Z [inf]      result = await func(*args, **kwargs)
2025-10-28T12:14:11.069236778Z [inf]               ^^^^^^^^^^^^^^^^^^^^^^^^^^^
2025-10-28T12:14:11.069241507Z [inf]    File "/app/src/clients/binance_client.py", line 193, in _do_request
2025-10-28T12:14:11.069245510Z [inf]      response.raise_for_status()
2025-10-28T12:14:11.069257774Z [inf]  2025-10-28 12:14:10,827 - src.core.circuit_breaker - WARNING - ⚠️  熔斷器警告級: 失敗3次 (操作: generic, 優先級: NORMAL)
2025-10-28T12:14:11.069264511Z [inf]  2025-10-28 12:14:10,901 - src.clients.binance_client - ERROR - Binance API 錯誤 400: code=-1022, msg=Signature for this request is not valid., endpoint=/fapi/v2/account, params={'timestamp': 1761653650827, 'signature': 'd74f002d09caa7693eee35429c2f4629b2e20a0947dce0700044dc6502624a13'}
2025-10-28T12:14:11.069271343Z [inf]  2025-10-28 12:14:10,901 - src.core.circuit_breaker - WARNING - 🔄 熔斷器級別變化: warning → throttled (失敗次數: 4)
2025-10-28T12:14:11.070536912Z [inf]      result = await self._request("GET", "/fapi/v2/account", signed=True)
2025-10-28T12:14:11.070538744Z [inf]    File "/opt/venv/lib/python3.11/site-packages/aiohttp/client_reqrep.py", line 636, in raise_for_status
2025-10-28T12:14:11.070546902Z [inf]      raise ClientResponseError(
2025-10-28T12:14:11.070547006Z [inf]               ^^^^^^^^^^^^^^^^^^^^^^^^^^^^^^^^^^^^^^^^^^^^^^^^^^^^^^^^^^^
2025-10-28T12:14:11.070553128Z [inf]  aiohttp.client_exceptions.ClientResponseError: 400, message='Bad Request', url='https://fapi.binance.com/fapi/v2/account?signature=d74f002d09caa7693eee35429c2f4629b2e20a0947dce0700044dc6502624a13&timestamp=1761653650827'
2025-10-28T12:14:11.070560074Z [inf]  
2025-10-28T12:14:11.070560229Z [inf]    File "/app/src/clients/binance_client.py", line 201, in _request
2025-10-28T12:14:11.070567344Z [inf]      raise BinanceRequestError(
2025-10-28T12:14:11.070567931Z [inf]  During handling of the above exception, another exception occurred:
2025-10-28T12:14:11.070573628Z [inf]  src.clients.binance_errors.BinanceRequestError: HTTP 400: Bad Request
2025-10-28T12:14:11.070575881Z [inf]  
2025-10-28T12:14:11.070581166Z [inf]  Traceback (most recent call last):
2025-10-28T12:14:11.070586540Z [inf]    File "/app/src/core/position_controller.py", line 135, in _fetch_all_positions
2025-10-28T12:14:11.070592029Z [inf]      raw_positions = await self.binance_client.get_position_info_async()
2025-10-28T12:14:11.070598008Z [inf]                      ^^^^^^^^^^^^^^^^^^^^^^^^^^^^^^^^^^^^^^^^^^^^^^^^^^^
2025-10-28T12:14:11.070604361Z [inf]    File "/app/src/clients/binance_client.py", line 469, in get_position_info_async
2025-10-28T12:14:11.070610824Z [inf]      account_info = await self.get_account_info()
2025-10-28T12:14:11.070617212Z [inf]                     ^^^^^^^^^^^^^^^^^^^^^^^^^^^^^
2025-10-28T12:14:11.070623555Z [inf]    File "/app/src/clients/binance_client.py", line 449, in get_account_info
2025-10-28T12:14:13.002611371Z [inf]  2025-10-28 12:14:12,904 - src.core.circuit_breaker - WARNING - 🔸 熔斷器限流: 增加2.0秒延遲 (失敗4次, 操作: generic)
2025-10-28T12:14:15.050456088Z [inf]    File "/app/src/clients/binance_client.py", line 197, in _request
2025-10-28T12:14:15.050469338Z [inf]      result = await self.circuit_breaker.call_async(_do_request)
2025-10-28T12:14:15.050480037Z [inf]               ^^^^^^^^^^^^^^^^^^^^^^^^^^^^^^^^^^^^^^^^^^^^^^^^^^
2025-10-28T12:14:15.050488021Z [inf]    File "/app/src/core/circuit_breaker.py", line 339, in call_async
2025-10-28T12:14:15.050495145Z [inf]      raise e
2025-10-28T12:14:15.050501697Z [inf]    File "/app/src/core/circuit_breaker.py", line 334, in call_async
2025-10-28T12:14:15.050507187Z [inf]      result = await func(*args, **kwargs)
2025-10-28T12:14:15.050512924Z [inf]               ^^^^^^^^^^^^^^^^^^^^^^^^^^^
2025-10-28T12:14:15.050518645Z [inf]    File "/app/src/clients/binance_client.py", line 193, in _do_request
2025-10-28T12:14:15.050525030Z [inf]      response.raise_for_status()
2025-10-28T12:14:15.050532196Z [inf]    File "/opt/venv/lib/python3.11/site-packages/aiohttp/client_reqrep.py", line 636, in raise_for_status
2025-10-28T12:14:15.050538253Z [inf]      raise ClientResponseError(
2025-10-28T12:14:15.050544816Z [inf]  2025-10-28 12:14:14,980 - src.clients.binance_client - ERROR - Binance API 錯誤 400: code=-1022, msg=Signature for this request is not valid., endpoint=/fapi/v2/account, params={'timestamp': 1761653654905, 'signature': '64d8012785d56ca12d6642b366b95e7d242b856b2473b7daf90975826fce4911'}
2025-10-28T12:14:15.050551578Z [inf]  2025-10-28 12:14:14,980 - src.core.circuit_breaker - WARNING - 🔄 熔斷器級別變化: throttled → blocked (失敗次數: 5)
2025-10-28T12:14:15.050557507Z [inf]  2025-10-28 12:14:14,980 - src.clients.binance_client - ERROR - API 請求失敗: /fapi/v2/account - HTTP 400: Bad Request
2025-10-28T12:14:15.050563696Z [inf]  2025-10-28 12:14:14,980 - src.core.position_controller - ERROR - ❌ 獲取持倉失敗: HTTP 400: Bad Request
2025-10-28T12:14:15.050569836Z [inf]  Traceback (most recent call last):
2025-10-28T12:14:15.052334116Z [inf]  aiohttp.client_exceptions.ClientResponseError: 400, message='Bad Request', url='https://fapi.binance.com/fapi/v2/account?signature=64d8012785d56ca12d6642b366b95e7d242b856b2473b7daf90975826fce4911&timestamp=1761653654905'
2025-10-28T12:14:15.052339080Z [inf]  
2025-10-28T12:14:15.052343677Z [inf]  During handling of the above exception, another exception occurred:
2025-10-28T12:14:15.052347719Z [inf]  
2025-10-28T12:14:15.052351964Z [inf]  Traceback (most recent call last):
2025-10-28T12:14:15.052356023Z [inf]    File "/app/src/core/position_controller.py", line 135, in _fetch_all_positions
2025-10-28T12:14:15.052360046Z [inf]      raw_positions = await self.binance_client.get_position_info_async()
2025-10-28T12:14:15.052364069Z [inf]                      ^^^^^^^^^^^^^^^^^^^^^^^^^^^^^^^^^^^^^^^^^^^^^^^^^^^
2025-10-28T12:14:15.052368522Z [inf]    File "/app/src/clients/binance_client.py", line 469, in get_position_info_async
2025-10-28T12:14:15.052372567Z [inf]      account_info = await self.get_account_info()
2025-10-28T12:14:15.052376837Z [inf]                     ^^^^^^^^^^^^^^^^^^^^^^^^^^^^^
2025-10-28T12:14:15.052381051Z [inf]    File "/app/src/clients/binance_client.py", line 449, in get_account_info
2025-10-28T12:14:15.052385288Z [inf]      result = await self._request("GET", "/fapi/v2/account", signed=True)
2025-10-28T12:14:15.052389127Z [inf]               ^^^^^^^^^^^^^^^^^^^^^^^^^^^^^^^^^^^^^^^^^^^^^^^^^^^^^^^^^^^
2025-10-28T12:14:15.052393259Z [inf]    File "/app/src/clients/binance_client.py", line 201, in _request
2025-10-28T12:14:15.052397690Z [inf]      raise BinanceRequestError(
2025-10-28T12:14:15.052402443Z [inf]  src.clients.binance_errors.BinanceRequestError: HTTP 400: Bad Request
2025-10-28T12:14:17.136185905Z [inf]  2025-10-28 12:14:16,983 - src.clients.binance_client - ERROR - API 請求失敗: /fapi/v2/account - 熔斷器阻斷(失敗5次)，請58秒後重試
2025-10-28T12:14:17.136194332Z [inf]  2025-10-28 12:14:16,983 - src.core.position_controller - ERROR - ❌ 獲取持倉失敗: 熔斷器阻斷(失敗5次)，請58秒後重試
2025-10-28T12:14:17.136199941Z [inf]  Traceback (most recent call last):
2025-10-28T12:14:17.136206397Z [inf]    File "/app/src/clients/binance_client.py", line 197, in _request
2025-10-28T12:14:17.136212280Z [inf]      result = await self.circuit_breaker.call_async(_do_request)
2025-10-28T12:14:17.136221243Z [inf]               ^^^^^^^^^^^^^^^^^^^^^^^^^^^^^^^^^^^^^^^^^^^^^^^^^^
2025-10-28T12:14:17.136229482Z [inf]  Exception: 熔斷器阻斷(失敗5次)，請58秒後重試
2025-10-28T12:14:17.136232751Z [inf]    File "/app/src/core/position_controller.py", line 135, in _fetch_all_positions
2025-10-28T12:14:17.136233049Z [inf]    File "/app/src/core/circuit_breaker.py", line 327, in call_async
2025-10-28T12:14:17.136240748Z [inf]  
2025-10-28T12:14:17.136243290Z [inf]      raise Exception(reason)
2025-10-28T12:14:17.136256821Z [inf]      raw_positions = await self.binance_client.get_position_info_async()
2025-10-28T12:14:17.136258769Z [inf]  During handling of the above exception, another exception occurred:
2025-10-28T12:14:17.136268538Z [inf]  
2025-10-28T12:14:17.136275668Z [inf]  Traceback (most recent call last):
2025-10-28T12:14:17.136290317Z [inf]                      ^^^^^^^^^^^^^^^^^^^^^^^^^^^^^^^^^^^^^^^^^^^^^^^^^^^
2025-10-28T12:14:17.136297123Z [inf]  2025-10-28 12:14:16,983 - src.core.circuit_breaker - ERROR - 🔴 熔斷器阻斷(失敗5次)，請58秒後重試 | 操作: generic | 優先級: NORMAL
2025-10-28T12:14:17.136299343Z [inf]    File "/app/src/clients/binance_client.py", line 469, in get_position_info_async
2025-10-28T12:14:17.136305971Z [inf]      account_info = await self.get_account_info()
2025-10-28T12:14:17.139194147Z [inf]                     ^^^^^^^^^^^^^^^^^^^^^^^^^^^^^
2025-10-28T12:14:17.139199113Z [inf]    File "/app/src/clients/binance_client.py", line 449, in get_account_info
2025-10-28T12:14:17.139204413Z [inf]      result = await self._request("GET", "/fapi/v2/account", signed=True)
2025-10-28T12:14:17.139210517Z [inf]               ^^^^^^^^^^^^^^^^^^^^^^^^^^^^^^^^^^^^^^^^^^^^^^^^^^^^^^^^^^^
2025-10-28T12:14:17.139216578Z [inf]    File "/app/src/clients/binance_client.py", line 213, in _request
2025-10-28T12:14:17.139222670Z [inf]      raise BinanceRequestError(
2025-10-28T12:14:17.139227820Z [inf]  src.clients.binance_errors.BinanceRequestError: 熔斷器阻斷(失敗5次)，請58秒後重試
2025-10-28T12:14:19.028382700Z [inf]  Exception: 熔斷器阻斷(失敗5次)，請56秒後重試
2025-10-28T12:14:19.028394455Z [inf]  
2025-10-28T12:14:19.028401645Z [inf]  During handling of the above exception, another exception occurred:
2025-10-28T12:14:19.028412250Z [inf]  
2025-10-28T12:14:19.028426353Z [inf]  Traceback (most recent call last):
2025-10-28T12:14:19.028435011Z [inf]    File "/app/src/core/position_controller.py", line 135, in _fetch_all_positions
2025-10-28T12:14:19.028440638Z [inf]      raw_positions = await self.binance_client.get_position_info_async()
2025-10-28T12:14:19.028445827Z [inf]                      ^^^^^^^^^^^^^^^^^^^^^^^^^^^^^^^^^^^^^^^^^^^^^^^^^^^
2025-10-28T12:14:19.028452470Z [inf]    File "/app/src/clients/binance_client.py", line 469, in get_position_info_async
2025-10-28T12:14:19.028461392Z [inf]      account_info = await self.get_account_info()
2025-10-28T12:14:19.028465620Z [inf]  2025-10-28 12:14:18,985 - src.core.circuit_breaker - ERROR - 🔴 熔斷器阻斷(失敗5次)，請56秒後重試 | 操作: generic | 優先級: NORMAL
2025-10-28T12:14:19.028476119Z [inf]  2025-10-28 12:14:18,986 - src.clients.binance_client - ERROR - API 請求失敗: /fapi/v2/account - 熔斷器阻斷(失敗5次)，請56秒後重試
2025-10-28T12:14:19.028484392Z [inf]  2025-10-28 12:14:18,986 - src.core.position_controller - ERROR - ❌ 獲取持倉失敗: 熔斷器阻斷(失敗5次)，請56秒後重試
2025-10-28T12:14:19.028491352Z [inf]  Traceback (most recent call last):
2025-10-28T12:14:19.028498094Z [inf]    File "/app/src/clients/binance_client.py", line 197, in _request
2025-10-28T12:14:19.028506704Z [inf]      result = await self.circuit_breaker.call_async(_do_request)
2025-10-28T12:14:19.028515665Z [inf]               ^^^^^^^^^^^^^^^^^^^^^^^^^^^^^^^^^^^^^^^^^^^^^^^^^^
2025-10-28T12:14:19.028523837Z [inf]    File "/app/src/core/circuit_breaker.py", line 327, in call_async
2025-10-28T12:14:19.028536505Z [inf]      raise Exception(reason)
2025-10-28T12:14:19.029164525Z [inf]                     ^^^^^^^^^^^^^^^^^^^^^^^^^^^^^
2025-10-28T12:14:19.029173882Z [inf]    File "/app/src/clients/binance_client.py", line 449, in get_account_info
2025-10-28T12:14:19.029179379Z [inf]      result = await self._request("GET", "/fapi/v2/account", signed=True)
2025-10-28T12:14:19.029184361Z [inf]               ^^^^^^^^^^^^^^^^^^^^^^^^^^^^^^^^^^^^^^^^^^^^^^^^^^^^^^^^^^^
2025-10-28T12:14:19.029189326Z [inf]    File "/app/src/clients/binance_client.py", line 213, in _request
2025-10-28T12:14:19.029194704Z [inf]      raise BinanceRequestError(
2025-10-28T12:14:19.029200154Z [inf]  src.clients.binance_errors.BinanceRequestError: 熔斷器阻斷(失敗5次)，請56秒後重試
2025-10-28T12:14:21.078906859Z [inf]      raw_positions = await self.binance_client.get_position_info_async()
2025-10-28T12:14:21.078935682Z [inf]                      ^^^^^^^^^^^^^^^^^^^^^^^^^^^^^^^^^^^^^^^^^^^^^^^^^^^
2025-10-28T12:14:21.078943087Z [inf]    File "/app/src/clients/binance_client.py", line 469, in get_position_info_async
2025-10-28T12:14:21.078948597Z [inf]      account_info = await self.get_account_info()
2025-10-28T12:14:21.078992316Z [inf]  2025-10-28 12:14:20,989 - src.core.circuit_breaker - ERROR - 🔴 熔斷器阻斷(失敗5次)，請54秒後重試 | 操作: generic | 優先級: NORMAL
2025-10-28T12:14:21.079000616Z [inf]  2025-10-28 12:14:20,989 - src.clients.binance_client - ERROR - API 請求失敗: /fapi/v2/account - 熔斷器阻斷(失敗5次)，請54秒後重試
2025-10-28T12:14:21.079005925Z [inf]  2025-10-28 12:14:20,989 - src.core.position_controller - ERROR - ❌ 獲取持倉失敗: 熔斷器阻斷(失敗5次)，請54秒後重試
2025-10-28T12:14:21.079011396Z [inf]  Traceback (most recent call last):
2025-10-28T12:14:21.079018431Z [inf]    File "/app/src/clients/binance_client.py", line 197, in _request
2025-10-28T12:14:21.079024764Z [inf]      result = await self.circuit_breaker.call_async(_do_request)
2025-10-28T12:14:21.079030759Z [inf]               ^^^^^^^^^^^^^^^^^^^^^^^^^^^^^^^^^^^^^^^^^^^^^^^^^^
2025-10-28T12:14:21.079037392Z [inf]    File "/app/src/core/circuit_breaker.py", line 327, in call_async
2025-10-28T12:14:21.079044812Z [inf]      raise Exception(reason)
2025-10-28T12:14:21.079052414Z [inf]  Exception: 熔斷器阻斷(失敗5次)，請54秒後重試
2025-10-28T12:14:21.079059784Z [inf]  
2025-10-28T12:14:21.079066732Z [inf]  During handling of the above exception, another exception occurred:
2025-10-28T12:14:21.079072229Z [inf]  
2025-10-28T12:14:21.079077175Z [inf]  Traceback (most recent call last):
2025-10-28T12:14:21.079082543Z [inf]    File "/app/src/core/position_controller.py", line 135, in _fetch_all_positions
2025-10-28T12:14:21.081551413Z [inf]                     ^^^^^^^^^^^^^^^^^^^^^^^^^^^^^
2025-10-28T12:14:21.081555987Z [inf]    File "/app/src/clients/binance_client.py", line 449, in get_account_info
2025-10-28T12:14:21.081560144Z [inf]      result = await self._request("GET", "/fapi/v2/account", signed=True)
2025-10-28T12:14:21.081564469Z [inf]               ^^^^^^^^^^^^^^^^^^^^^^^^^^^^^^^^^^^^^^^^^^^^^^^^^^^^^^^^^^^
2025-10-28T12:14:21.081568747Z [inf]    File "/app/src/clients/binance_client.py", line 213, in _request
2025-10-28T12:14:21.081572938Z [inf]      raise BinanceRequestError(
2025-10-28T12:14:21.081577573Z [inf]  src.clients.binance_errors.BinanceRequestError: 熔斷器阻斷(失敗5次)，請54秒後重試
2025-10-28T12:14:23.128847501Z [inf]  2025-10-28 12:14:22,992 - src.core.circuit_breaker - ERROR - 🔴 熔斷器阻斷(失敗5次)，請52秒後重試 | 操作: generic | 優先級: NORMAL
2025-10-28T12:14:23.128853374Z [inf]  2025-10-28 12:14:22,992 - src.clients.binance_client - ERROR - API 請求失敗: /fapi/v2/account - 熔斷器阻斷(失敗5次)，請52秒後重試
2025-10-28T12:14:23.128861883Z [inf]  2025-10-28 12:14:22,992 - src.core.position_controller - ERROR - ❌ 獲取持倉失敗: 熔斷器阻斷(失敗5次)，請52秒後重試
2025-10-28T12:14:23.128867760Z [inf]  Traceback (most recent call last):
2025-10-28T12:14:23.128876026Z [inf]    File "/app/src/clients/binance_client.py", line 197, in _request
2025-10-28T12:14:23.128883548Z [inf]      result = await self.circuit_breaker.call_async(_do_request)
2025-10-28T12:14:23.128890840Z [inf]               ^^^^^^^^^^^^^^^^^^^^^^^^^^^^^^^^^^^^^^^^^^^^^^^^^^
2025-10-28T12:14:23.128895867Z [inf]    File "/app/src/core/circuit_breaker.py", line 327, in call_async
2025-10-28T12:14:23.128906477Z [inf]      raise Exception(reason)
2025-10-28T12:14:23.128912657Z [inf]  Exception: 熔斷器阻斷(失敗5次)，請52秒後重試
2025-10-28T12:14:23.128918224Z [inf]  
2025-10-28T12:14:23.128923459Z [inf]  During handling of the above exception, another exception occurred:
2025-10-28T12:14:23.128930131Z [inf]  
2025-10-28T12:14:23.128935404Z [inf]  Traceback (most recent call last):
2025-10-28T12:14:23.128940753Z [inf]    File "/app/src/core/position_controller.py", line 135, in _fetch_all_positions
2025-10-28T12:14:23.128946429Z [inf]      raw_positions = await self.binance_client.get_position_info_async()
2025-10-28T12:14:23.128951505Z [inf]                      ^^^^^^^^^^^^^^^^^^^^^^^^^^^^^^^^^^^^^^^^^^^^^^^^^^^
2025-10-28T12:14:23.128962978Z [inf]    File "/app/src/clients/binance_client.py", line 469, in get_position_info_async
2025-10-28T12:14:23.128968650Z [inf]      account_info = await self.get_account_info()
2025-10-28T12:14:23.129687452Z [inf]                     ^^^^^^^^^^^^^^^^^^^^^^^^^^^^^
2025-10-28T12:14:23.129698447Z [inf]    File "/app/src/clients/binance_client.py", line 449, in get_account_info
2025-10-28T12:14:23.129706689Z [inf]      result = await self._request("GET", "/fapi/v2/account", signed=True)
2025-10-28T12:14:23.129713090Z [inf]               ^^^^^^^^^^^^^^^^^^^^^^^^^^^^^^^^^^^^^^^^^^^^^^^^^^^^^^^^^^^
2025-10-28T12:14:23.129720329Z [inf]    File "/app/src/clients/binance_client.py", line 213, in _request
2025-10-28T12:14:23.129729164Z [inf]      raise BinanceRequestError(
2025-10-28T12:14:23.129737025Z [inf]  src.clients.binance_errors.BinanceRequestError: 熔斷器阻斷(失敗5次)，請52秒後重試
2025-10-28T12:14:25.092053663Z [inf]      account_info = await self.get_account_info()
2025-10-28T12:14:25.092053758Z [inf]  2025-10-28 12:14:24,995 - src.core.circuit_breaker - ERROR - 🔴 熔斷器阻斷(失敗5次)，請50秒後重試 | 操作: generic | 優先級: NORMAL
2025-10-28T12:14:25.092063771Z [inf]  2025-10-28 12:14:24,995 - src.clients.binance_client - ERROR - API 請求失敗: /fapi/v2/account - 熔斷器阻斷(失敗5次)，請50秒後重試
2025-10-28T12:14:25.092069791Z [inf]  2025-10-28 12:14:24,995 - src.core.position_controller - ERROR - ❌ 獲取持倉失敗: 熔斷器阻斷(失敗5次)，請50秒後重試
2025-10-28T12:14:25.092078732Z [inf]  Traceback (most recent call last):
2025-10-28T12:14:25.092083663Z [inf]    File "/app/src/clients/binance_client.py", line 197, in _request
2025-10-28T12:14:25.092088503Z [inf]      result = await self.circuit_breaker.call_async(_do_request)
2025-10-28T12:14:25.092093655Z [inf]               ^^^^^^^^^^^^^^^^^^^^^^^^^^^^^^^^^^^^^^^^^^^^^^^^^^
2025-10-28T12:14:25.092098949Z [inf]    File "/app/src/core/circuit_breaker.py", line 327, in call_async
2025-10-28T12:14:25.092104919Z [inf]      raise Exception(reason)
2025-10-28T12:14:25.092110548Z [inf]  Exception: 熔斷器阻斷(失敗5次)，請50秒後重試
2025-10-28T12:14:25.092118174Z [inf]  
2025-10-28T12:14:25.092123017Z [inf]  During handling of the above exception, another exception occurred:
2025-10-28T12:14:25.092127539Z [inf]  
2025-10-28T12:14:25.092132281Z [inf]  Traceback (most recent call last):
2025-10-28T12:14:25.092137576Z [inf]    File "/app/src/core/position_controller.py", line 135, in _fetch_all_positions
2025-10-28T12:14:25.092145606Z [inf]      raw_positions = await self.binance_client.get_position_info_async()
2025-10-28T12:14:25.092150098Z [inf]                      ^^^^^^^^^^^^^^^^^^^^^^^^^^^^^^^^^^^^^^^^^^^^^^^^^^^
2025-10-28T12:14:25.092154379Z [inf]    File "/app/src/clients/binance_client.py", line 469, in get_position_info_async
2025-10-28T12:14:25.092613253Z [inf]                     ^^^^^^^^^^^^^^^^^^^^^^^^^^^^^
2025-10-28T12:14:25.092617428Z [inf]    File "/app/src/clients/binance_client.py", line 449, in get_account_info
2025-10-28T12:14:25.092621664Z [inf]      result = await self._request("GET", "/fapi/v2/account", signed=True)
2025-10-28T12:14:25.092625903Z [inf]               ^^^^^^^^^^^^^^^^^^^^^^^^^^^^^^^^^^^^^^^^^^^^^^^^^^^^^^^^^^^
2025-10-28T12:14:25.092630507Z [inf]    File "/app/src/clients/binance_client.py", line 213, in _request
2025-10-28T12:14:25.092634363Z [inf]      raise BinanceRequestError(
2025-10-28T12:14:25.092640136Z [inf]  src.clients.binance_errors.BinanceRequestError: 熔斷器阻斷(失敗5次)，請50秒後重試
2025-10-28T12:14:27.104642081Z [inf]  2025-10-28 12:14:26,997 - src.core.circuit_breaker - ERROR - 🔴 熔斷器阻斷(失敗5次)，請48秒後重試 | 操作: generic | 優先級: NORMAL
2025-10-28T12:14:27.104649654Z [inf]  2025-10-28 12:14:26,997 - src.clients.binance_client - ERROR - API 請求失敗: /fapi/v2/account - 熔斷器阻斷(失敗5次)，請48秒後重試
2025-10-28T12:14:27.104656567Z [inf]  2025-10-28 12:14:26,997 - src.core.position_controller - ERROR - ❌ 獲取持倉失敗: 熔斷器阻斷(失敗5次)，請48秒後重試
2025-10-28T12:14:27.104663992Z [inf]  Traceback (most recent call last):
2025-10-28T12:14:27.104669549Z [inf]    File "/app/src/clients/binance_client.py", line 197, in _request
2025-10-28T12:14:27.104677651Z [inf]      result = await self.circuit_breaker.call_async(_do_request)
2025-10-28T12:14:27.104683307Z [inf]               ^^^^^^^^^^^^^^^^^^^^^^^^^^^^^^^^^^^^^^^^^^^^^^^^^^
2025-10-28T12:14:27.104690035Z [inf]    File "/app/src/core/circuit_breaker.py", line 327, in call_async
2025-10-28T12:14:27.104697293Z [inf]      raise Exception(reason)
2025-10-28T12:14:27.104705062Z [inf]  Exception: 熔斷器阻斷(失敗5次)，請48秒後重試
2025-10-28T12:14:27.104714586Z [inf]  
2025-10-28T12:14:27.104721479Z [inf]  During handling of the above exception, another exception occurred:
2025-10-28T12:14:27.104728171Z [inf]  
2025-10-28T12:14:27.104743237Z [inf]  Traceback (most recent call last):
2025-10-28T12:14:27.104748563Z [inf]    File "/app/src/core/position_controller.py", line 135, in _fetch_all_positions
2025-10-28T12:14:27.104755386Z [inf]      raw_positions = await self.binance_client.get_position_info_async()
2025-10-28T12:14:27.104763262Z [inf]                      ^^^^^^^^^^^^^^^^^^^^^^^^^^^^^^^^^^^^^^^^^^^^^^^^^^^
2025-10-28T12:14:27.104772251Z [inf]    File "/app/src/clients/binance_client.py", line 469, in get_position_info_async
2025-10-28T12:14:27.104783293Z [inf]      account_info = await self.get_account_info()
2025-10-28T12:14:27.104823070Z [inf]                     ^^^^^^^^^^^^^^^^^^^^^^^^^^^^^
2025-10-28T12:14:27.104832506Z [inf]    File "/app/src/clients/binance_client.py", line 449, in get_account_info
2025-10-28T12:14:27.104839026Z [inf]      result = await self._request("GET", "/fapi/v2/account", signed=True)
2025-10-28T12:14:27.104845921Z [inf]               ^^^^^^^^^^^^^^^^^^^^^^^^^^^^^^^^^^^^^^^^^^^^^^^^^^^^^^^^^^^
2025-10-28T12:14:27.104852813Z [inf]    File "/app/src/clients/binance_client.py", line 213, in _request
2025-10-28T12:14:27.104860307Z [inf]      raise BinanceRequestError(
2025-10-28T12:14:27.104868599Z [inf]  src.clients.binance_errors.BinanceRequestError: 熔斷器阻斷(失敗5次)，請48秒後重試
2025-10-28T12:14:29.130703934Z [inf]  2025-10-28 12:14:28,999 - src.core.circuit_breaker - ERROR - 🔴 熔斷器阻斷(失敗5次)，請46秒後重試 | 操作: generic | 優先級: NORMAL
2025-10-28T12:14:29.130714561Z [inf]  2025-10-28 12:14:28,999 - src.clients.binance_client - ERROR - API 請求失敗: /fapi/v2/account - 熔斷器阻斷(失敗5次)，請46秒後重試
2025-10-28T12:14:29.130725567Z [inf]  2025-10-28 12:14:28,999 - src.core.position_controller - ERROR - ❌ 獲取持倉失敗: 熔斷器阻斷(失敗5次)，請46秒後重試
2025-10-28T12:14:29.130733696Z [inf]  Traceback (most recent call last):
2025-10-28T12:14:29.130741467Z [inf]    File "/app/src/clients/binance_client.py", line 197, in _request
2025-10-28T12:14:29.130748895Z [inf]      result = await self.circuit_breaker.call_async(_do_request)
2025-10-28T12:14:29.130764483Z [inf]               ^^^^^^^^^^^^^^^^^^^^^^^^^^^^^^^^^^^^^^^^^^^^^^^^^^
2025-10-28T12:14:29.130773340Z [inf]    File "/app/src/core/circuit_breaker.py", line 327, in call_async
2025-10-28T12:14:29.130781562Z [inf]      raise Exception(reason)
2025-10-28T12:14:29.130797641Z [inf]  Exception: 熔斷器阻斷(失敗5次)，請46秒後重試
2025-10-28T12:14:29.130808295Z [inf]  
2025-10-28T12:14:29.130817294Z [inf]  During handling of the above exception, another exception occurred:
2025-10-28T12:14:29.130824484Z [inf]  
2025-10-28T12:14:29.130831578Z [inf]  Traceback (most recent call last):
2025-10-28T12:14:29.130838929Z [inf]    File "/app/src/core/position_controller.py", line 135, in _fetch_all_positions
2025-10-28T12:14:29.130846424Z [inf]      raw_positions = await self.binance_client.get_position_info_async()
2025-10-28T12:14:29.130853794Z [inf]                      ^^^^^^^^^^^^^^^^^^^^^^^^^^^^^^^^^^^^^^^^^^^^^^^^^^^
2025-10-28T12:14:29.130861998Z [inf]    File "/app/src/clients/binance_client.py", line 469, in get_position_info_async
2025-10-28T12:14:29.130869314Z [inf]      account_info = await self.get_account_info()
2025-10-28T12:14:29.132104757Z [inf]                     ^^^^^^^^^^^^^^^^^^^^^^^^^^^^^
2025-10-28T12:14:29.132114757Z [inf]    File "/app/src/clients/binance_client.py", line 449, in get_account_info
2025-10-28T12:14:29.132121766Z [inf]      result = await self._request("GET", "/fapi/v2/account", signed=True)
2025-10-28T12:14:29.132128485Z [inf]               ^^^^^^^^^^^^^^^^^^^^^^^^^^^^^^^^^^^^^^^^^^^^^^^^^^^^^^^^^^^
2025-10-28T12:14:29.132135698Z [inf]    File "/app/src/clients/binance_client.py", line 213, in _request
2025-10-28T12:14:29.132142065Z [inf]      raise BinanceRequestError(
2025-10-28T12:14:29.132147999Z [inf]  src.clients.binance_errors.BinanceRequestError: 熔斷器阻斷(失敗5次)，請46秒後重試
2025-10-28T12:14:31.092914489Z [inf]    File "/app/src/clients/binance_client.py", line 469, in get_position_info_async
2025-10-28T12:14:31.092930608Z [inf]      account_info = await self.get_account_info()
2025-10-28T12:14:31.092934259Z [inf]    File "/app/src/clients/binance_client.py", line 197, in _request
2025-10-28T12:14:31.092954176Z [inf]      result = await self.circuit_breaker.call_async(_do_request)
2025-10-28T12:14:31.092964611Z [inf]               ^^^^^^^^^^^^^^^^^^^^^^^^^^^^^^^^^^^^^^^^^^^^^^^^^^
2025-10-28T12:14:31.092972829Z [inf]    File "/app/src/core/circuit_breaker.py", line 327, in call_async
2025-10-28T12:14:31.092982360Z [inf]      raise Exception(reason)
2025-10-28T12:14:31.092992863Z [inf]  Exception: 熔斷器阻斷(失敗5次)，請44秒後重試
2025-10-28T12:14:31.093003594Z [inf]  
2025-10-28T12:14:31.093013950Z [inf]  During handling of the above exception, another exception occurred:
2025-10-28T12:14:31.093023397Z [inf]  2025-10-28 12:14:31,002 - src.core.circuit_breaker - ERROR - 🔴 熔斷器阻斷(失敗5次)，請44秒後重試 | 操作: generic | 優先級: NORMAL
2025-10-28T12:14:31.093024480Z [inf]  
2025-10-28T12:14:31.093039100Z [inf]  2025-10-28 12:14:31,003 - src.clients.binance_client - ERROR - API 請求失敗: /fapi/v2/account - 熔斷器阻斷(失敗5次)，請44秒後重試
2025-10-28T12:14:31.093042430Z [inf]  Traceback (most recent call last):
2025-10-28T12:14:31.093048470Z [inf]                     ^^^^^^^^^^^^^^^^^^^^^^^^^^^^^
2025-10-28T12:14:31.093050039Z [inf]  2025-10-28 12:14:31,003 - src.core.position_controller - ERROR - ❌ 獲取持倉失敗: 熔斷器阻斷(失敗5次)，請44秒後重試
2025-10-28T12:14:31.093054678Z [inf]    File "/app/src/core/position_controller.py", line 135, in _fetch_all_positions
2025-10-28T12:14:31.093064059Z [inf]  Traceback (most recent call last):
2025-10-28T12:14:31.093067613Z [inf]    File "/app/src/clients/binance_client.py", line 449, in get_account_info
2025-10-28T12:14:31.093068038Z [inf]      raw_positions = await self.binance_client.get_position_info_async()
2025-10-28T12:14:31.093079768Z [inf]                      ^^^^^^^^^^^^^^^^^^^^^^^^^^^^^^^^^^^^^^^^^^^^^^^^^^^
2025-10-28T12:14:31.093083535Z [inf]      result = await self._request("GET", "/fapi/v2/account", signed=True)
2025-10-28T12:14:31.093095151Z [inf]               ^^^^^^^^^^^^^^^^^^^^^^^^^^^^^^^^^^^^^^^^^^^^^^^^^^^^^^^^^^^
2025-10-28T12:14:31.093104162Z [inf]    File "/app/src/clients/binance_client.py", line 213, in _request
2025-10-28T12:14:31.093113174Z [inf]      raise BinanceRequestError(
2025-10-28T12:14:31.093122350Z [inf]  src.clients.binance_errors.BinanceRequestError: 熔斷器阻斷(失敗5次)，請44秒後重試
2025-10-28T12:14:33.125162973Z [inf]  2025-10-28 12:14:33,004 - src.core.circuit_breaker - ERROR - 🔴 熔斷器阻斷(失敗5次)，請42秒後重試 | 操作: generic | 優先級: NORMAL
2025-10-28T12:14:33.125177422Z [inf]  2025-10-28 12:14:33,004 - src.clients.binance_client - ERROR - API 請求失敗: /fapi/v2/account - 熔斷器阻斷(失敗5次)，請42秒後重試
2025-10-28T12:14:33.125186811Z [inf]  2025-10-28 12:14:33,005 - src.core.position_controller - ERROR - ❌ 獲取持倉失敗: 熔斷器阻斷(失敗5次)，請42秒後重試
2025-10-28T12:14:33.125194681Z [inf]  Traceback (most recent call last):
2025-10-28T12:14:33.125202396Z [inf]    File "/app/src/clients/binance_client.py", line 197, in _request
2025-10-28T12:14:33.125210637Z [inf]      result = await self.circuit_breaker.call_async(_do_request)
2025-10-28T12:14:33.125218466Z [inf]               ^^^^^^^^^^^^^^^^^^^^^^^^^^^^^^^^^^^^^^^^^^^^^^^^^^
2025-10-28T12:14:33.125226650Z [inf]    File "/app/src/core/circuit_breaker.py", line 327, in call_async
2025-10-28T12:14:33.125233791Z [inf]      raise Exception(reason)
2025-10-28T12:14:33.125242507Z [inf]  Exception: 熔斷器阻斷(失敗5次)，請42秒後重試
2025-10-28T12:14:33.125250319Z [inf]  
2025-10-28T12:14:33.125258774Z [inf]  During handling of the above exception, another exception occurred:
2025-10-28T12:14:33.125266222Z [inf]  
2025-10-28T12:14:33.125274130Z [inf]  Traceback (most recent call last):
2025-10-28T12:14:33.125285285Z [inf]    File "/app/src/core/position_controller.py", line 135, in _fetch_all_positions
2025-10-28T12:14:33.125292975Z [inf]      raw_positions = await self.binance_client.get_position_info_async()
2025-10-28T12:14:33.125300922Z [inf]                      ^^^^^^^^^^^^^^^^^^^^^^^^^^^^^^^^^^^^^^^^^^^^^^^^^^^
2025-10-28T12:14:33.125309066Z [inf]    File "/app/src/clients/binance_client.py", line 469, in get_position_info_async
2025-10-28T12:14:33.125316488Z [inf]      account_info = await self.get_account_info()
2025-10-28T12:14:33.125884157Z [inf]                     ^^^^^^^^^^^^^^^^^^^^^^^^^^^^^
2025-10-28T12:14:33.125893830Z [inf]    File "/app/src/clients/binance_client.py", line 449, in get_account_info
2025-10-28T12:14:33.125900701Z [inf]      result = await self._request("GET", "/fapi/v2/account", signed=True)
2025-10-28T12:14:33.125906428Z [inf]               ^^^^^^^^^^^^^^^^^^^^^^^^^^^^^^^^^^^^^^^^^^^^^^^^^^^^^^^^^^^
2025-10-28T12:14:33.125910593Z [inf]    File "/app/src/clients/binance_client.py", line 213, in _request
2025-10-28T12:14:33.125916547Z [inf]      raise BinanceRequestError(
2025-10-28T12:14:33.125922837Z [inf]  src.clients.binance_errors.BinanceRequestError: 熔斷器阻斷(失敗5次)，請42秒後重試
2025-10-28T12:14:35.214149380Z [inf]    File "/app/src/core/position_controller.py", line 135, in _fetch_all_positions
2025-10-28T12:14:35.214159532Z [inf]      raw_positions = await self.binance_client.get_position_info_async()
2025-10-28T12:14:35.214165012Z [inf]                      ^^^^^^^^^^^^^^^^^^^^^^^^^^^^^^^^^^^^^^^^^^^^^^^^^^^
2025-10-28T12:14:35.214172575Z [inf]    File "/app/src/clients/binance_client.py", line 469, in get_position_info_async
2025-10-28T12:14:35.214177128Z [inf]      account_info = await self.get_account_info()
2025-10-28T12:14:35.214191338Z [inf]               ^^^^^^^^^^^^^^^^^^^^^^^^^^^^^^^^^^^^^^^^^^^^^^^^^^
2025-10-28T12:14:35.214197396Z [inf]    File "/app/src/core/circuit_breaker.py", line 327, in call_async
2025-10-28T12:14:35.214203119Z [inf]      raise Exception(reason)
2025-10-28T12:14:35.214206220Z [inf]  2025-10-28 12:14:35,008 - src.core.circuit_breaker - ERROR - 🔴 熔斷器阻斷(失敗5次)，請40秒後重試 | 操作: generic | 優先級: NORMAL
2025-10-28T12:14:35.214211563Z [inf]  2025-10-28 12:14:35,008 - src.clients.binance_client - ERROR - API 請求失敗: /fapi/v2/account - 熔斷器阻斷(失敗5次)，請40秒後重試
2025-10-28T12:14:35.214214259Z [inf]  Exception: 熔斷器阻斷(失敗5次)，請40秒後重試
2025-10-28T12:14:35.214217692Z [inf]  2025-10-28 12:14:35,008 - src.core.position_controller - ERROR - ❌ 獲取持倉失敗: 熔斷器阻斷(失敗5次)，請40秒後重試
2025-10-28T12:14:35.214224169Z [inf]  
2025-10-28T12:14:35.214225036Z [inf]  Traceback (most recent call last):
2025-10-28T12:14:35.214231246Z [inf]    File "/app/src/clients/binance_client.py", line 197, in _request
2025-10-28T12:14:35.214235334Z [inf]  During handling of the above exception, another exception occurred:
2025-10-28T12:14:35.214239283Z [inf]      result = await self.circuit_breaker.call_async(_do_request)
2025-10-28T12:14:35.214242054Z [inf]  
2025-10-28T12:14:35.214247525Z [inf]  Traceback (most recent call last):
2025-10-28T12:14:35.216617204Z [inf]                     ^^^^^^^^^^^^^^^^^^^^^^^^^^^^^
2025-10-28T12:14:35.216622236Z [inf]    File "/app/src/clients/binance_client.py", line 449, in get_account_info
2025-10-28T12:14:35.216628024Z [inf]      result = await self._request("GET", "/fapi/v2/account", signed=True)
2025-10-28T12:14:35.216633886Z [inf]               ^^^^^^^^^^^^^^^^^^^^^^^^^^^^^^^^^^^^^^^^^^^^^^^^^^^^^^^^^^^
2025-10-28T12:14:35.216639684Z [inf]    File "/app/src/clients/binance_client.py", line 213, in _request
2025-10-28T12:14:35.216645414Z [inf]      raise BinanceRequestError(
2025-10-28T12:14:35.216651392Z [inf]  src.clients.binance_errors.BinanceRequestError: 熔斷器阻斷(失敗5次)，請40秒後重試
2025-10-28T12:14:37.155859288Z [inf]    File "/app/src/core/circuit_breaker.py", line 327, in call_async
2025-10-28T12:14:37.155868369Z [inf]      raise Exception(reason)
2025-10-28T12:14:37.155873507Z [inf]  Exception: 熔斷器阻斷(失敗5次)，請38秒後重試
2025-10-28T12:14:37.155879032Z [inf]  
2025-10-28T12:14:37.155883627Z [inf]  During handling of the above exception, another exception occurred:
2025-10-28T12:14:37.155888547Z [inf]  
2025-10-28T12:14:37.155894632Z [inf]  Traceback (most recent call last):
2025-10-28T12:14:37.155900979Z [inf]    File "/app/src/core/position_controller.py", line 135, in _fetch_all_positions
2025-10-28T12:14:37.155904653Z [inf]  2025-10-28 12:14:37,010 - src.core.circuit_breaker - ERROR - 🔴 熔斷器阻斷(失敗5次)，請38秒後重試 | 操作: generic | 優先級: NORMAL
2025-10-28T12:14:37.155908475Z [inf]      raw_positions = await self.binance_client.get_position_info_async()
2025-10-28T12:14:37.155911348Z [inf]  2025-10-28 12:14:37,010 - src.clients.binance_client - ERROR - API 請求失敗: /fapi/v2/account - 熔斷器阻斷(失敗5次)，請38秒後重試
2025-10-28T12:14:37.155917563Z [inf]  2025-10-28 12:14:37,010 - src.core.position_controller - ERROR - ❌ 獲取持倉失敗: 熔斷器阻斷(失敗5次)，請38秒後重試
2025-10-28T12:14:37.155917666Z [inf]                      ^^^^^^^^^^^^^^^^^^^^^^^^^^^^^^^^^^^^^^^^^^^^^^^^^^^
2025-10-28T12:14:37.155927601Z [inf]  Traceback (most recent call last):
2025-10-28T12:14:37.155930255Z [inf]    File "/app/src/clients/binance_client.py", line 469, in get_position_info_async
2025-10-28T12:14:37.155933166Z [inf]    File "/app/src/clients/binance_client.py", line 197, in _request
2025-10-28T12:14:37.155939871Z [inf]      result = await self.circuit_breaker.call_async(_do_request)
2025-10-28T12:14:37.155942935Z [inf]      account_info = await self.get_account_info()
2025-10-28T12:14:37.155945612Z [inf]               ^^^^^^^^^^^^^^^^^^^^^^^^^^^^^^^^^^^^^^^^^^^^^^^^^^
2025-10-28T12:14:37.157041225Z [inf]      raise BinanceRequestError(
2025-10-28T12:14:37.157049686Z [inf]  src.clients.binance_errors.BinanceRequestError: 熔斷器阻斷(失敗5次)，請38秒後重試
2025-10-28T12:14:37.157052970Z [inf]                     ^^^^^^^^^^^^^^^^^^^^^^^^^^^^^
2025-10-28T12:14:37.157063290Z [inf]    File "/app/src/clients/binance_client.py", line 449, in get_account_info
2025-10-28T12:14:37.157070606Z [inf]      result = await self._request("GET", "/fapi/v2/account", signed=True)
2025-10-28T12:14:37.157075946Z [inf]               ^^^^^^^^^^^^^^^^^^^^^^^^^^^^^^^^^^^^^^^^^^^^^^^^^^^^^^^^^^^
2025-10-28T12:14:37.157085304Z [inf]    File "/app/src/clients/binance_client.py", line 213, in _request
2025-10-28T12:14:39.189146461Z [inf]  Exception: 熔斷器阻斷(失敗5次)，請36秒後重試
2025-10-28T12:14:39.189162340Z [inf]  
2025-10-28T12:14:39.189170169Z [inf]  During handling of the above exception, another exception occurred:
2025-10-28T12:14:39.189178971Z [inf]  
2025-10-28T12:14:39.189185448Z [inf]  Traceback (most recent call last):
2025-10-28T12:14:39.189193101Z [inf]    File "/app/src/core/position_controller.py", line 135, in _fetch_all_positions
2025-10-28T12:14:39.189200195Z [inf]      raw_positions = await self.binance_client.get_position_info_async()
2025-10-28T12:14:39.189207404Z [inf]                      ^^^^^^^^^^^^^^^^^^^^^^^^^^^^^^^^^^^^^^^^^^^^^^^^^^^
2025-10-28T12:14:39.189220201Z [inf]    File "/app/src/clients/binance_client.py", line 469, in get_position_info_async
2025-10-28T12:14:39.189228378Z [inf]      account_info = await self.get_account_info()
2025-10-28T12:14:39.189382432Z [inf]  2025-10-28 12:14:39,012 - src.core.circuit_breaker - ERROR - 🔴 熔斷器阻斷(失敗5次)，請36秒後重試 | 操作: generic | 優先級: NORMAL
2025-10-28T12:14:39.189388885Z [inf]  2025-10-28 12:14:39,012 - src.clients.binance_client - ERROR - API 請求失敗: /fapi/v2/account - 熔斷器阻斷(失敗5次)，請36秒後重試
2025-10-28T12:14:39.189395384Z [inf]  2025-10-28 12:14:39,012 - src.core.position_controller - ERROR - ❌ 獲取持倉失敗: 熔斷器阻斷(失敗5次)，請36秒後重試
2025-10-28T12:14:39.189403784Z [inf]  Traceback (most recent call last):
2025-10-28T12:14:39.189409265Z [inf]    File "/app/src/clients/binance_client.py", line 197, in _request
2025-10-28T12:14:39.189413767Z [inf]      result = await self.circuit_breaker.call_async(_do_request)
2025-10-28T12:14:39.189418414Z [inf]               ^^^^^^^^^^^^^^^^^^^^^^^^^^^^^^^^^^^^^^^^^^^^^^^^^^
2025-10-28T12:14:39.189424493Z [inf]    File "/app/src/core/circuit_breaker.py", line 327, in call_async
2025-10-28T12:14:39.189429336Z [inf]      raise Exception(reason)
2025-10-28T12:14:39.189753664Z [inf]                     ^^^^^^^^^^^^^^^^^^^^^^^^^^^^^
2025-10-28T12:14:39.189762104Z [inf]    File "/app/src/clients/binance_client.py", line 449, in get_account_info
2025-10-28T12:14:39.189767957Z [inf]      result = await self._request("GET", "/fapi/v2/account", signed=True)
2025-10-28T12:14:39.189773698Z [inf]               ^^^^^^^^^^^^^^^^^^^^^^^^^^^^^^^^^^^^^^^^^^^^^^^^^^^^^^^^^^^
2025-10-28T12:14:39.189779344Z [inf]    File "/app/src/clients/binance_client.py", line 213, in _request
2025-10-28T12:14:39.189788271Z [inf]      raise BinanceRequestError(
2025-10-28T12:14:39.189794379Z [inf]  src.clients.binance_errors.BinanceRequestError: 熔斷器阻斷(失敗5次)，請36秒後重試
2025-10-28T12:14:41.137547505Z [inf]  2025-10-28 12:14:41,016 - src.core.circuit_breaker - ERROR - 🔴 熔斷器阻斷(失敗5次)，請34秒後重試 | 操作: generic | 優先級: NORMAL
2025-10-28T12:14:41.137553254Z [inf]  2025-10-28 12:14:41,016 - src.clients.binance_client - ERROR - API 請求失敗: /fapi/v2/account - 熔斷器阻斷(失敗5次)，請34秒後重試
2025-10-28T12:14:41.137558397Z [inf]  2025-10-28 12:14:41,016 - src.core.position_controller - ERROR - ❌ 獲取持倉失敗: 熔斷器阻斷(失敗5次)，請34秒後重試
2025-10-28T12:14:41.137563764Z [inf]  Traceback (most recent call last):
2025-10-28T12:14:41.137568915Z [inf]    File "/app/src/clients/binance_client.py", line 197, in _request
2025-10-28T12:14:41.137573661Z [inf]      result = await self.circuit_breaker.call_async(_do_request)
2025-10-28T12:14:41.137578711Z [inf]               ^^^^^^^^^^^^^^^^^^^^^^^^^^^^^^^^^^^^^^^^^^^^^^^^^^
2025-10-28T12:14:41.137584184Z [inf]    File "/app/src/core/circuit_breaker.py", line 327, in call_async
2025-10-28T12:14:41.137589123Z [inf]      raise Exception(reason)
2025-10-28T12:14:41.137595153Z [inf]  Exception: 熔斷器阻斷(失敗5次)，請34秒後重試
2025-10-28T12:14:41.137601530Z [inf]  
2025-10-28T12:14:41.137607355Z [inf]  During handling of the above exception, another exception occurred:
2025-10-28T12:14:41.137613630Z [inf]  
2025-10-28T12:14:41.137619088Z [inf]  Traceback (most recent call last):
2025-10-28T12:14:41.137624494Z [inf]    File "/app/src/core/position_controller.py", line 135, in _fetch_all_positions
2025-10-28T12:14:41.137629783Z [inf]      raw_positions = await self.binance_client.get_position_info_async()
2025-10-28T12:14:41.137635600Z [inf]                      ^^^^^^^^^^^^^^^^^^^^^^^^^^^^^^^^^^^^^^^^^^^^^^^^^^^
2025-10-28T12:14:41.137640958Z [inf]    File "/app/src/clients/binance_client.py", line 469, in get_position_info_async
2025-10-28T12:14:41.137645959Z [inf]      account_info = await self.get_account_info()
2025-10-28T12:14:41.138159693Z [inf]                     ^^^^^^^^^^^^^^^^^^^^^^^^^^^^^
2025-10-28T12:14:41.138164634Z [inf]    File "/app/src/clients/binance_client.py", line 449, in get_account_info
2025-10-28T12:14:41.138168592Z [inf]      result = await self._request("GET", "/fapi/v2/account", signed=True)
2025-10-28T12:14:41.138172920Z [inf]               ^^^^^^^^^^^^^^^^^^^^^^^^^^^^^^^^^^^^^^^^^^^^^^^^^^^^^^^^^^^
2025-10-28T12:14:41.138177412Z [inf]    File "/app/src/clients/binance_client.py", line 213, in _request
2025-10-28T12:14:41.138182699Z [inf]      raise BinanceRequestError(
2025-10-28T12:14:41.138186714Z [inf]  src.clients.binance_errors.BinanceRequestError: 熔斷器阻斷(失敗5次)，請34秒後重試
2025-10-28T12:14:43.233905727Z [inf]               ^^^^^^^^^^^^^^^^^^^^^^^^^^^^^^^^^^^^^^^^^^^^^^^^^^
2025-10-28T12:14:43.233908379Z [inf]  2025-10-28 12:14:43,018 - src.core.circuit_breaker - ERROR - 🔴 熔斷器阻斷(失敗5次)，請32秒後重試 | 操作: generic | 優先級: NORMAL
2025-10-28T12:14:43.233914514Z [inf]  During handling of the above exception, another exception occurred:
2025-10-28T12:14:43.233915930Z [inf]  2025-10-28 12:14:43,019 - src.clients.binance_client - ERROR - API 請求失敗: /fapi/v2/account - 熔斷器阻斷(失敗5次)，請32秒後重試
2025-10-28T12:14:43.233916517Z [inf]    File "/app/src/core/circuit_breaker.py", line 327, in call_async
2025-10-28T12:14:43.233924509Z [inf]  2025-10-28 12:14:43,019 - src.core.position_controller - ERROR - ❌ 獲取持倉失敗: 熔斷器阻斷(失敗5次)，請32秒後重試
2025-10-28T12:14:43.233925048Z [inf]      raise Exception(reason)
2025-10-28T12:14:43.233926836Z [inf]  src.clients.binance_errors.BinanceRequestError: 熔斷器阻斷(失敗5次)，請32秒後重試
2025-10-28T12:14:43.233927898Z [inf]  
2025-10-28T12:14:43.233934938Z [inf]  Exception: 熔斷器阻斷(失敗5次)，請32秒後重試
2025-10-28T12:14:43.233935706Z [inf]  Traceback (most recent call last):
2025-10-28T12:14:43.233939086Z [inf]  Traceback (most recent call last):
2025-10-28T12:14:43.233944859Z [inf]    File "/app/src/clients/binance_client.py", line 197, in _request
2025-10-28T12:14:43.233945308Z [inf]  
2025-10-28T12:14:43.233949110Z [inf]    File "/app/src/core/position_controller.py", line 135, in _fetch_all_positions
2025-10-28T12:14:43.233950834Z [inf]                      ^^^^^^^^^^^^^^^^^^^^^^^^^^^^^^^^^^^^^^^^^^^^^^^^^^^
2025-10-28T12:14:43.233954933Z [inf]      result = await self.circuit_breaker.call_async(_do_request)
2025-10-28T12:14:43.233958523Z [inf]      raw_positions = await self.binance_client.get_position_info_async()
2025-10-28T12:14:43.233960596Z [inf]    File "/app/src/clients/binance_client.py", line 469, in get_position_info_async
2025-10-28T12:14:43.233970633Z [inf]      account_info = await self.get_account_info()
2025-10-28T12:14:43.233979464Z [inf]                     ^^^^^^^^^^^^^^^^^^^^^^^^^^^^^
2025-10-28T12:14:43.233986890Z [inf]      result = await self._request("GET", "/fapi/v2/account", signed=True)
2025-10-28T12:14:43.233987420Z [inf]    File "/app/src/clients/binance_client.py", line 449, in get_account_info
2025-10-28T12:14:43.234003781Z [inf]               ^^^^^^^^^^^^^^^^^^^^^^^^^^^^^^^^^^^^^^^^^^^^^^^^^^^^^^^^^^^
2025-10-28T12:14:43.234013728Z [inf]    File "/app/src/clients/binance_client.py", line 213, in _request
2025-10-28T12:14:43.234022957Z [inf]      raise BinanceRequestError(
2025-10-28T12:14:45.271004727Z [inf]  2025-10-28 12:14:45,021 - src.core.circuit_breaker - ERROR - 🔴 熔斷器阻斷(失敗5次)，請30秒後重試 | 操作: generic | 優先級: NORMAL
2025-10-28T12:14:45.271017487Z [inf]  2025-10-28 12:14:45,022 - src.clients.binance_client - ERROR - API 請求失敗: /fapi/v2/account - 熔斷器阻斷(失敗5次)，請30秒後重試
2025-10-28T12:14:45.271031444Z [inf]  2025-10-28 12:14:45,022 - src.core.position_controller - ERROR - ❌ 獲取持倉失敗: 熔斷器阻斷(失敗5次)，請30秒後重試
2025-10-28T12:14:45.271127474Z [inf]  Traceback (most recent call last):
2025-10-28T12:14:45.271141078Z [inf]    File "/app/src/clients/binance_client.py", line 197, in _request
2025-10-28T12:14:45.271149639Z [inf]      result = await self.circuit_breaker.call_async(_do_request)
2025-10-28T12:14:45.271157434Z [inf]               ^^^^^^^^^^^^^^^^^^^^^^^^^^^^^^^^^^^^^^^^^^^^^^^^^^
2025-10-28T12:14:45.271166990Z [inf]    File "/app/src/core/circuit_breaker.py", line 327, in call_async
2025-10-28T12:14:45.271175481Z [inf]      raise Exception(reason)
2025-10-28T12:14:45.271185465Z [inf]  Exception: 熔斷器阻斷(失敗5次)，請30秒後重試
2025-10-28T12:14:45.271194602Z [inf]  
2025-10-28T12:14:45.271202210Z [inf]  During handling of the above exception, another exception occurred:
2025-10-28T12:14:45.271209986Z [inf]  
2025-10-28T12:14:45.271216578Z [inf]  Traceback (most recent call last):
2025-10-28T12:14:45.271223745Z [inf]    File "/app/src/core/position_controller.py", line 135, in _fetch_all_positions
2025-10-28T12:14:45.271232408Z [inf]      raw_positions = await self.binance_client.get_position_info_async()
2025-10-28T12:14:45.271241011Z [inf]                      ^^^^^^^^^^^^^^^^^^^^^^^^^^^^^^^^^^^^^^^^^^^^^^^^^^^
2025-10-28T12:14:45.271245784Z [inf]                     ^^^^^^^^^^^^^^^^^^^^^^^^^^^^^
2025-10-28T12:14:45.271253120Z [inf]    File "/app/src/clients/binance_client.py", line 469, in get_position_info_async
2025-10-28T12:14:45.271257425Z [inf]    File "/app/src/clients/binance_client.py", line 449, in get_account_info
2025-10-28T12:14:45.271267218Z [inf]      account_info = await self.get_account_info()
2025-10-28T12:14:45.271270387Z [inf]      result = await self._request("GET", "/fapi/v2/account", signed=True)
2025-10-28T12:14:45.271276368Z [inf]               ^^^^^^^^^^^^^^^^^^^^^^^^^^^^^^^^^^^^^^^^^^^^^^^^^^^^^^^^^^^
2025-10-28T12:14:45.271281493Z [inf]    File "/app/src/clients/binance_client.py", line 213, in _request
2025-10-28T12:14:45.271286480Z [inf]      raise BinanceRequestError(
2025-10-28T12:14:45.271291382Z [inf]  src.clients.binance_errors.BinanceRequestError: 熔斷器阻斷(失敗5次)，請30秒後重試
2025-10-28T12:14:47.287700774Z [inf]                     ^^^^^^^^^^^^^^^^^^^^^^^^^^^^^
2025-10-28T12:14:47.287707661Z [inf]    File "/app/src/clients/binance_client.py", line 449, in get_account_info
2025-10-28T12:14:47.287716421Z [inf]      result = await self._request("GET", "/fapi/v2/account", signed=True)
2025-10-28T12:14:47.287723867Z [inf]               ^^^^^^^^^^^^^^^^^^^^^^^^^^^^^^^^^^^^^^^^^^^^^^^^^^^^^^^^^^^
2025-10-28T12:14:47.287729531Z [inf]  2025-10-28 12:14:47,023 - src.core.circuit_breaker - ERROR - 🔴 熔斷器阻斷(失敗5次)，請28秒後重試 | 操作: generic | 優先級: NORMAL
2025-10-28T12:14:47.287731317Z [inf]    File "/app/src/clients/binance_client.py", line 213, in _request
2025-10-28T12:14:47.287737180Z [inf]  2025-10-28 12:14:47,023 - src.clients.binance_client - ERROR - API 請求失敗: /fapi/v2/account - 熔斷器阻斷(失敗5次)，請28秒後重試
2025-10-28T12:14:47.287742455Z [inf]  2025-10-28 12:14:47,024 - src.core.position_controller - ERROR - ❌ 獲取持倉失敗: 熔斷器阻斷(失敗5次)，請28秒後重試
2025-10-28T12:14:47.287743714Z [inf]      raise BinanceRequestError(
2025-10-28T12:14:47.287747478Z [inf]  Traceback (most recent call last):
2025-10-28T12:14:47.287752381Z [inf]  src.clients.binance_errors.BinanceRequestError: 熔斷器阻斷(失敗5次)，請28秒後重試
2025-10-28T12:14:47.287754325Z [inf]    File "/app/src/clients/binance_client.py", line 197, in _request
2025-10-28T12:14:47.287758412Z [inf]      result = await self.circuit_breaker.call_async(_do_request)
2025-10-28T12:14:47.287762051Z [inf]               ^^^^^^^^^^^^^^^^^^^^^^^^^^^^^^^^^^^^^^^^^^^^^^^^^^
2025-10-28T12:14:47.287766233Z [inf]    File "/app/src/core/circuit_breaker.py", line 327, in call_async
2025-10-28T12:14:47.287770623Z [inf]      raise Exception(reason)
2025-10-28T12:14:47.287775221Z [inf]  Exception: 熔斷器阻斷(失敗5次)，請28秒後重試
2025-10-28T12:14:47.287779587Z [inf]  
2025-10-28T12:14:47.287783462Z [inf]  During handling of the above exception, another exception occurred:
2025-10-28T12:14:47.287787086Z [inf]  
2025-10-28T12:14:47.287791092Z [inf]  Traceback (most recent call last):
2025-10-28T12:14:47.287795921Z [inf]    File "/app/src/core/position_controller.py", line 135, in _fetch_all_positions
2025-10-28T12:14:47.287801375Z [inf]      raw_positions = await self.binance_client.get_position_info_async()
2025-10-28T12:14:47.287805733Z [inf]                      ^^^^^^^^^^^^^^^^^^^^^^^^^^^^^^^^^^^^^^^^^^^^^^^^^^^
2025-10-28T12:14:47.287810714Z [inf]    File "/app/src/clients/binance_client.py", line 469, in get_position_info_async
2025-10-28T12:14:47.287814809Z [inf]      account_info = await self.get_account_info()
2025-10-28T12:14:49.329836922Z [inf]  During handling of the above exception, another exception occurred:
2025-10-28T12:14:49.329854186Z [inf]  
2025-10-28T12:14:49.329863035Z [inf]  Traceback (most recent call last):
2025-10-28T12:14:49.329869518Z [inf]    File "/app/src/core/position_controller.py", line 135, in _fetch_all_positions
2025-10-28T12:14:49.329877513Z [inf]      raw_positions = await self.binance_client.get_position_info_async()
2025-10-28T12:14:49.329887975Z [inf]                      ^^^^^^^^^^^^^^^^^^^^^^^^^^^^^^^^^^^^^^^^^^^^^^^^^^^
2025-10-28T12:14:49.329895491Z [inf]    File "/app/src/clients/binance_client.py", line 469, in get_position_info_async
2025-10-28T12:14:49.329906956Z [inf]  2025-10-28 12:14:49,026 - src.core.circuit_breaker - ERROR - 🔴 熔斷器阻斷(失敗5次)，請26秒後重試 | 操作: generic | 優先級: NORMAL
2025-10-28T12:14:49.329907828Z [inf]      account_info = await self.get_account_info()
2025-10-28T12:14:49.329914652Z [inf]  2025-10-28 12:14:49,026 - src.clients.binance_client - ERROR - API 請求失敗: /fapi/v2/account - 熔斷器阻斷(失敗5次)，請26秒後重試
2025-10-28T12:14:49.329920567Z [inf]  2025-10-28 12:14:49,026 - src.core.position_controller - ERROR - ❌ 獲取持倉失敗: 熔斷器阻斷(失敗5次)，請26秒後重試
2025-10-28T12:14:49.329926410Z [inf]  Traceback (most recent call last):
2025-10-28T12:14:49.329933139Z [inf]    File "/app/src/clients/binance_client.py", line 197, in _request
2025-10-28T12:14:49.329938708Z [inf]      result = await self.circuit_breaker.call_async(_do_request)
2025-10-28T12:14:49.329944790Z [inf]               ^^^^^^^^^^^^^^^^^^^^^^^^^^^^^^^^^^^^^^^^^^^^^^^^^^
2025-10-28T12:14:49.329949366Z [inf]    File "/app/src/core/circuit_breaker.py", line 327, in call_async
2025-10-28T12:14:49.329955753Z [inf]      raise Exception(reason)
2025-10-28T12:14:49.329961759Z [inf]  Exception: 熔斷器阻斷(失敗5次)，請26秒後重試
2025-10-28T12:14:49.329967556Z [inf]  
2025-10-28T12:14:49.330037585Z [inf]                     ^^^^^^^^^^^^^^^^^^^^^^^^^^^^^
2025-10-28T12:14:49.330044102Z [inf]    File "/app/src/clients/binance_client.py", line 449, in get_account_info
2025-10-28T12:14:49.330051292Z [inf]      result = await self._request("GET", "/fapi/v2/account", signed=True)
2025-10-28T12:14:49.330056931Z [inf]               ^^^^^^^^^^^^^^^^^^^^^^^^^^^^^^^^^^^^^^^^^^^^^^^^^^^^^^^^^^^
2025-10-28T12:14:49.330062585Z [inf]    File "/app/src/clients/binance_client.py", line 213, in _request
2025-10-28T12:14:49.332486132Z [inf]      raise BinanceRequestError(
2025-10-28T12:14:49.332495329Z [inf]  src.clients.binance_errors.BinanceRequestError: 熔斷器阻斷(失敗5次)，請26秒後重試
2025-10-28T12:14:50.011220398Z [inf]  2025-10-28 12:14:50,004 - src.clients.binance_client - ERROR - API 請求失敗: /fapi/v2/account - 熔斷器阻斷(失敗5次)，請25秒後重試
2025-10-28T12:14:50.011222946Z [inf]  2025-10-28 12:14:50,004 - src.core.unified_scheduler - INFO - ================================================================================
2025-10-28T12:14:50.011229217Z [inf]  2025-10-28 12:14:50,004 - src.core.unified_scheduler - ERROR - ❌ 交易週期執行失敗: 熔斷器阻斷(失敗5次)，請25秒後重試
2025-10-28T12:14:50.011233379Z [inf]  2025-10-28 12:14:50,004 - src.core.unified_scheduler - INFO - 🔄 交易週期 #4 | 2025-10-28 12:14:50 UTC
2025-10-28T12:14:50.011238354Z [inf]  Traceback (most recent call last):
2025-10-28T12:14:50.011241142Z [inf]  2025-10-28 12:14:50,004 - src.core.unified_scheduler - INFO - ================================================================================
2025-10-28T12:14:50.011245201Z [inf]    File "/app/src/clients/binance_client.py", line 197, in _request
2025-10-28T12:14:50.011248231Z [inf]  2025-10-28 12:14:50,004 - src.core.circuit_breaker - ERROR - 🔴 熔斷器阻斷(失敗5次)，請25秒後重試 | 操作: generic | 優先級: NORMAL
2025-10-28T12:14:50.011251696Z [inf]      result = await self.circuit_breaker.call_async(_do_request)
2025-10-28T12:14:50.011254820Z [inf]  2025-10-28 12:14:50,004 - src.clients.binance_client - ERROR - API 請求失敗: /fapi/v2/account - 熔斷器阻斷(失敗5次)，請25秒後重試
2025-10-28T12:14:50.011259223Z [inf]               ^^^^^^^^^^^^^^^^^^^^^^^^^^^^^^^^^^^^^^^^^^^^^^^^^^
2025-10-28T12:14:50.011261145Z [inf]  2025-10-28 12:14:50,004 - src.core.unified_scheduler - ERROR - ❌ 獲取持倉失敗: 熔斷器阻斷(失敗5次)，請25秒後重試
2025-10-28T12:14:50.011265956Z [inf]  2025-10-28 12:14:50,004 - src.core.circuit_breaker - ERROR - 🔴 熔斷器阻斷(失敗5次)，請25秒後重試 | 操作: generic | 優先級: NORMAL
2025-10-28T12:14:50.012065350Z [inf]    File "/app/src/core/circuit_breaker.py", line 327, in call_async
2025-10-28T12:14:50.012074682Z [inf]      raise Exception(reason)
2025-10-28T12:14:50.012079954Z [inf]  Exception: 熔斷器阻斷(失敗5次)，請25秒後重試
2025-10-28T12:14:50.012085293Z [inf]  
2025-10-28T12:14:50.012087845Z [inf]      result = await self._request("GET", "/fapi/v2/account", signed=True)
2025-10-28T12:14:50.012091034Z [inf]  During handling of the above exception, another exception occurred:
2025-10-28T12:14:50.012096209Z [inf]  
2025-10-28T12:14:50.012099255Z [inf]               ^^^^^^^^^^^^^^^^^^^^^^^^^^^^^^^^^^^^^^^^^^^^^^^^^^^^^^^^^^^
2025-10-28T12:14:50.012102002Z [inf]  Traceback (most recent call last):
2025-10-28T12:14:50.012107584Z [inf]    File "/app/src/clients/binance_client.py", line 213, in _request
2025-10-28T12:14:50.012108833Z [inf]    File "/app/src/core/unified_scheduler.py", line 212, in _execute_trading_cycle
2025-10-28T12:14:50.012115551Z [inf]      account_info = await self.binance_client.get_account_info()
2025-10-28T12:14:50.012117004Z [inf]      raise BinanceRequestError(
2025-10-28T12:14:50.012121581Z [inf]                     ^^^^^^^^^^^^^^^^^^^^^^^^^^^^^^^^^^^^^^^^^^^^
2025-10-28T12:14:50.012125256Z [inf]  src.clients.binance_errors.BinanceRequestError: 熔斷器阻斷(失敗5次)，請25秒後重試
2025-10-28T12:14:50.012127747Z [inf]    File "/app/src/clients/binance_client.py", line 449, in get_account_info
2025-10-28T12:14:51.033712320Z [inf]  2025-10-28 12:14:51,028 - src.core.circuit_breaker - ERROR - 🔴 熔斷器阻斷(失敗5次)，請24秒後重試 | 操作: generic | 優先級: NORMAL
2025-10-28T12:14:51.033722307Z [inf]  2025-10-28 12:14:51,028 - src.clients.binance_client - ERROR - API 請求失敗: /fapi/v2/account - 熔斷器阻斷(失敗5次)，請24秒後重試
2025-10-28T12:14:51.033722562Z [inf]  
2025-10-28T12:14:51.033729490Z [inf]  2025-10-28 12:14:51,028 - src.core.position_controller - ERROR - ❌ 獲取持倉失敗: 熔斷器阻斷(失敗5次)，請24秒後重試
2025-10-28T12:14:51.033734563Z [inf]  During handling of the above exception, another exception occurred:
2025-10-28T12:14:51.033736719Z [inf]  Traceback (most recent call last):
2025-10-28T12:14:51.033743745Z [inf]    File "/app/src/clients/binance_client.py", line 197, in _request
2025-10-28T12:14:51.033746230Z [inf]  
2025-10-28T12:14:51.033751853Z [inf]      result = await self.circuit_breaker.call_async(_do_request)
2025-10-28T12:14:51.033753945Z [inf]  Traceback (most recent call last):
2025-10-28T12:14:51.033760032Z [inf]               ^^^^^^^^^^^^^^^^^^^^^^^^^^^^^^^^^^^^^^^^^^^^^^^^^^
2025-10-28T12:14:51.033760296Z [inf]    File "/app/src/core/position_controller.py", line 135, in _fetch_all_positions
2025-10-28T12:14:51.033767618Z [inf]      raw_positions = await self.binance_client.get_position_info_async()
2025-10-28T12:14:51.033768448Z [inf]    File "/app/src/core/circuit_breaker.py", line 327, in call_async
2025-10-28T12:14:51.033773296Z [inf]                      ^^^^^^^^^^^^^^^^^^^^^^^^^^^^^^^^^^^^^^^^^^^^^^^^^^^
2025-10-28T12:14:51.033776326Z [inf]      raise Exception(reason)
2025-10-28T12:14:51.033779841Z [inf]    File "/app/src/clients/binance_client.py", line 469, in get_position_info_async
2025-10-28T12:14:51.033785633Z [inf]  Exception: 熔斷器阻斷(失敗5次)，請24秒後重試
2025-10-28T12:14:51.033787078Z [inf]      account_info = await self.get_account_info()
2025-10-28T12:14:51.034430230Z [inf]                     ^^^^^^^^^^^^^^^^^^^^^^^^^^^^^
2025-10-28T12:14:51.034438200Z [inf]    File "/app/src/clients/binance_client.py", line 449, in get_account_info
2025-10-28T12:14:51.034444096Z [inf]      result = await self._request("GET", "/fapi/v2/account", signed=True)
2025-10-28T12:14:51.034449800Z [inf]               ^^^^^^^^^^^^^^^^^^^^^^^^^^^^^^^^^^^^^^^^^^^^^^^^^^^^^^^^^^^
2025-10-28T12:14:51.034456283Z [inf]    File "/app/src/clients/binance_client.py", line 213, in _request
2025-10-28T12:14:51.034462264Z [inf]      raise BinanceRequestError(
2025-10-28T12:14:51.034467854Z [inf]  src.clients.binance_errors.BinanceRequestError: 熔斷器阻斷(失敗5次)，請24秒後重試
2025-10-28T12:14:53.035481735Z [inf]  2025-10-28 12:14:53,031 - src.core.circuit_breaker - ERROR - 🔴 熔斷器阻斷(失敗5次)，請22秒後重試 | 操作: generic | 優先級: NORMAL
2025-10-28T12:14:53.035496017Z [inf]  2025-10-28 12:14:53,031 - src.clients.binance_client - ERROR - API 請求失敗: /fapi/v2/account - 熔斷器阻斷(失敗5次)，請22秒後重試
2025-10-28T12:14:53.035501004Z [inf]      raw_positions = await self.binance_client.get_position_info_async()
2025-10-28T12:14:53.035508248Z [inf]  2025-10-28 12:14:53,031 - src.core.position_controller - ERROR - ❌ 獲取持倉失敗: 熔斷器阻斷(失敗5次)，請22秒後重試
2025-10-28T12:14:53.035518284Z [inf]                      ^^^^^^^^^^^^^^^^^^^^^^^^^^^^^^^^^^^^^^^^^^^^^^^^^^^
2025-10-28T12:14:53.035520101Z [inf]  Traceback (most recent call last):
2025-10-28T12:14:53.035531571Z [inf]    File "/app/src/clients/binance_client.py", line 469, in get_position_info_async
2025-10-28T12:14:53.035532494Z [inf]    File "/app/src/clients/binance_client.py", line 197, in _request
2025-10-28T12:14:53.035543318Z [inf]      account_info = await self.get_account_info()
2025-10-28T12:14:53.035543870Z [inf]      result = await self.circuit_breaker.call_async(_do_request)
2025-10-28T12:14:53.035553063Z [inf]               ^^^^^^^^^^^^^^^^^^^^^^^^^^^^^^^^^^^^^^^^^^^^^^^^^^
2025-10-28T12:14:53.035560473Z [inf]    File "/app/src/core/circuit_breaker.py", line 327, in call_async
2025-10-28T12:14:53.035566862Z [inf]      raise Exception(reason)
2025-10-28T12:14:53.035575255Z [inf]  Exception: 熔斷器阻斷(失敗5次)，請22秒後重試
2025-10-28T12:14:53.035581891Z [inf]  
2025-10-28T12:14:53.035589227Z [inf]  During handling of the above exception, another exception occurred:
2025-10-28T12:14:53.035596662Z [inf]  
2025-10-28T12:14:53.035602407Z [inf]  Traceback (most recent call last):
2025-10-28T12:14:53.035610159Z [inf]    File "/app/src/core/position_controller.py", line 135, in _fetch_all_positions
2025-10-28T12:14:53.036228802Z [inf]                     ^^^^^^^^^^^^^^^^^^^^^^^^^^^^^
2025-10-28T12:14:53.036234893Z [inf]    File "/app/src/clients/binance_client.py", line 449, in get_account_info
2025-10-28T12:14:53.036240366Z [inf]      result = await self._request("GET", "/fapi/v2/account", signed=True)
2025-10-28T12:14:53.036245463Z [inf]               ^^^^^^^^^^^^^^^^^^^^^^^^^^^^^^^^^^^^^^^^^^^^^^^^^^^^^^^^^^^
2025-10-28T12:14:53.036250001Z [inf]    File "/app/src/clients/binance_client.py", line 213, in _request
2025-10-28T12:14:53.036254815Z [inf]      raise BinanceRequestError(
2025-10-28T12:14:53.036259660Z [inf]  src.clients.binance_errors.BinanceRequestError: 熔斷器阻斷(失敗5次)，請22秒後重試
2025-10-28T12:14:55.036048819Z [inf]  2025-10-28 12:14:55,035 - src.core.circuit_breaker - ERROR - 🔴 熔斷器阻斷(失敗5次)，請20秒後重試 | 操作: generic | 優先級: NORMAL
2025-10-28T12:14:55.036058286Z [inf]  2025-10-28 12:14:55,035 - src.clients.binance_client - ERROR - API 請求失敗: /fapi/v2/account - 熔斷器阻斷(失敗5次)，請20秒後重試
2025-10-28T12:14:55.037710977Z [inf]      account_info = await self.get_account_info()
2025-10-28T12:14:55.037726143Z [inf]                     ^^^^^^^^^^^^^^^^^^^^^^^^^^^^^
2025-10-28T12:14:55.037737300Z [inf]    File "/app/src/clients/binance_client.py", line 449, in get_account_info
2025-10-28T12:14:55.037748632Z [inf]  2025-10-28 12:14:55,035 - src.core.position_controller - ERROR - ❌ 獲取持倉失敗: 熔斷器阻斷(失敗5次)，請20秒後重試
2025-10-28T12:14:55.037750386Z [inf]      result = await self._request("GET", "/fapi/v2/account", signed=True)
2025-10-28T12:14:55.037764101Z [inf]  Traceback (most recent call last):
2025-10-28T12:14:55.037771530Z [inf]    File "/app/src/clients/binance_client.py", line 197, in _request
2025-10-28T12:14:55.037778399Z [inf]      result = await self.circuit_breaker.call_async(_do_request)
2025-10-28T12:14:55.037785397Z [inf]               ^^^^^^^^^^^^^^^^^^^^^^^^^^^^^^^^^^^^^^^^^^^^^^^^^^
2025-10-28T12:14:55.037793558Z [inf]    File "/app/src/core/circuit_breaker.py", line 327, in call_async
2025-10-28T12:14:55.037801427Z [inf]      raise Exception(reason)
2025-10-28T12:14:55.037808492Z [inf]  Exception: 熔斷器阻斷(失敗5次)，請20秒後重試
2025-10-28T12:14:55.037815326Z [inf]  
2025-10-28T12:14:55.037823075Z [inf]  During handling of the above exception, another exception occurred:
2025-10-28T12:14:55.037829024Z [inf]  
2025-10-28T12:14:55.037835448Z [inf]  Traceback (most recent call last):
2025-10-28T12:14:55.037841978Z [inf]    File "/app/src/core/position_controller.py", line 135, in _fetch_all_positions
2025-10-28T12:14:55.037848531Z [inf]      raw_positions = await self.binance_client.get_position_info_async()
2025-10-28T12:14:55.037854725Z [inf]                      ^^^^^^^^^^^^^^^^^^^^^^^^^^^^^^^^^^^^^^^^^^^^^^^^^^^
2025-10-28T12:14:55.037860248Z [inf]    File "/app/src/clients/binance_client.py", line 469, in get_position_info_async
2025-10-28T12:14:55.038265838Z [inf]               ^^^^^^^^^^^^^^^^^^^^^^^^^^^^^^^^^^^^^^^^^^^^^^^^^^^^^^^^^^^
2025-10-28T12:14:55.038275290Z [inf]    File "/app/src/clients/binance_client.py", line 213, in _request
2025-10-28T12:14:55.038281944Z [inf]      raise BinanceRequestError(
2025-10-28T12:14:55.038292256Z [inf]  src.clients.binance_errors.BinanceRequestError: 熔斷器阻斷(失敗5次)，請20秒後重試
2025-10-28T12:14:57.043346480Z [inf]  2025-10-28 12:14:57,037 - src.core.circuit_breaker - ERROR - 🔴 熔斷器阻斷(失敗5次)，請18秒後重試 | 操作: generic | 優先級: NORMAL
2025-10-28T12:14:57.043357603Z [inf]  2025-10-28 12:14:57,038 - src.clients.binance_client - ERROR - API 請求失敗: /fapi/v2/account - 熔斷器阻斷(失敗5次)，請18秒後重試
2025-10-28T12:14:57.043364862Z [inf]  2025-10-28 12:14:57,038 - src.core.position_controller - ERROR - ❌ 獲取持倉失敗: 熔斷器阻斷(失敗5次)，請18秒後重試
2025-10-28T12:14:57.043371071Z [inf]  Traceback (most recent call last):
2025-10-28T12:14:57.043376779Z [inf]    File "/app/src/clients/binance_client.py", line 197, in _request
2025-10-28T12:14:57.043383231Z [inf]      result = await self.circuit_breaker.call_async(_do_request)
2025-10-28T12:14:57.043388774Z [inf]               ^^^^^^^^^^^^^^^^^^^^^^^^^^^^^^^^^^^^^^^^^^^^^^^^^^
2025-10-28T12:14:57.043394835Z [inf]    File "/app/src/core/circuit_breaker.py", line 327, in call_async
2025-10-28T12:14:57.043401256Z [inf]      raise Exception(reason)
2025-10-28T12:14:57.043408275Z [inf]  Exception: 熔斷器阻斷(失敗5次)，請18秒後重試
2025-10-28T12:14:57.043414399Z [inf]  
2025-10-28T12:14:57.043420730Z [inf]  During handling of the above exception, another exception occurred:
2025-10-28T12:14:57.043426047Z [inf]  
2025-10-28T12:14:57.043432413Z [inf]  Traceback (most recent call last):
2025-10-28T12:14:57.043439288Z [inf]    File "/app/src/core/position_controller.py", line 135, in _fetch_all_positions
2025-10-28T12:14:57.043444975Z [inf]      raw_positions = await self.binance_client.get_position_info_async()
2025-10-28T12:14:57.043450478Z [inf]                      ^^^^^^^^^^^^^^^^^^^^^^^^^^^^^^^^^^^^^^^^^^^^^^^^^^^
2025-10-28T12:14:57.043456771Z [inf]    File "/app/src/clients/binance_client.py", line 469, in get_position_info_async
2025-10-28T12:14:57.043462727Z [inf]      account_info = await self.get_account_info()
2025-10-28T12:14:57.044036222Z [inf]                     ^^^^^^^^^^^^^^^^^^^^^^^^^^^^^
2025-10-28T12:14:57.044045486Z [inf]    File "/app/src/clients/binance_client.py", line 449, in get_account_info
2025-10-28T12:14:57.044054239Z [inf]      result = await self._request("GET", "/fapi/v2/account", signed=True)
2025-10-28T12:14:57.044059933Z [inf]               ^^^^^^^^^^^^^^^^^^^^^^^^^^^^^^^^^^^^^^^^^^^^^^^^^^^^^^^^^^^
2025-10-28T12:14:57.044064970Z [inf]    File "/app/src/clients/binance_client.py", line 213, in _request
2025-10-28T12:14:57.044070658Z [inf]      raise BinanceRequestError(
2025-10-28T12:14:57.044076312Z [inf]  src.clients.binance_errors.BinanceRequestError: 熔斷器阻斷(失敗5次)，請18秒後重試
2025-10-28T12:14:59.048458453Z [inf]  2025-10-28 12:14:59,040 - src.core.circuit_breaker - ERROR - 🔴 熔斷器阻斷(失敗5次)，請16秒後重試 | 操作: generic | 優先級: NORMAL
2025-10-28T12:14:59.048469223Z [inf]  2025-10-28 12:14:59,040 - src.clients.binance_client - ERROR - API 請求失敗: /fapi/v2/account - 熔斷器阻斷(失敗5次)，請16秒後重試
2025-10-28T12:14:59.048475923Z [inf]  2025-10-28 12:14:59,040 - src.core.position_controller - ERROR - ❌ 獲取持倉失敗: 熔斷器阻斷(失敗5次)，請16秒後重試
2025-10-28T12:14:59.048482364Z [inf]  Traceback (most recent call last):
2025-10-28T12:14:59.048490940Z [inf]    File "/app/src/clients/binance_client.py", line 197, in _request
2025-10-28T12:14:59.048509526Z [inf]      result = await self.circuit_breaker.call_async(_do_request)
2025-10-28T12:14:59.048516081Z [inf]               ^^^^^^^^^^^^^^^^^^^^^^^^^^^^^^^^^^^^^^^^^^^^^^^^^^
2025-10-28T12:14:59.048523014Z [inf]    File "/app/src/core/circuit_breaker.py", line 327, in call_async
2025-10-28T12:14:59.048528766Z [inf]      raise Exception(reason)
2025-10-28T12:14:59.048534759Z [inf]  Exception: 熔斷器阻斷(失敗5次)，請16秒後重試
2025-10-28T12:14:59.048543363Z [inf]  
2025-10-28T12:14:59.048549145Z [inf]  During handling of the above exception, another exception occurred:
2025-10-28T12:14:59.048554392Z [inf]  
2025-10-28T12:14:59.048560097Z [inf]  Traceback (most recent call last):
2025-10-28T12:14:59.048567553Z [inf]    File "/app/src/core/position_controller.py", line 135, in _fetch_all_positions
2025-10-28T12:14:59.048574499Z [inf]      raw_positions = await self.binance_client.get_position_info_async()
2025-10-28T12:14:59.048580155Z [inf]                      ^^^^^^^^^^^^^^^^^^^^^^^^^^^^^^^^^^^^^^^^^^^^^^^^^^^
2025-10-28T12:14:59.048585735Z [inf]    File "/app/src/clients/binance_client.py", line 469, in get_position_info_async
2025-10-28T12:14:59.048591454Z [inf]      account_info = await self.get_account_info()
2025-10-28T12:14:59.050432798Z [inf]                     ^^^^^^^^^^^^^^^^^^^^^^^^^^^^^
2025-10-28T12:14:59.050439516Z [inf]    File "/app/src/clients/binance_client.py", line 449, in get_account_info
2025-10-28T12:14:59.050443943Z [inf]      result = await self._request("GET", "/fapi/v2/account", signed=True)
2025-10-28T12:14:59.050447938Z [inf]               ^^^^^^^^^^^^^^^^^^^^^^^^^^^^^^^^^^^^^^^^^^^^^^^^^^^^^^^^^^^
2025-10-28T12:14:59.050452219Z [inf]    File "/app/src/clients/binance_client.py", line 213, in _request
2025-10-28T12:14:59.050456033Z [inf]      raise BinanceRequestError(
2025-10-28T12:14:59.050459803Z [inf]  src.clients.binance_errors.BinanceRequestError: 熔斷器阻斷(失敗5次)，請16秒後重試
2025-10-28T12:15:01.047092686Z [inf]  During handling of the above exception, another exception occurred:
2025-10-28T12:15:01.047098371Z [inf]  2025-10-28 12:15:01,042 - src.core.circuit_breaker - ERROR - 🔴 熔斷器阻斷(失敗5次)，請14秒後重試 | 操作: generic | 優先級: NORMAL
2025-10-28T12:15:01.047106714Z [inf]  2025-10-28 12:15:01,042 - src.clients.binance_client - ERROR - API 請求失敗: /fapi/v2/account - 熔斷器阻斷(失敗5次)，請14秒後重試
2025-10-28T12:15:01.047107543Z [inf]  
2025-10-28T12:15:01.047115057Z [inf]  2025-10-28 12:15:01,042 - src.core.position_controller - ERROR - ❌ 獲取持倉失敗: 熔斷器阻斷(失敗5次)，請14秒後重試
2025-10-28T12:15:01.047117664Z [inf]  Traceback (most recent call last):
2025-10-28T12:15:01.047124807Z [inf]  Traceback (most recent call last):
2025-10-28T12:15:01.047127036Z [inf]    File "/app/src/core/position_controller.py", line 135, in _fetch_all_positions
2025-10-28T12:15:01.047133271Z [inf]    File "/app/src/clients/binance_client.py", line 197, in _request
2025-10-28T12:15:01.047136159Z [inf]      raw_positions = await self.binance_client.get_position_info_async()
2025-10-28T12:15:01.047141357Z [inf]      result = await self.circuit_breaker.call_async(_do_request)
2025-10-28T12:15:01.047144739Z [inf]                      ^^^^^^^^^^^^^^^^^^^^^^^^^^^^^^^^^^^^^^^^^^^^^^^^^^^
2025-10-28T12:15:01.047149558Z [inf]               ^^^^^^^^^^^^^^^^^^^^^^^^^^^^^^^^^^^^^^^^^^^^^^^^^^
2025-10-28T12:15:01.047152853Z [inf]    File "/app/src/clients/binance_client.py", line 469, in get_position_info_async
2025-10-28T12:15:01.047160464Z [inf]    File "/app/src/core/circuit_breaker.py", line 327, in call_async
2025-10-28T12:15:01.047162001Z [inf]      account_info = await self.get_account_info()
2025-10-28T12:15:01.047167567Z [inf]      raise Exception(reason)
2025-10-28T12:15:01.047173551Z [inf]  Exception: 熔斷器阻斷(失敗5次)，請14秒後重試
2025-10-28T12:15:01.047182179Z [inf]  
2025-10-28T12:15:01.048130507Z [inf]  src.clients.binance_errors.BinanceRequestError: 熔斷器阻斷(失敗5次)，請14秒後重試
2025-10-28T12:15:01.048149420Z [inf]                     ^^^^^^^^^^^^^^^^^^^^^^^^^^^^^
2025-10-28T12:15:01.048156769Z [inf]    File "/app/src/clients/binance_client.py", line 449, in get_account_info
2025-10-28T12:15:01.048165025Z [inf]      result = await self._request("GET", "/fapi/v2/account", signed=True)
2025-10-28T12:15:01.048170674Z [inf]               ^^^^^^^^^^^^^^^^^^^^^^^^^^^^^^^^^^^^^^^^^^^^^^^^^^^^^^^^^^^
2025-10-28T12:15:01.048176247Z [inf]    File "/app/src/clients/binance_client.py", line 213, in _request
2025-10-28T12:15:01.048182349Z [inf]      raise BinanceRequestError(
2025-10-28T12:15:03.050063503Z [inf]    File "/app/src/core/position_controller.py", line 135, in _fetch_all_positions
2025-10-28T12:15:03.050073860Z [inf]      raw_positions = await self.binance_client.get_position_info_async()
2025-10-28T12:15:03.050080119Z [inf]                      ^^^^^^^^^^^^^^^^^^^^^^^^^^^^^^^^^^^^^^^^^^^^^^^^^^^
2025-10-28T12:15:03.050085315Z [inf]    File "/app/src/clients/binance_client.py", line 469, in get_position_info_async
2025-10-28T12:15:03.050090799Z [inf]      account_info = await self.get_account_info()
2025-10-28T12:15:03.050106675Z [inf]  2025-10-28 12:15:03,045 - src.core.circuit_breaker - ERROR - 🔴 熔斷器阻斷(失敗5次)，請12秒後重試 | 操作: generic | 優先級: NORMAL
2025-10-28T12:15:03.050112960Z [inf]  2025-10-28 12:15:03,045 - src.clients.binance_client - ERROR - API 請求失敗: /fapi/v2/account - 熔斷器阻斷(失敗5次)，請12秒後重試
2025-10-28T12:15:03.050118386Z [inf]  2025-10-28 12:15:03,045 - src.core.position_controller - ERROR - ❌ 獲取持倉失敗: 熔斷器阻斷(失敗5次)，請12秒後重試
2025-10-28T12:15:03.050123650Z [inf]  Traceback (most recent call last):
2025-10-28T12:15:03.050129051Z [inf]    File "/app/src/clients/binance_client.py", line 197, in _request
2025-10-28T12:15:03.050135750Z [inf]      result = await self.circuit_breaker.call_async(_do_request)
2025-10-28T12:15:03.050142716Z [inf]               ^^^^^^^^^^^^^^^^^^^^^^^^^^^^^^^^^^^^^^^^^^^^^^^^^^
2025-10-28T12:15:03.050147769Z [inf]    File "/app/src/core/circuit_breaker.py", line 327, in call_async
2025-10-28T12:15:03.050152309Z [inf]      raise Exception(reason)
2025-10-28T12:15:03.050157228Z [inf]  Exception: 熔斷器阻斷(失敗5次)，請12秒後重試
2025-10-28T12:15:03.050163576Z [inf]  
2025-10-28T12:15:03.050168707Z [inf]  During handling of the above exception, another exception occurred:
2025-10-28T12:15:03.050173294Z [inf]  
2025-10-28T12:15:03.050178887Z [inf]  Traceback (most recent call last):
2025-10-28T12:15:03.051109365Z [inf]                     ^^^^^^^^^^^^^^^^^^^^^^^^^^^^^
2025-10-28T12:15:03.051114938Z [inf]    File "/app/src/clients/binance_client.py", line 449, in get_account_info
2025-10-28T12:15:03.051119471Z [inf]      result = await self._request("GET", "/fapi/v2/account", signed=True)
2025-10-28T12:15:03.051124780Z [inf]               ^^^^^^^^^^^^^^^^^^^^^^^^^^^^^^^^^^^^^^^^^^^^^^^^^^^^^^^^^^^
2025-10-28T12:15:03.051130166Z [inf]    File "/app/src/clients/binance_client.py", line 213, in _request
2025-10-28T12:15:03.051137890Z [inf]      raise BinanceRequestError(
2025-10-28T12:15:03.051143522Z [inf]  src.clients.binance_errors.BinanceRequestError: 熔斷器阻斷(失敗5次)，請12秒後重試
2025-10-28T12:15:05.062163035Z [inf]  2025-10-28 12:15:05,047 - src.core.circuit_breaker - ERROR - 🔴 熔斷器阻斷(失敗5次)，請10秒後重試 | 操作: generic | 優先級: NORMAL
2025-10-28T12:15:05.062173059Z [inf]  2025-10-28 12:15:05,047 - src.clients.binance_client - ERROR - API 請求失敗: /fapi/v2/account - 熔斷器阻斷(失敗5次)，請10秒後重試
2025-10-28T12:15:05.062180358Z [inf]  2025-10-28 12:15:05,047 - src.core.position_controller - ERROR - ❌ 獲取持倉失敗: 熔斷器阻斷(失敗5次)，請10秒後重試
2025-10-28T12:15:05.062185673Z [inf]  Traceback (most recent call last):
2025-10-28T12:15:05.062190857Z [inf]    File "/app/src/clients/binance_client.py", line 197, in _request
2025-10-28T12:15:05.062197192Z [inf]      result = await self.circuit_breaker.call_async(_do_request)
2025-10-28T12:15:05.062204062Z [inf]               ^^^^^^^^^^^^^^^^^^^^^^^^^^^^^^^^^^^^^^^^^^^^^^^^^^
2025-10-28T12:15:05.062210243Z [inf]    File "/app/src/core/circuit_breaker.py", line 327, in call_async
2025-10-28T12:15:05.062215091Z [inf]      raise Exception(reason)
2025-10-28T12:15:05.062219903Z [inf]  Exception: 熔斷器阻斷(失敗5次)，請10秒後重試
2025-10-28T12:15:05.062224382Z [inf]  
2025-10-28T12:15:05.062228605Z [inf]  During handling of the above exception, another exception occurred:
2025-10-28T12:15:05.062233072Z [inf]  
2025-10-28T12:15:05.062239376Z [inf]  Traceback (most recent call last):
2025-10-28T12:15:05.062243611Z [inf]    File "/app/src/core/position_controller.py", line 135, in _fetch_all_positions
2025-10-28T12:15:05.062247937Z [inf]      raw_positions = await self.binance_client.get_position_info_async()
2025-10-28T12:15:05.062252526Z [inf]                      ^^^^^^^^^^^^^^^^^^^^^^^^^^^^^^^^^^^^^^^^^^^^^^^^^^^
2025-10-28T12:15:05.062257475Z [inf]    File "/app/src/clients/binance_client.py", line 469, in get_position_info_async
2025-10-28T12:15:05.062262602Z [inf]      account_info = await self.get_account_info()
2025-10-28T12:15:05.063506851Z [inf]                     ^^^^^^^^^^^^^^^^^^^^^^^^^^^^^
2025-10-28T12:15:05.063516281Z [inf]    File "/app/src/clients/binance_client.py", line 449, in get_account_info
2025-10-28T12:15:05.063523744Z [inf]      result = await self._request("GET", "/fapi/v2/account", signed=True)
2025-10-28T12:15:05.063537258Z [inf]               ^^^^^^^^^^^^^^^^^^^^^^^^^^^^^^^^^^^^^^^^^^^^^^^^^^^^^^^^^^^
2025-10-28T12:15:05.063544343Z [inf]    File "/app/src/clients/binance_client.py", line 213, in _request
2025-10-28T12:15:05.063551279Z [inf]      raise BinanceRequestError(
2025-10-28T12:15:05.063557819Z [inf]  src.clients.binance_errors.BinanceRequestError: 熔斷器阻斷(失敗5次)，請10秒後重試